2022-04-17 19:17:38,032:INFO:PyCaret Supervised Module
2022-04-17 19:17:38,035:INFO:ML Usecase: classification
2022-04-17 19:17:38,036:INFO:version 2.3.10
2022-04-17 19:17:38,038:INFO:Initializing setup()
2022-04-17 19:17:38,040:INFO:setup(target=label_-15_1min_close, ml_usecase=classification, available_plots={'parameter': 'Hyperparameters', 'auc': 'AUC', 'confusion_matrix': 'Confusion Matrix', 'threshold': 'Threshold', 'pr': 'Precision Recall', 'error': 'Prediction Error', 'class_report': 'Class Report', 'rfe': 'Feature Selection', 'learning': 'Learning Curve', 'manifold': 'Manifold Learning', 'calibration': 'Calibration Curve', 'vc': 'Validation Curve', 'dimension': 'Dimensions', 'feature': 'Feature Importance', 'feature_all': 'Feature Importance (All)', 'boundary': 'Decision Boundary', 'lift': 'Lift Chart', 'gain': 'Gain Chart', 'tree': 'Decision Tree', 'ks': 'KS Statistic Plot'}, train_size=0.7, test_data=None, preprocess=True, imputation_type=simple, iterative_imputation_iters=5, categorical_features=None, categorical_imputation=constant, categorical_iterative_imputer=lightgbm, ordinal_features=None, high_cardinality_features=None, high_cardinality_method=frequency, numeric_features=None, numeric_imputation=mean, numeric_iterative_imputer=lightgbm, date_features=None, ignore_features=None, normalize=False, normalize_method=zscore, transformation=False, transformation_method=yeo-johnson, handle_unknown_categorical=True, unknown_categorical_method=least_frequent, pca=False, pca_method=linear, pca_components=None, ignore_low_variance=False, combine_rare_levels=False, rare_level_threshold=0.1, bin_numeric_features=None, remove_outliers=False, outliers_threshold=0.05, remove_multicollinearity=False, multicollinearity_threshold=0.9, remove_perfect_collinearity=True, create_clusters=False, cluster_iter=20, polynomial_features=False, polynomial_degree=2, trigonometry_features=False, polynomial_threshold=0.1, group_features=None, group_names=None, feature_selection=False, feature_selection_threshold=0.8, feature_selection_method=classic, feature_interaction=False, feature_ratio=False, interaction_threshold=0.01, fix_imbalance=False, fix_imbalance_method=None, transform_target=False, transform_target_method=box-cox, data_split_shuffle=True, data_split_stratify=False, fold_strategy=stratifiedkfold, fold=10, fold_shuffle=False, fold_groups=None, n_jobs=-1, use_gpu=False, custom_pipeline=None, html=True, session_id=123, log_experiment=False, experiment_name=None, experiment_custom_tags=None, log_plots=False, log_profile=False, log_data=False, silent=False, verbose=True, profile=False, profile_kwargs=None, display=None)
2022-04-17 19:17:38,044:INFO:Checking environment
2022-04-17 19:17:38,046:INFO:python_version: 3.8.2
2022-04-17 19:17:38,048:INFO:python_build: ('default', 'Apr 24 2020 07:34:03')
2022-04-17 19:17:38,050:INFO:machine: AMD64
2022-04-17 19:17:38,053:INFO:platform: Windows-10-10.0.19041-SP0
2022-04-17 19:17:38,059:WARNING:cannot find psutil installation. memory not traceable. Install psutil using pip to enable memory logging.
2022-04-17 19:17:38,061:INFO:Checking libraries
2022-04-17 19:17:38,063:INFO:pd==1.4.1
2022-04-17 19:17:38,064:INFO:numpy==1.20.0
2022-04-17 19:17:38,065:INFO:sklearn==0.23.2
2022-04-17 19:17:38,067:INFO:lightgbm==3.3.2
2022-04-17 19:17:38,076:WARNING:catboost not found
2022-04-17 19:17:38,080:WARNING:xgboost not found
2022-04-17 19:17:38,081:INFO:mlflow==1.25.1
2022-04-17 19:17:38,085:INFO:Checking Exceptions
2022-04-17 19:17:38,088:INFO:Declaring global variables
2022-04-17 19:17:38,091:INFO:USI: 880d
2022-04-17 19:17:38,094:INFO:pycaret_globals: {'fold_groups_param', 'USI', '_gpu_n_jobs_param', 'imputation_regressor', 'gpu_param', 'fix_imbalance_method_param', 'X_train', 'master_model_container', 'logging_param', 'fold_generator', 'imputation_classifier', 'experiment__', '_all_models', 'fix_imbalance_param', 'fold_shuffle_param', 'n_jobs_param', 'seed', 'y_train', 'exp_name_log', 'transform_target_method_param', 'html_param', 'dashboard_logger', 'transform_target_param', 'iterative_imputation_iters_param', 'stratify_param', 'data_before_preprocess', 'X', 'y', 'fold_groups_param_full', 'fold_param', 'y_test', 'log_plots_param', '_all_models_internal', '_ml_usecase', 'create_model_container', '_internal_pipeline', 'pycaret_globals', '_available_plots', 'display_container', 'X_test', 'target_param', '_all_metrics', 'prep_pipe'}
2022-04-17 19:17:38,096:INFO:Preparing display monitor
2022-04-17 19:17:38,098:INFO:Preparing display monitor
2022-04-17 19:17:38,124:INFO:Importing libraries
2022-04-17 19:17:38,125:INFO:Copying data for preprocessing
2022-04-17 19:17:38,378:INFO:Declaring preprocessing parameters
2022-04-17 19:17:38,846:INFO:Creating preprocessing pipeline
2022-04-17 19:17:46,944:INFO:Preprocessing pipeline created successfully
2022-04-17 19:17:46,944:ERROR:(Process Exit): setup has been interupted with user command 'quit'. setup must rerun.
2022-04-17 19:17:46,949:INFO:Creating global containers
2022-04-17 19:17:46,965:INFO:Internal pipeline: Pipeline(memory=None, steps=[('empty_step', 'passthrough')], verbose=False)
2022-04-17 19:22:39,308:INFO:Creating grid variables
2022-04-17 19:22:39,572:INFO:create_model_container: 0
2022-04-17 19:22:39,573:INFO:master_model_container: 0
2022-04-17 19:22:39,574:INFO:display_container: 1
2022-04-17 19:22:39,584:INFO:Pipeline(memory=None,
         steps=[('dtypes',
                 DataTypes_Auto_infer(categorical_features=[],
                                      display_types=True, features_todrop=[],
                                      id_columns=[],
                                      ml_usecase='classification',
                                      numerical_features=[],
                                      target='label_-15_1min_close',
                                      time_features=[])),
                ('imputer',
                 Simple_Imputer(categorical_strategy='not_available',
                                fill_value_categorical=None,
                                fill_value_numerical=None...
                ('scaling', 'passthrough'), ('P_transform', 'passthrough'),
                ('binn', 'passthrough'), ('rem_outliers', 'passthrough'),
                ('cluster_all', 'passthrough'),
                ('dummy', Dummify(target='label_-15_1min_close')),
                ('fix_perfect', Remove_100(target='label_-15_1min_close')),
                ('clean_names', Clean_Colum_Names()),
                ('feature_select', 'passthrough'), ('fix_multi', 'passthrough'),
                ('dfs', 'passthrough'), ('pca', 'passthrough')],
         verbose=False)
2022-04-17 19:22:39,586:INFO:setup() succesfully completed......................................
2022-04-17 19:24:20,456:INFO:Initializing compare_models()
2022-04-17 19:24:20,457:INFO:compare_models(include=None, fold=None, round=4, cross_validation=True, sort=Accuracy, n_select=1, budget_time=None, turbo=True, errors=ignore, fit_kwargs=None, groups=None, experiment_custom_tags=None, probability_threshold=None, verbose=True, display=None, exclude=None)
2022-04-17 19:24:20,458:INFO:Checking exceptions
2022-04-17 19:24:20,469:INFO:Preparing display monitor
2022-04-17 19:24:20,471:INFO:Preparing display monitor
2022-04-17 19:24:20,528:INFO:Initializing Logistic Regression
2022-04-17 19:24:20,530:INFO:Total runtime is 3.3179918924967446e-05 minutes
2022-04-17 19:24:20,553:INFO:SubProcess create_model() called ==================================
2022-04-17 19:24:20,555:INFO:Initializing create_model()
2022-04-17 19:24:20,557:INFO:create_model(estimator=lr, fold=StratifiedKFold(n_splits=10, random_state=None, shuffle=False), round=4, cross_validation=True, predict=True, fit_kwargs={}, groups=None, refit=False, verbose=False, system=False, metrics=None, experiment_custom_tags=None, add_to_model_list=True, probability_threshold=None, display=<pycaret.internal.Display.Display object at 0x000001D75ACFC490>, return_train_score=False, kwargs={})
2022-04-17 19:24:20,558:INFO:Checking exceptions
2022-04-17 19:24:20,560:INFO:Importing libraries
2022-04-17 19:24:20,562:INFO:Copying training dataset
2022-04-17 19:24:20,614:INFO:Defining folds
2022-04-17 19:24:20,617:INFO:Declaring metric variables
2022-04-17 19:24:20,628:INFO:Importing untrained model
2022-04-17 19:24:20,657:INFO:Logistic Regression Imported succesfully
2022-04-17 19:24:20,693:INFO:Starting cross validation
2022-04-17 19:24:20,695:INFO:Cross validating with StratifiedKFold(n_splits=10, random_state=None, shuffle=False), n_jobs=-1
2022-04-17 19:24:20,987:WARNING:create_model() for lr raised an exception or returned all 0.0, trying without fit_kwargs:
2022-04-17 19:24:21,078:WARNING:Traceback (most recent call last):
  File "C:\Users\8prab\.conda\envs\ee\lib\site-packages\pycaret\internal\tabular.py", line 2203, in compare_models
    model, model_fit_time = create_model_supervised(**create_model_args)
  File "C:\Users\8prab\.conda\envs\ee\lib\site-packages\pycaret\internal\tabular.py", line 3200, in create_model_supervised
    scores = cross_validate(
  File "C:\Users\8prab\.conda\envs\ee\lib\site-packages\sklearn\utils\validation.py", line 72, in inner_f
    return f(**kwargs)
  File "C:\Users\8prab\.conda\envs\ee\lib\site-packages\sklearn\model_selection\_validation.py", line 242, in cross_validate
    scores = parallel(
  File "C:\Users\8prab\AppData\Roaming\Python\Python38\site-packages\joblib\parallel.py", line 1043, in __call__
    if self.dispatch_one_batch(iterator):
  File "C:\Users\8prab\AppData\Roaming\Python\Python38\site-packages\joblib\parallel.py", line 861, in dispatch_one_batch
    self._dispatch(tasks)
  File "C:\Users\8prab\AppData\Roaming\Python\Python38\site-packages\joblib\parallel.py", line 779, in _dispatch
    job = self._backend.apply_async(batch, callback=cb)
  File "C:\Users\8prab\AppData\Roaming\Python\Python38\site-packages\joblib\_parallel_backends.py", line 531, in apply_async
    future = self._workers.submit(SafeFunction(func))
  File "C:\Users\8prab\AppData\Roaming\Python\Python38\site-packages\joblib\externals\loky\reusable_executor.py", line 177, in submit
    return super(_ReusablePoolExecutor, self).submit(
  File "C:\Users\8prab\AppData\Roaming\Python\Python38\site-packages\joblib\externals\loky\process_executor.py", line 1135, in submit
    self._ensure_executor_running()
  File "C:\Users\8prab\AppData\Roaming\Python\Python38\site-packages\joblib\externals\loky\process_executor.py", line 1109, in _ensure_executor_running
    self._adjust_process_count()
  File "C:\Users\8prab\AppData\Roaming\Python\Python38\site-packages\joblib\externals\loky\process_executor.py", line 1100, in _adjust_process_count
    p.start()
  File "C:\Users\8prab\.conda\envs\ee\lib\multiprocessing\process.py", line 121, in start
    self._popen = self._Popen(self)
  File "C:\Users\8prab\AppData\Roaming\Python\Python38\site-packages\joblib\externals\loky\backend\process.py", line 39, in _Popen
    return Popen(process_obj)
  File "C:\Users\8prab\AppData\Roaming\Python\Python38\site-packages\joblib\externals\loky\backend\popen_loky_win32.py", line 54, in __init__
    prep_data = spawn.get_preparation_data(
  File "C:\Users\8prab\AppData\Roaming\Python\Python38\site-packages\joblib\externals\loky\backend\spawn.py", line 86, in get_preparation_data
    _resource_tracker.ensure_running()
  File "C:\Users\8prab\AppData\Roaming\Python\Python38\site-packages\joblib\externals\loky\backend\resource_tracker.py", line 102, in ensure_running
    if self._check_alive():
  File "C:\Users\8prab\AppData\Roaming\Python\Python38\site-packages\joblib\externals\loky\backend\resource_tracker.py", line 182, in _check_alive
    self._send('PROBE', '', '')
  File "C:\Users\8prab\AppData\Roaming\Python\Python38\site-packages\joblib\externals\loky\backend\resource_tracker.py", line 209, in _send
    nbytes = os.write(self._fd, msg)
OSError: [Errno 22] Invalid argument

2022-04-17 19:24:21,084:INFO:Initializing create_model()
2022-04-17 19:24:21,086:INFO:create_model(estimator=lr, fold=StratifiedKFold(n_splits=10, random_state=None, shuffle=False), round=4, cross_validation=True, predict=True, fit_kwargs={}, groups=None, refit=False, verbose=False, system=False, metrics=None, experiment_custom_tags=None, add_to_model_list=True, probability_threshold=None, display=<pycaret.internal.Display.Display object at 0x000001D75ACFC490>, return_train_score=False, kwargs={})
2022-04-17 19:24:21,088:INFO:Checking exceptions
2022-04-17 19:24:21,091:INFO:Importing libraries
2022-04-17 19:24:21,093:INFO:Copying training dataset
2022-04-17 19:24:21,157:INFO:Defining folds
2022-04-17 19:24:21,159:INFO:Declaring metric variables
2022-04-17 19:24:21,186:INFO:Importing untrained model
2022-04-17 19:24:21,219:INFO:Logistic Regression Imported succesfully
2022-04-17 19:24:21,279:INFO:Starting cross validation
2022-04-17 19:24:21,282:INFO:Cross validating with StratifiedKFold(n_splits=10, random_state=None, shuffle=False), n_jobs=-1
2022-04-17 19:24:21,289:ERROR:create_model() for lr raised an exception or returned all 0.0:
2022-04-17 19:24:21,297:ERROR:Traceback (most recent call last):
  File "C:\Users\8prab\.conda\envs\ee\lib\site-packages\pycaret\internal\tabular.py", line 2203, in compare_models
    model, model_fit_time = create_model_supervised(**create_model_args)
  File "C:\Users\8prab\.conda\envs\ee\lib\site-packages\pycaret\internal\tabular.py", line 3200, in create_model_supervised
    scores = cross_validate(
  File "C:\Users\8prab\.conda\envs\ee\lib\site-packages\sklearn\utils\validation.py", line 72, in inner_f
    return f(**kwargs)
  File "C:\Users\8prab\.conda\envs\ee\lib\site-packages\sklearn\model_selection\_validation.py", line 242, in cross_validate
    scores = parallel(
  File "C:\Users\8prab\AppData\Roaming\Python\Python38\site-packages\joblib\parallel.py", line 1043, in __call__
    if self.dispatch_one_batch(iterator):
  File "C:\Users\8prab\AppData\Roaming\Python\Python38\site-packages\joblib\parallel.py", line 861, in dispatch_one_batch
    self._dispatch(tasks)
  File "C:\Users\8prab\AppData\Roaming\Python\Python38\site-packages\joblib\parallel.py", line 779, in _dispatch
    job = self._backend.apply_async(batch, callback=cb)
  File "C:\Users\8prab\AppData\Roaming\Python\Python38\site-packages\joblib\_parallel_backends.py", line 531, in apply_async
    future = self._workers.submit(SafeFunction(func))
  File "C:\Users\8prab\AppData\Roaming\Python\Python38\site-packages\joblib\externals\loky\reusable_executor.py", line 177, in submit
    return super(_ReusablePoolExecutor, self).submit(
  File "C:\Users\8prab\AppData\Roaming\Python\Python38\site-packages\joblib\externals\loky\process_executor.py", line 1135, in submit
    self._ensure_executor_running()
  File "C:\Users\8prab\AppData\Roaming\Python\Python38\site-packages\joblib\externals\loky\process_executor.py", line 1109, in _ensure_executor_running
    self._adjust_process_count()
  File "C:\Users\8prab\AppData\Roaming\Python\Python38\site-packages\joblib\externals\loky\process_executor.py", line 1100, in _adjust_process_count
    p.start()
  File "C:\Users\8prab\.conda\envs\ee\lib\multiprocessing\process.py", line 121, in start
    self._popen = self._Popen(self)
  File "C:\Users\8prab\AppData\Roaming\Python\Python38\site-packages\joblib\externals\loky\backend\process.py", line 39, in _Popen
    return Popen(process_obj)
  File "C:\Users\8prab\AppData\Roaming\Python\Python38\site-packages\joblib\externals\loky\backend\popen_loky_win32.py", line 54, in __init__
    prep_data = spawn.get_preparation_data(
  File "C:\Users\8prab\AppData\Roaming\Python\Python38\site-packages\joblib\externals\loky\backend\spawn.py", line 86, in get_preparation_data
    _resource_tracker.ensure_running()
  File "C:\Users\8prab\AppData\Roaming\Python\Python38\site-packages\joblib\externals\loky\backend\resource_tracker.py", line 102, in ensure_running
    if self._check_alive():
  File "C:\Users\8prab\AppData\Roaming\Python\Python38\site-packages\joblib\externals\loky\backend\resource_tracker.py", line 182, in _check_alive
    self._send('PROBE', '', '')
  File "C:\Users\8prab\AppData\Roaming\Python\Python38\site-packages\joblib\externals\loky\backend\resource_tracker.py", line 209, in _send
    nbytes = os.write(self._fd, msg)
OSError: [Errno 22] Invalid argument

During handling of the above exception, another exception occurred:

Traceback (most recent call last):
  File "C:\Users\8prab\.conda\envs\ee\lib\site-packages\pycaret\internal\tabular.py", line 2212, in compare_models
    model, model_fit_time = create_model_supervised(**create_model_args)
  File "C:\Users\8prab\.conda\envs\ee\lib\site-packages\pycaret\internal\tabular.py", line 3200, in create_model_supervised
    scores = cross_validate(
  File "C:\Users\8prab\.conda\envs\ee\lib\site-packages\sklearn\utils\validation.py", line 72, in inner_f
    return f(**kwargs)
  File "C:\Users\8prab\.conda\envs\ee\lib\site-packages\sklearn\model_selection\_validation.py", line 242, in cross_validate
    scores = parallel(
  File "C:\Users\8prab\AppData\Roaming\Python\Python38\site-packages\joblib\parallel.py", line 968, in __call__
    n_jobs = self._initialize_backend()
  File "C:\Users\8prab\AppData\Roaming\Python\Python38\site-packages\joblib\parallel.py", line 735, in _initialize_backend
    n_jobs = self._backend.configure(n_jobs=self.n_jobs, parallel=self,
  File "C:\Users\8prab\AppData\Roaming\Python\Python38\site-packages\joblib\_parallel_backends.py", line 494, in configure
    self._workers = get_memmapping_executor(
  File "C:\Users\8prab\AppData\Roaming\Python\Python38\site-packages\joblib\executor.py", line 20, in get_memmapping_executor
    return MemmappingExecutor.get_memmapping_executor(n_jobs, **kwargs)
  File "C:\Users\8prab\AppData\Roaming\Python\Python38\site-packages\joblib\executor.py", line 42, in get_memmapping_executor
    manager = TemporaryResourcesManager(temp_folder)
  File "C:\Users\8prab\AppData\Roaming\Python\Python38\site-packages\joblib\_memmapping_reducer.py", line 531, in __init__
    self.set_current_context(context_id)
  File "C:\Users\8prab\AppData\Roaming\Python\Python38\site-packages\joblib\_memmapping_reducer.py", line 535, in set_current_context
    self.register_new_context(context_id)
  File "C:\Users\8prab\AppData\Roaming\Python\Python38\site-packages\joblib\_memmapping_reducer.py", line 560, in register_new_context
    self.register_folder_finalizer(new_folder_path, context_id)
  File "C:\Users\8prab\AppData\Roaming\Python\Python38\site-packages\joblib\_memmapping_reducer.py", line 590, in register_folder_finalizer
    resource_tracker.register(pool_subfolder, "folder")
  File "C:\Users\8prab\AppData\Roaming\Python\Python38\site-packages\joblib\externals\loky\backend\resource_tracker.py", line 190, in register
    self.ensure_running()
  File "C:\Users\8prab\AppData\Roaming\Python\Python38\site-packages\joblib\externals\loky\backend\resource_tracker.py", line 102, in ensure_running
    if self._check_alive():
  File "C:\Users\8prab\AppData\Roaming\Python\Python38\site-packages\joblib\externals\loky\backend\resource_tracker.py", line 182, in _check_alive
    self._send('PROBE', '', '')
  File "C:\Users\8prab\AppData\Roaming\Python\Python38\site-packages\joblib\externals\loky\backend\resource_tracker.py", line 209, in _send
    nbytes = os.write(self._fd, msg)
OSError: [Errno 22] Invalid argument

2022-04-17 19:24:21,316:INFO:Initializing K Neighbors Classifier
2022-04-17 19:24:21,320:INFO:Total runtime is 0.01319657564163208 minutes
2022-04-17 19:24:21,342:INFO:SubProcess create_model() called ==================================
2022-04-17 19:24:21,344:INFO:Initializing create_model()
2022-04-17 19:24:21,346:INFO:create_model(estimator=knn, fold=StratifiedKFold(n_splits=10, random_state=None, shuffle=False), round=4, cross_validation=True, predict=True, fit_kwargs={}, groups=None, refit=False, verbose=False, system=False, metrics=None, experiment_custom_tags=None, add_to_model_list=True, probability_threshold=None, display=<pycaret.internal.Display.Display object at 0x000001D75ACFC490>, return_train_score=False, kwargs={})
2022-04-17 19:24:21,348:INFO:Checking exceptions
2022-04-17 19:24:21,350:INFO:Importing libraries
2022-04-17 19:24:21,353:INFO:Copying training dataset
2022-04-17 19:24:21,414:INFO:Defining folds
2022-04-17 19:24:21,424:INFO:Declaring metric variables
2022-04-17 19:24:21,458:INFO:Importing untrained model
2022-04-17 19:24:21,480:INFO:K Neighbors Classifier Imported succesfully
2022-04-17 19:24:21,518:INFO:Starting cross validation
2022-04-17 19:24:21,520:INFO:Cross validating with StratifiedKFold(n_splits=10, random_state=None, shuffle=False), n_jobs=-1
2022-04-17 19:24:21,523:WARNING:create_model() for knn raised an exception or returned all 0.0, trying without fit_kwargs:
2022-04-17 19:24:21,527:WARNING:Traceback (most recent call last):
  File "C:\Users\8prab\.conda\envs\ee\lib\site-packages\pycaret\internal\tabular.py", line 2203, in compare_models
    model, model_fit_time = create_model_supervised(**create_model_args)
  File "C:\Users\8prab\.conda\envs\ee\lib\site-packages\pycaret\internal\tabular.py", line 3200, in create_model_supervised
    scores = cross_validate(
  File "C:\Users\8prab\.conda\envs\ee\lib\site-packages\sklearn\utils\validation.py", line 72, in inner_f
    return f(**kwargs)
  File "C:\Users\8prab\.conda\envs\ee\lib\site-packages\sklearn\model_selection\_validation.py", line 242, in cross_validate
    scores = parallel(
  File "C:\Users\8prab\AppData\Roaming\Python\Python38\site-packages\joblib\parallel.py", line 968, in __call__
    n_jobs = self._initialize_backend()
  File "C:\Users\8prab\AppData\Roaming\Python\Python38\site-packages\joblib\parallel.py", line 735, in _initialize_backend
    n_jobs = self._backend.configure(n_jobs=self.n_jobs, parallel=self,
  File "C:\Users\8prab\AppData\Roaming\Python\Python38\site-packages\joblib\_parallel_backends.py", line 494, in configure
    self._workers = get_memmapping_executor(
  File "C:\Users\8prab\AppData\Roaming\Python\Python38\site-packages\joblib\executor.py", line 20, in get_memmapping_executor
    return MemmappingExecutor.get_memmapping_executor(n_jobs, **kwargs)
  File "C:\Users\8prab\AppData\Roaming\Python\Python38\site-packages\joblib\executor.py", line 42, in get_memmapping_executor
    manager = TemporaryResourcesManager(temp_folder)
  File "C:\Users\8prab\AppData\Roaming\Python\Python38\site-packages\joblib\_memmapping_reducer.py", line 531, in __init__
    self.set_current_context(context_id)
  File "C:\Users\8prab\AppData\Roaming\Python\Python38\site-packages\joblib\_memmapping_reducer.py", line 535, in set_current_context
    self.register_new_context(context_id)
  File "C:\Users\8prab\AppData\Roaming\Python\Python38\site-packages\joblib\_memmapping_reducer.py", line 560, in register_new_context
    self.register_folder_finalizer(new_folder_path, context_id)
  File "C:\Users\8prab\AppData\Roaming\Python\Python38\site-packages\joblib\_memmapping_reducer.py", line 590, in register_folder_finalizer
    resource_tracker.register(pool_subfolder, "folder")
  File "C:\Users\8prab\AppData\Roaming\Python\Python38\site-packages\joblib\externals\loky\backend\resource_tracker.py", line 190, in register
    self.ensure_running()
  File "C:\Users\8prab\AppData\Roaming\Python\Python38\site-packages\joblib\externals\loky\backend\resource_tracker.py", line 102, in ensure_running
    if self._check_alive():
  File "C:\Users\8prab\AppData\Roaming\Python\Python38\site-packages\joblib\externals\loky\backend\resource_tracker.py", line 182, in _check_alive
    self._send('PROBE', '', '')
  File "C:\Users\8prab\AppData\Roaming\Python\Python38\site-packages\joblib\externals\loky\backend\resource_tracker.py", line 209, in _send
    nbytes = os.write(self._fd, msg)
OSError: [Errno 22] Invalid argument

2022-04-17 19:24:21,529:INFO:Initializing create_model()
2022-04-17 19:24:21,531:INFO:create_model(estimator=knn, fold=StratifiedKFold(n_splits=10, random_state=None, shuffle=False), round=4, cross_validation=True, predict=True, fit_kwargs={}, groups=None, refit=False, verbose=False, system=False, metrics=None, experiment_custom_tags=None, add_to_model_list=True, probability_threshold=None, display=<pycaret.internal.Display.Display object at 0x000001D75ACFC490>, return_train_score=False, kwargs={})
2022-04-17 19:24:21,534:INFO:Checking exceptions
2022-04-17 19:24:21,536:INFO:Importing libraries
2022-04-17 19:24:21,538:INFO:Copying training dataset
2022-04-17 19:24:21,581:INFO:Defining folds
2022-04-17 19:24:21,583:INFO:Declaring metric variables
2022-04-17 19:24:21,604:INFO:Importing untrained model
2022-04-17 19:24:21,628:INFO:K Neighbors Classifier Imported succesfully
2022-04-17 19:24:21,675:INFO:Starting cross validation
2022-04-17 19:24:21,678:INFO:Cross validating with StratifiedKFold(n_splits=10, random_state=None, shuffle=False), n_jobs=-1
2022-04-17 19:24:21,681:ERROR:create_model() for knn raised an exception or returned all 0.0:
2022-04-17 19:24:21,692:ERROR:Traceback (most recent call last):
  File "C:\Users\8prab\.conda\envs\ee\lib\site-packages\pycaret\internal\tabular.py", line 2203, in compare_models
    model, model_fit_time = create_model_supervised(**create_model_args)
  File "C:\Users\8prab\.conda\envs\ee\lib\site-packages\pycaret\internal\tabular.py", line 3200, in create_model_supervised
    scores = cross_validate(
  File "C:\Users\8prab\.conda\envs\ee\lib\site-packages\sklearn\utils\validation.py", line 72, in inner_f
    return f(**kwargs)
  File "C:\Users\8prab\.conda\envs\ee\lib\site-packages\sklearn\model_selection\_validation.py", line 242, in cross_validate
    scores = parallel(
  File "C:\Users\8prab\AppData\Roaming\Python\Python38\site-packages\joblib\parallel.py", line 968, in __call__
    n_jobs = self._initialize_backend()
  File "C:\Users\8prab\AppData\Roaming\Python\Python38\site-packages\joblib\parallel.py", line 735, in _initialize_backend
    n_jobs = self._backend.configure(n_jobs=self.n_jobs, parallel=self,
  File "C:\Users\8prab\AppData\Roaming\Python\Python38\site-packages\joblib\_parallel_backends.py", line 494, in configure
    self._workers = get_memmapping_executor(
  File "C:\Users\8prab\AppData\Roaming\Python\Python38\site-packages\joblib\executor.py", line 20, in get_memmapping_executor
    return MemmappingExecutor.get_memmapping_executor(n_jobs, **kwargs)
  File "C:\Users\8prab\AppData\Roaming\Python\Python38\site-packages\joblib\executor.py", line 42, in get_memmapping_executor
    manager = TemporaryResourcesManager(temp_folder)
  File "C:\Users\8prab\AppData\Roaming\Python\Python38\site-packages\joblib\_memmapping_reducer.py", line 531, in __init__
    self.set_current_context(context_id)
  File "C:\Users\8prab\AppData\Roaming\Python\Python38\site-packages\joblib\_memmapping_reducer.py", line 535, in set_current_context
    self.register_new_context(context_id)
  File "C:\Users\8prab\AppData\Roaming\Python\Python38\site-packages\joblib\_memmapping_reducer.py", line 560, in register_new_context
    self.register_folder_finalizer(new_folder_path, context_id)
  File "C:\Users\8prab\AppData\Roaming\Python\Python38\site-packages\joblib\_memmapping_reducer.py", line 590, in register_folder_finalizer
    resource_tracker.register(pool_subfolder, "folder")
  File "C:\Users\8prab\AppData\Roaming\Python\Python38\site-packages\joblib\externals\loky\backend\resource_tracker.py", line 190, in register
    self.ensure_running()
  File "C:\Users\8prab\AppData\Roaming\Python\Python38\site-packages\joblib\externals\loky\backend\resource_tracker.py", line 102, in ensure_running
    if self._check_alive():
  File "C:\Users\8prab\AppData\Roaming\Python\Python38\site-packages\joblib\externals\loky\backend\resource_tracker.py", line 182, in _check_alive
    self._send('PROBE', '', '')
  File "C:\Users\8prab\AppData\Roaming\Python\Python38\site-packages\joblib\externals\loky\backend\resource_tracker.py", line 209, in _send
    nbytes = os.write(self._fd, msg)
OSError: [Errno 22] Invalid argument

During handling of the above exception, another exception occurred:

Traceback (most recent call last):
  File "C:\Users\8prab\.conda\envs\ee\lib\site-packages\pycaret\internal\tabular.py", line 2212, in compare_models
    model, model_fit_time = create_model_supervised(**create_model_args)
  File "C:\Users\8prab\.conda\envs\ee\lib\site-packages\pycaret\internal\tabular.py", line 3200, in create_model_supervised
    scores = cross_validate(
  File "C:\Users\8prab\.conda\envs\ee\lib\site-packages\sklearn\utils\validation.py", line 72, in inner_f
    return f(**kwargs)
  File "C:\Users\8prab\.conda\envs\ee\lib\site-packages\sklearn\model_selection\_validation.py", line 242, in cross_validate
    scores = parallel(
  File "C:\Users\8prab\AppData\Roaming\Python\Python38\site-packages\joblib\parallel.py", line 968, in __call__
    n_jobs = self._initialize_backend()
  File "C:\Users\8prab\AppData\Roaming\Python\Python38\site-packages\joblib\parallel.py", line 735, in _initialize_backend
    n_jobs = self._backend.configure(n_jobs=self.n_jobs, parallel=self,
  File "C:\Users\8prab\AppData\Roaming\Python\Python38\site-packages\joblib\_parallel_backends.py", line 494, in configure
    self._workers = get_memmapping_executor(
  File "C:\Users\8prab\AppData\Roaming\Python\Python38\site-packages\joblib\executor.py", line 20, in get_memmapping_executor
    return MemmappingExecutor.get_memmapping_executor(n_jobs, **kwargs)
  File "C:\Users\8prab\AppData\Roaming\Python\Python38\site-packages\joblib\executor.py", line 42, in get_memmapping_executor
    manager = TemporaryResourcesManager(temp_folder)
  File "C:\Users\8prab\AppData\Roaming\Python\Python38\site-packages\joblib\_memmapping_reducer.py", line 531, in __init__
    self.set_current_context(context_id)
  File "C:\Users\8prab\AppData\Roaming\Python\Python38\site-packages\joblib\_memmapping_reducer.py", line 535, in set_current_context
    self.register_new_context(context_id)
  File "C:\Users\8prab\AppData\Roaming\Python\Python38\site-packages\joblib\_memmapping_reducer.py", line 560, in register_new_context
    self.register_folder_finalizer(new_folder_path, context_id)
  File "C:\Users\8prab\AppData\Roaming\Python\Python38\site-packages\joblib\_memmapping_reducer.py", line 590, in register_folder_finalizer
    resource_tracker.register(pool_subfolder, "folder")
  File "C:\Users\8prab\AppData\Roaming\Python\Python38\site-packages\joblib\externals\loky\backend\resource_tracker.py", line 190, in register
    self.ensure_running()
  File "C:\Users\8prab\AppData\Roaming\Python\Python38\site-packages\joblib\externals\loky\backend\resource_tracker.py", line 102, in ensure_running
    if self._check_alive():
  File "C:\Users\8prab\AppData\Roaming\Python\Python38\site-packages\joblib\externals\loky\backend\resource_tracker.py", line 182, in _check_alive
    self._send('PROBE', '', '')
  File "C:\Users\8prab\AppData\Roaming\Python\Python38\site-packages\joblib\externals\loky\backend\resource_tracker.py", line 209, in _send
    nbytes = os.write(self._fd, msg)
OSError: [Errno 22] Invalid argument

2022-04-17 19:24:21,728:INFO:Initializing Naive Bayes
2022-04-17 19:24:21,729:INFO:Total runtime is 0.020011818408966063 minutes
2022-04-17 19:24:21,749:INFO:SubProcess create_model() called ==================================
2022-04-17 19:24:21,752:INFO:Initializing create_model()
2022-04-17 19:24:21,755:INFO:create_model(estimator=nb, fold=StratifiedKFold(n_splits=10, random_state=None, shuffle=False), round=4, cross_validation=True, predict=True, fit_kwargs={}, groups=None, refit=False, verbose=False, system=False, metrics=None, experiment_custom_tags=None, add_to_model_list=True, probability_threshold=None, display=<pycaret.internal.Display.Display object at 0x000001D75ACFC490>, return_train_score=False, kwargs={})
2022-04-17 19:24:21,756:INFO:Checking exceptions
2022-04-17 19:24:21,758:INFO:Importing libraries
2022-04-17 19:24:21,759:INFO:Copying training dataset
2022-04-17 19:24:21,839:INFO:Defining folds
2022-04-17 19:24:21,841:INFO:Declaring metric variables
2022-04-17 19:24:21,882:INFO:Importing untrained model
2022-04-17 19:24:21,907:INFO:Naive Bayes Imported succesfully
2022-04-17 19:24:21,958:INFO:Starting cross validation
2022-04-17 19:24:21,961:INFO:Cross validating with StratifiedKFold(n_splits=10, random_state=None, shuffle=False), n_jobs=-1
2022-04-17 19:24:21,968:WARNING:create_model() for nb raised an exception or returned all 0.0, trying without fit_kwargs:
2022-04-17 19:24:21,971:WARNING:Traceback (most recent call last):
  File "C:\Users\8prab\.conda\envs\ee\lib\site-packages\pycaret\internal\tabular.py", line 2203, in compare_models
    model, model_fit_time = create_model_supervised(**create_model_args)
  File "C:\Users\8prab\.conda\envs\ee\lib\site-packages\pycaret\internal\tabular.py", line 3200, in create_model_supervised
    scores = cross_validate(
  File "C:\Users\8prab\.conda\envs\ee\lib\site-packages\sklearn\utils\validation.py", line 72, in inner_f
    return f(**kwargs)
  File "C:\Users\8prab\.conda\envs\ee\lib\site-packages\sklearn\model_selection\_validation.py", line 242, in cross_validate
    scores = parallel(
  File "C:\Users\8prab\AppData\Roaming\Python\Python38\site-packages\joblib\parallel.py", line 968, in __call__
    n_jobs = self._initialize_backend()
  File "C:\Users\8prab\AppData\Roaming\Python\Python38\site-packages\joblib\parallel.py", line 735, in _initialize_backend
    n_jobs = self._backend.configure(n_jobs=self.n_jobs, parallel=self,
  File "C:\Users\8prab\AppData\Roaming\Python\Python38\site-packages\joblib\_parallel_backends.py", line 494, in configure
    self._workers = get_memmapping_executor(
  File "C:\Users\8prab\AppData\Roaming\Python\Python38\site-packages\joblib\executor.py", line 20, in get_memmapping_executor
    return MemmappingExecutor.get_memmapping_executor(n_jobs, **kwargs)
  File "C:\Users\8prab\AppData\Roaming\Python\Python38\site-packages\joblib\executor.py", line 42, in get_memmapping_executor
    manager = TemporaryResourcesManager(temp_folder)
  File "C:\Users\8prab\AppData\Roaming\Python\Python38\site-packages\joblib\_memmapping_reducer.py", line 531, in __init__
    self.set_current_context(context_id)
  File "C:\Users\8prab\AppData\Roaming\Python\Python38\site-packages\joblib\_memmapping_reducer.py", line 535, in set_current_context
    self.register_new_context(context_id)
  File "C:\Users\8prab\AppData\Roaming\Python\Python38\site-packages\joblib\_memmapping_reducer.py", line 560, in register_new_context
    self.register_folder_finalizer(new_folder_path, context_id)
  File "C:\Users\8prab\AppData\Roaming\Python\Python38\site-packages\joblib\_memmapping_reducer.py", line 590, in register_folder_finalizer
    resource_tracker.register(pool_subfolder, "folder")
  File "C:\Users\8prab\AppData\Roaming\Python\Python38\site-packages\joblib\externals\loky\backend\resource_tracker.py", line 190, in register
    self.ensure_running()
  File "C:\Users\8prab\AppData\Roaming\Python\Python38\site-packages\joblib\externals\loky\backend\resource_tracker.py", line 102, in ensure_running
    if self._check_alive():
  File "C:\Users\8prab\AppData\Roaming\Python\Python38\site-packages\joblib\externals\loky\backend\resource_tracker.py", line 182, in _check_alive
    self._send('PROBE', '', '')
  File "C:\Users\8prab\AppData\Roaming\Python\Python38\site-packages\joblib\externals\loky\backend\resource_tracker.py", line 209, in _send
    nbytes = os.write(self._fd, msg)
OSError: [Errno 22] Invalid argument

2022-04-17 19:24:21,974:INFO:Initializing create_model()
2022-04-17 19:24:21,977:INFO:create_model(estimator=nb, fold=StratifiedKFold(n_splits=10, random_state=None, shuffle=False), round=4, cross_validation=True, predict=True, fit_kwargs={}, groups=None, refit=False, verbose=False, system=False, metrics=None, experiment_custom_tags=None, add_to_model_list=True, probability_threshold=None, display=<pycaret.internal.Display.Display object at 0x000001D75ACFC490>, return_train_score=False, kwargs={})
2022-04-17 19:24:21,979:INFO:Checking exceptions
2022-04-17 19:24:21,981:INFO:Importing libraries
2022-04-17 19:24:21,990:INFO:Copying training dataset
2022-04-17 19:24:22,054:INFO:Defining folds
2022-04-17 19:24:22,056:INFO:Declaring metric variables
2022-04-17 19:24:22,086:INFO:Importing untrained model
2022-04-17 19:24:22,111:INFO:Naive Bayes Imported succesfully
2022-04-17 19:24:22,161:INFO:Starting cross validation
2022-04-17 19:24:22,164:INFO:Cross validating with StratifiedKFold(n_splits=10, random_state=None, shuffle=False), n_jobs=-1
2022-04-17 19:24:22,172:ERROR:create_model() for nb raised an exception or returned all 0.0:
2022-04-17 19:24:22,178:ERROR:Traceback (most recent call last):
  File "C:\Users\8prab\.conda\envs\ee\lib\site-packages\pycaret\internal\tabular.py", line 2203, in compare_models
    model, model_fit_time = create_model_supervised(**create_model_args)
  File "C:\Users\8prab\.conda\envs\ee\lib\site-packages\pycaret\internal\tabular.py", line 3200, in create_model_supervised
    scores = cross_validate(
  File "C:\Users\8prab\.conda\envs\ee\lib\site-packages\sklearn\utils\validation.py", line 72, in inner_f
    return f(**kwargs)
  File "C:\Users\8prab\.conda\envs\ee\lib\site-packages\sklearn\model_selection\_validation.py", line 242, in cross_validate
    scores = parallel(
  File "C:\Users\8prab\AppData\Roaming\Python\Python38\site-packages\joblib\parallel.py", line 968, in __call__
    n_jobs = self._initialize_backend()
  File "C:\Users\8prab\AppData\Roaming\Python\Python38\site-packages\joblib\parallel.py", line 735, in _initialize_backend
    n_jobs = self._backend.configure(n_jobs=self.n_jobs, parallel=self,
  File "C:\Users\8prab\AppData\Roaming\Python\Python38\site-packages\joblib\_parallel_backends.py", line 494, in configure
    self._workers = get_memmapping_executor(
  File "C:\Users\8prab\AppData\Roaming\Python\Python38\site-packages\joblib\executor.py", line 20, in get_memmapping_executor
    return MemmappingExecutor.get_memmapping_executor(n_jobs, **kwargs)
  File "C:\Users\8prab\AppData\Roaming\Python\Python38\site-packages\joblib\executor.py", line 42, in get_memmapping_executor
    manager = TemporaryResourcesManager(temp_folder)
  File "C:\Users\8prab\AppData\Roaming\Python\Python38\site-packages\joblib\_memmapping_reducer.py", line 531, in __init__
    self.set_current_context(context_id)
  File "C:\Users\8prab\AppData\Roaming\Python\Python38\site-packages\joblib\_memmapping_reducer.py", line 535, in set_current_context
    self.register_new_context(context_id)
  File "C:\Users\8prab\AppData\Roaming\Python\Python38\site-packages\joblib\_memmapping_reducer.py", line 560, in register_new_context
    self.register_folder_finalizer(new_folder_path, context_id)
  File "C:\Users\8prab\AppData\Roaming\Python\Python38\site-packages\joblib\_memmapping_reducer.py", line 590, in register_folder_finalizer
    resource_tracker.register(pool_subfolder, "folder")
  File "C:\Users\8prab\AppData\Roaming\Python\Python38\site-packages\joblib\externals\loky\backend\resource_tracker.py", line 190, in register
    self.ensure_running()
  File "C:\Users\8prab\AppData\Roaming\Python\Python38\site-packages\joblib\externals\loky\backend\resource_tracker.py", line 102, in ensure_running
    if self._check_alive():
  File "C:\Users\8prab\AppData\Roaming\Python\Python38\site-packages\joblib\externals\loky\backend\resource_tracker.py", line 182, in _check_alive
    self._send('PROBE', '', '')
  File "C:\Users\8prab\AppData\Roaming\Python\Python38\site-packages\joblib\externals\loky\backend\resource_tracker.py", line 209, in _send
    nbytes = os.write(self._fd, msg)
OSError: [Errno 22] Invalid argument

During handling of the above exception, another exception occurred:

Traceback (most recent call last):
  File "C:\Users\8prab\.conda\envs\ee\lib\site-packages\pycaret\internal\tabular.py", line 2212, in compare_models
    model, model_fit_time = create_model_supervised(**create_model_args)
  File "C:\Users\8prab\.conda\envs\ee\lib\site-packages\pycaret\internal\tabular.py", line 3200, in create_model_supervised
    scores = cross_validate(
  File "C:\Users\8prab\.conda\envs\ee\lib\site-packages\sklearn\utils\validation.py", line 72, in inner_f
    return f(**kwargs)
  File "C:\Users\8prab\.conda\envs\ee\lib\site-packages\sklearn\model_selection\_validation.py", line 242, in cross_validate
    scores = parallel(
  File "C:\Users\8prab\AppData\Roaming\Python\Python38\site-packages\joblib\parallel.py", line 968, in __call__
    n_jobs = self._initialize_backend()
  File "C:\Users\8prab\AppData\Roaming\Python\Python38\site-packages\joblib\parallel.py", line 735, in _initialize_backend
    n_jobs = self._backend.configure(n_jobs=self.n_jobs, parallel=self,
  File "C:\Users\8prab\AppData\Roaming\Python\Python38\site-packages\joblib\_parallel_backends.py", line 494, in configure
    self._workers = get_memmapping_executor(
  File "C:\Users\8prab\AppData\Roaming\Python\Python38\site-packages\joblib\executor.py", line 20, in get_memmapping_executor
    return MemmappingExecutor.get_memmapping_executor(n_jobs, **kwargs)
  File "C:\Users\8prab\AppData\Roaming\Python\Python38\site-packages\joblib\executor.py", line 42, in get_memmapping_executor
    manager = TemporaryResourcesManager(temp_folder)
  File "C:\Users\8prab\AppData\Roaming\Python\Python38\site-packages\joblib\_memmapping_reducer.py", line 531, in __init__
    self.set_current_context(context_id)
  File "C:\Users\8prab\AppData\Roaming\Python\Python38\site-packages\joblib\_memmapping_reducer.py", line 535, in set_current_context
    self.register_new_context(context_id)
  File "C:\Users\8prab\AppData\Roaming\Python\Python38\site-packages\joblib\_memmapping_reducer.py", line 560, in register_new_context
    self.register_folder_finalizer(new_folder_path, context_id)
  File "C:\Users\8prab\AppData\Roaming\Python\Python38\site-packages\joblib\_memmapping_reducer.py", line 590, in register_folder_finalizer
    resource_tracker.register(pool_subfolder, "folder")
  File "C:\Users\8prab\AppData\Roaming\Python\Python38\site-packages\joblib\externals\loky\backend\resource_tracker.py", line 190, in register
    self.ensure_running()
  File "C:\Users\8prab\AppData\Roaming\Python\Python38\site-packages\joblib\externals\loky\backend\resource_tracker.py", line 102, in ensure_running
    if self._check_alive():
  File "C:\Users\8prab\AppData\Roaming\Python\Python38\site-packages\joblib\externals\loky\backend\resource_tracker.py", line 182, in _check_alive
    self._send('PROBE', '', '')
  File "C:\Users\8prab\AppData\Roaming\Python\Python38\site-packages\joblib\externals\loky\backend\resource_tracker.py", line 209, in _send
    nbytes = os.write(self._fd, msg)
OSError: [Errno 22] Invalid argument

2022-04-17 19:24:22,215:INFO:Initializing Decision Tree Classifier
2022-04-17 19:24:22,218:INFO:Total runtime is 0.028173247973124184 minutes
2022-04-17 19:24:22,244:INFO:SubProcess create_model() called ==================================
2022-04-17 19:24:22,247:INFO:Initializing create_model()
2022-04-17 19:24:22,248:INFO:create_model(estimator=dt, fold=StratifiedKFold(n_splits=10, random_state=None, shuffle=False), round=4, cross_validation=True, predict=True, fit_kwargs={}, groups=None, refit=False, verbose=False, system=False, metrics=None, experiment_custom_tags=None, add_to_model_list=True, probability_threshold=None, display=<pycaret.internal.Display.Display object at 0x000001D75ACFC490>, return_train_score=False, kwargs={})
2022-04-17 19:24:22,253:INFO:Checking exceptions
2022-04-17 19:24:22,257:INFO:Importing libraries
2022-04-17 19:24:22,259:INFO:Copying training dataset
2022-04-17 19:24:22,339:INFO:Defining folds
2022-04-17 19:24:22,342:INFO:Declaring metric variables
2022-04-17 19:24:22,368:INFO:Importing untrained model
2022-04-17 19:24:22,398:INFO:Decision Tree Classifier Imported succesfully
2022-04-17 19:24:22,454:INFO:Starting cross validation
2022-04-17 19:24:22,461:INFO:Cross validating with StratifiedKFold(n_splits=10, random_state=None, shuffle=False), n_jobs=-1
2022-04-17 19:24:22,464:WARNING:create_model() for dt raised an exception or returned all 0.0, trying without fit_kwargs:
2022-04-17 19:24:22,470:WARNING:Traceback (most recent call last):
  File "C:\Users\8prab\.conda\envs\ee\lib\site-packages\pycaret\internal\tabular.py", line 2203, in compare_models
    model, model_fit_time = create_model_supervised(**create_model_args)
  File "C:\Users\8prab\.conda\envs\ee\lib\site-packages\pycaret\internal\tabular.py", line 3200, in create_model_supervised
    scores = cross_validate(
  File "C:\Users\8prab\.conda\envs\ee\lib\site-packages\sklearn\utils\validation.py", line 72, in inner_f
    return f(**kwargs)
  File "C:\Users\8prab\.conda\envs\ee\lib\site-packages\sklearn\model_selection\_validation.py", line 242, in cross_validate
    scores = parallel(
  File "C:\Users\8prab\AppData\Roaming\Python\Python38\site-packages\joblib\parallel.py", line 968, in __call__
    n_jobs = self._initialize_backend()
  File "C:\Users\8prab\AppData\Roaming\Python\Python38\site-packages\joblib\parallel.py", line 735, in _initialize_backend
    n_jobs = self._backend.configure(n_jobs=self.n_jobs, parallel=self,
  File "C:\Users\8prab\AppData\Roaming\Python\Python38\site-packages\joblib\_parallel_backends.py", line 494, in configure
    self._workers = get_memmapping_executor(
  File "C:\Users\8prab\AppData\Roaming\Python\Python38\site-packages\joblib\executor.py", line 20, in get_memmapping_executor
    return MemmappingExecutor.get_memmapping_executor(n_jobs, **kwargs)
  File "C:\Users\8prab\AppData\Roaming\Python\Python38\site-packages\joblib\executor.py", line 42, in get_memmapping_executor
    manager = TemporaryResourcesManager(temp_folder)
  File "C:\Users\8prab\AppData\Roaming\Python\Python38\site-packages\joblib\_memmapping_reducer.py", line 531, in __init__
    self.set_current_context(context_id)
  File "C:\Users\8prab\AppData\Roaming\Python\Python38\site-packages\joblib\_memmapping_reducer.py", line 535, in set_current_context
    self.register_new_context(context_id)
  File "C:\Users\8prab\AppData\Roaming\Python\Python38\site-packages\joblib\_memmapping_reducer.py", line 560, in register_new_context
    self.register_folder_finalizer(new_folder_path, context_id)
  File "C:\Users\8prab\AppData\Roaming\Python\Python38\site-packages\joblib\_memmapping_reducer.py", line 590, in register_folder_finalizer
    resource_tracker.register(pool_subfolder, "folder")
  File "C:\Users\8prab\AppData\Roaming\Python\Python38\site-packages\joblib\externals\loky\backend\resource_tracker.py", line 190, in register
    self.ensure_running()
  File "C:\Users\8prab\AppData\Roaming\Python\Python38\site-packages\joblib\externals\loky\backend\resource_tracker.py", line 102, in ensure_running
    if self._check_alive():
  File "C:\Users\8prab\AppData\Roaming\Python\Python38\site-packages\joblib\externals\loky\backend\resource_tracker.py", line 182, in _check_alive
    self._send('PROBE', '', '')
  File "C:\Users\8prab\AppData\Roaming\Python\Python38\site-packages\joblib\externals\loky\backend\resource_tracker.py", line 209, in _send
    nbytes = os.write(self._fd, msg)
OSError: [Errno 22] Invalid argument

2022-04-17 19:24:22,477:INFO:Initializing create_model()
2022-04-17 19:24:22,479:INFO:create_model(estimator=dt, fold=StratifiedKFold(n_splits=10, random_state=None, shuffle=False), round=4, cross_validation=True, predict=True, fit_kwargs={}, groups=None, refit=False, verbose=False, system=False, metrics=None, experiment_custom_tags=None, add_to_model_list=True, probability_threshold=None, display=<pycaret.internal.Display.Display object at 0x000001D75ACFC490>, return_train_score=False, kwargs={})
2022-04-17 19:24:22,481:INFO:Checking exceptions
2022-04-17 19:24:22,483:INFO:Importing libraries
2022-04-17 19:24:22,491:INFO:Copying training dataset
2022-04-17 19:24:22,554:INFO:Defining folds
2022-04-17 19:24:22,559:INFO:Declaring metric variables
2022-04-17 19:24:22,581:INFO:Importing untrained model
2022-04-17 19:24:22,611:INFO:Decision Tree Classifier Imported succesfully
2022-04-17 19:24:22,659:INFO:Starting cross validation
2022-04-17 19:24:22,661:INFO:Cross validating with StratifiedKFold(n_splits=10, random_state=None, shuffle=False), n_jobs=-1
2022-04-17 19:24:22,664:ERROR:create_model() for dt raised an exception or returned all 0.0:
2022-04-17 19:24:22,675:ERROR:Traceback (most recent call last):
  File "C:\Users\8prab\.conda\envs\ee\lib\site-packages\pycaret\internal\tabular.py", line 2203, in compare_models
    model, model_fit_time = create_model_supervised(**create_model_args)
  File "C:\Users\8prab\.conda\envs\ee\lib\site-packages\pycaret\internal\tabular.py", line 3200, in create_model_supervised
    scores = cross_validate(
  File "C:\Users\8prab\.conda\envs\ee\lib\site-packages\sklearn\utils\validation.py", line 72, in inner_f
    return f(**kwargs)
  File "C:\Users\8prab\.conda\envs\ee\lib\site-packages\sklearn\model_selection\_validation.py", line 242, in cross_validate
    scores = parallel(
  File "C:\Users\8prab\AppData\Roaming\Python\Python38\site-packages\joblib\parallel.py", line 968, in __call__
    n_jobs = self._initialize_backend()
  File "C:\Users\8prab\AppData\Roaming\Python\Python38\site-packages\joblib\parallel.py", line 735, in _initialize_backend
    n_jobs = self._backend.configure(n_jobs=self.n_jobs, parallel=self,
  File "C:\Users\8prab\AppData\Roaming\Python\Python38\site-packages\joblib\_parallel_backends.py", line 494, in configure
    self._workers = get_memmapping_executor(
  File "C:\Users\8prab\AppData\Roaming\Python\Python38\site-packages\joblib\executor.py", line 20, in get_memmapping_executor
    return MemmappingExecutor.get_memmapping_executor(n_jobs, **kwargs)
  File "C:\Users\8prab\AppData\Roaming\Python\Python38\site-packages\joblib\executor.py", line 42, in get_memmapping_executor
    manager = TemporaryResourcesManager(temp_folder)
  File "C:\Users\8prab\AppData\Roaming\Python\Python38\site-packages\joblib\_memmapping_reducer.py", line 531, in __init__
    self.set_current_context(context_id)
  File "C:\Users\8prab\AppData\Roaming\Python\Python38\site-packages\joblib\_memmapping_reducer.py", line 535, in set_current_context
    self.register_new_context(context_id)
  File "C:\Users\8prab\AppData\Roaming\Python\Python38\site-packages\joblib\_memmapping_reducer.py", line 560, in register_new_context
    self.register_folder_finalizer(new_folder_path, context_id)
  File "C:\Users\8prab\AppData\Roaming\Python\Python38\site-packages\joblib\_memmapping_reducer.py", line 590, in register_folder_finalizer
    resource_tracker.register(pool_subfolder, "folder")
  File "C:\Users\8prab\AppData\Roaming\Python\Python38\site-packages\joblib\externals\loky\backend\resource_tracker.py", line 190, in register
    self.ensure_running()
  File "C:\Users\8prab\AppData\Roaming\Python\Python38\site-packages\joblib\externals\loky\backend\resource_tracker.py", line 102, in ensure_running
    if self._check_alive():
  File "C:\Users\8prab\AppData\Roaming\Python\Python38\site-packages\joblib\externals\loky\backend\resource_tracker.py", line 182, in _check_alive
    self._send('PROBE', '', '')
  File "C:\Users\8prab\AppData\Roaming\Python\Python38\site-packages\joblib\externals\loky\backend\resource_tracker.py", line 209, in _send
    nbytes = os.write(self._fd, msg)
OSError: [Errno 22] Invalid argument

During handling of the above exception, another exception occurred:

Traceback (most recent call last):
  File "C:\Users\8prab\.conda\envs\ee\lib\site-packages\pycaret\internal\tabular.py", line 2212, in compare_models
    model, model_fit_time = create_model_supervised(**create_model_args)
  File "C:\Users\8prab\.conda\envs\ee\lib\site-packages\pycaret\internal\tabular.py", line 3200, in create_model_supervised
    scores = cross_validate(
  File "C:\Users\8prab\.conda\envs\ee\lib\site-packages\sklearn\utils\validation.py", line 72, in inner_f
    return f(**kwargs)
  File "C:\Users\8prab\.conda\envs\ee\lib\site-packages\sklearn\model_selection\_validation.py", line 242, in cross_validate
    scores = parallel(
  File "C:\Users\8prab\AppData\Roaming\Python\Python38\site-packages\joblib\parallel.py", line 968, in __call__
    n_jobs = self._initialize_backend()
  File "C:\Users\8prab\AppData\Roaming\Python\Python38\site-packages\joblib\parallel.py", line 735, in _initialize_backend
    n_jobs = self._backend.configure(n_jobs=self.n_jobs, parallel=self,
  File "C:\Users\8prab\AppData\Roaming\Python\Python38\site-packages\joblib\_parallel_backends.py", line 494, in configure
    self._workers = get_memmapping_executor(
  File "C:\Users\8prab\AppData\Roaming\Python\Python38\site-packages\joblib\executor.py", line 20, in get_memmapping_executor
    return MemmappingExecutor.get_memmapping_executor(n_jobs, **kwargs)
  File "C:\Users\8prab\AppData\Roaming\Python\Python38\site-packages\joblib\executor.py", line 42, in get_memmapping_executor
    manager = TemporaryResourcesManager(temp_folder)
  File "C:\Users\8prab\AppData\Roaming\Python\Python38\site-packages\joblib\_memmapping_reducer.py", line 531, in __init__
    self.set_current_context(context_id)
  File "C:\Users\8prab\AppData\Roaming\Python\Python38\site-packages\joblib\_memmapping_reducer.py", line 535, in set_current_context
    self.register_new_context(context_id)
  File "C:\Users\8prab\AppData\Roaming\Python\Python38\site-packages\joblib\_memmapping_reducer.py", line 560, in register_new_context
    self.register_folder_finalizer(new_folder_path, context_id)
  File "C:\Users\8prab\AppData\Roaming\Python\Python38\site-packages\joblib\_memmapping_reducer.py", line 590, in register_folder_finalizer
    resource_tracker.register(pool_subfolder, "folder")
  File "C:\Users\8prab\AppData\Roaming\Python\Python38\site-packages\joblib\externals\loky\backend\resource_tracker.py", line 190, in register
    self.ensure_running()
  File "C:\Users\8prab\AppData\Roaming\Python\Python38\site-packages\joblib\externals\loky\backend\resource_tracker.py", line 102, in ensure_running
    if self._check_alive():
  File "C:\Users\8prab\AppData\Roaming\Python\Python38\site-packages\joblib\externals\loky\backend\resource_tracker.py", line 182, in _check_alive
    self._send('PROBE', '', '')
  File "C:\Users\8prab\AppData\Roaming\Python\Python38\site-packages\joblib\externals\loky\backend\resource_tracker.py", line 209, in _send
    nbytes = os.write(self._fd, msg)
OSError: [Errno 22] Invalid argument

2022-04-17 19:24:22,710:INFO:Initializing SVM - Linear Kernel
2022-04-17 19:24:22,712:INFO:Total runtime is 0.03640045324961344 minutes
2022-04-17 19:24:22,737:INFO:SubProcess create_model() called ==================================
2022-04-17 19:24:22,739:INFO:Initializing create_model()
2022-04-17 19:24:22,741:INFO:create_model(estimator=svm, fold=StratifiedKFold(n_splits=10, random_state=None, shuffle=False), round=4, cross_validation=True, predict=True, fit_kwargs={}, groups=None, refit=False, verbose=False, system=False, metrics=None, experiment_custom_tags=None, add_to_model_list=True, probability_threshold=None, display=<pycaret.internal.Display.Display object at 0x000001D75ACFC490>, return_train_score=False, kwargs={})
2022-04-17 19:24:22,742:INFO:Checking exceptions
2022-04-17 19:24:22,744:INFO:Importing libraries
2022-04-17 19:24:22,745:INFO:Copying training dataset
2022-04-17 19:24:22,805:INFO:Defining folds
2022-04-17 19:24:22,807:INFO:Declaring metric variables
2022-04-17 19:24:22,828:INFO:Importing untrained model
2022-04-17 19:24:22,867:INFO:SVM - Linear Kernel Imported succesfully
2022-04-17 19:24:22,917:INFO:Starting cross validation
2022-04-17 19:24:22,924:INFO:Cross validating with StratifiedKFold(n_splits=10, random_state=None, shuffle=False), n_jobs=-1
2022-04-17 19:24:22,928:WARNING:create_model() for svm raised an exception or returned all 0.0, trying without fit_kwargs:
2022-04-17 19:24:22,932:WARNING:Traceback (most recent call last):
  File "C:\Users\8prab\.conda\envs\ee\lib\site-packages\pycaret\internal\tabular.py", line 2203, in compare_models
    model, model_fit_time = create_model_supervised(**create_model_args)
  File "C:\Users\8prab\.conda\envs\ee\lib\site-packages\pycaret\internal\tabular.py", line 3200, in create_model_supervised
    scores = cross_validate(
  File "C:\Users\8prab\.conda\envs\ee\lib\site-packages\sklearn\utils\validation.py", line 72, in inner_f
    return f(**kwargs)
  File "C:\Users\8prab\.conda\envs\ee\lib\site-packages\sklearn\model_selection\_validation.py", line 242, in cross_validate
    scores = parallel(
  File "C:\Users\8prab\AppData\Roaming\Python\Python38\site-packages\joblib\parallel.py", line 968, in __call__
    n_jobs = self._initialize_backend()
  File "C:\Users\8prab\AppData\Roaming\Python\Python38\site-packages\joblib\parallel.py", line 735, in _initialize_backend
    n_jobs = self._backend.configure(n_jobs=self.n_jobs, parallel=self,
  File "C:\Users\8prab\AppData\Roaming\Python\Python38\site-packages\joblib\_parallel_backends.py", line 494, in configure
    self._workers = get_memmapping_executor(
  File "C:\Users\8prab\AppData\Roaming\Python\Python38\site-packages\joblib\executor.py", line 20, in get_memmapping_executor
    return MemmappingExecutor.get_memmapping_executor(n_jobs, **kwargs)
  File "C:\Users\8prab\AppData\Roaming\Python\Python38\site-packages\joblib\executor.py", line 42, in get_memmapping_executor
    manager = TemporaryResourcesManager(temp_folder)
  File "C:\Users\8prab\AppData\Roaming\Python\Python38\site-packages\joblib\_memmapping_reducer.py", line 531, in __init__
    self.set_current_context(context_id)
  File "C:\Users\8prab\AppData\Roaming\Python\Python38\site-packages\joblib\_memmapping_reducer.py", line 535, in set_current_context
    self.register_new_context(context_id)
  File "C:\Users\8prab\AppData\Roaming\Python\Python38\site-packages\joblib\_memmapping_reducer.py", line 560, in register_new_context
    self.register_folder_finalizer(new_folder_path, context_id)
  File "C:\Users\8prab\AppData\Roaming\Python\Python38\site-packages\joblib\_memmapping_reducer.py", line 590, in register_folder_finalizer
    resource_tracker.register(pool_subfolder, "folder")
  File "C:\Users\8prab\AppData\Roaming\Python\Python38\site-packages\joblib\externals\loky\backend\resource_tracker.py", line 190, in register
    self.ensure_running()
  File "C:\Users\8prab\AppData\Roaming\Python\Python38\site-packages\joblib\externals\loky\backend\resource_tracker.py", line 102, in ensure_running
    if self._check_alive():
  File "C:\Users\8prab\AppData\Roaming\Python\Python38\site-packages\joblib\externals\loky\backend\resource_tracker.py", line 182, in _check_alive
    self._send('PROBE', '', '')
  File "C:\Users\8prab\AppData\Roaming\Python\Python38\site-packages\joblib\externals\loky\backend\resource_tracker.py", line 209, in _send
    nbytes = os.write(self._fd, msg)
OSError: [Errno 22] Invalid argument

2022-04-17 19:24:22,935:INFO:Initializing create_model()
2022-04-17 19:24:22,939:INFO:create_model(estimator=svm, fold=StratifiedKFold(n_splits=10, random_state=None, shuffle=False), round=4, cross_validation=True, predict=True, fit_kwargs={}, groups=None, refit=False, verbose=False, system=False, metrics=None, experiment_custom_tags=None, add_to_model_list=True, probability_threshold=None, display=<pycaret.internal.Display.Display object at 0x000001D75ACFC490>, return_train_score=False, kwargs={})
2022-04-17 19:24:22,942:INFO:Checking exceptions
2022-04-17 19:24:22,943:INFO:Importing libraries
2022-04-17 19:24:22,945:INFO:Copying training dataset
2022-04-17 19:24:23,044:INFO:Defining folds
2022-04-17 19:24:23,046:INFO:Declaring metric variables
2022-04-17 19:24:23,063:INFO:Importing untrained model
2022-04-17 19:24:23,081:INFO:SVM - Linear Kernel Imported succesfully
2022-04-17 19:24:23,110:INFO:Starting cross validation
2022-04-17 19:24:23,112:INFO:Cross validating with StratifiedKFold(n_splits=10, random_state=None, shuffle=False), n_jobs=-1
2022-04-17 19:24:23,119:ERROR:create_model() for svm raised an exception or returned all 0.0:
2022-04-17 19:24:23,129:ERROR:Traceback (most recent call last):
  File "C:\Users\8prab\.conda\envs\ee\lib\site-packages\pycaret\internal\tabular.py", line 2203, in compare_models
    model, model_fit_time = create_model_supervised(**create_model_args)
  File "C:\Users\8prab\.conda\envs\ee\lib\site-packages\pycaret\internal\tabular.py", line 3200, in create_model_supervised
    scores = cross_validate(
  File "C:\Users\8prab\.conda\envs\ee\lib\site-packages\sklearn\utils\validation.py", line 72, in inner_f
    return f(**kwargs)
  File "C:\Users\8prab\.conda\envs\ee\lib\site-packages\sklearn\model_selection\_validation.py", line 242, in cross_validate
    scores = parallel(
  File "C:\Users\8prab\AppData\Roaming\Python\Python38\site-packages\joblib\parallel.py", line 968, in __call__
    n_jobs = self._initialize_backend()
  File "C:\Users\8prab\AppData\Roaming\Python\Python38\site-packages\joblib\parallel.py", line 735, in _initialize_backend
    n_jobs = self._backend.configure(n_jobs=self.n_jobs, parallel=self,
  File "C:\Users\8prab\AppData\Roaming\Python\Python38\site-packages\joblib\_parallel_backends.py", line 494, in configure
    self._workers = get_memmapping_executor(
  File "C:\Users\8prab\AppData\Roaming\Python\Python38\site-packages\joblib\executor.py", line 20, in get_memmapping_executor
    return MemmappingExecutor.get_memmapping_executor(n_jobs, **kwargs)
  File "C:\Users\8prab\AppData\Roaming\Python\Python38\site-packages\joblib\executor.py", line 42, in get_memmapping_executor
    manager = TemporaryResourcesManager(temp_folder)
  File "C:\Users\8prab\AppData\Roaming\Python\Python38\site-packages\joblib\_memmapping_reducer.py", line 531, in __init__
    self.set_current_context(context_id)
  File "C:\Users\8prab\AppData\Roaming\Python\Python38\site-packages\joblib\_memmapping_reducer.py", line 535, in set_current_context
    self.register_new_context(context_id)
  File "C:\Users\8prab\AppData\Roaming\Python\Python38\site-packages\joblib\_memmapping_reducer.py", line 560, in register_new_context
    self.register_folder_finalizer(new_folder_path, context_id)
  File "C:\Users\8prab\AppData\Roaming\Python\Python38\site-packages\joblib\_memmapping_reducer.py", line 590, in register_folder_finalizer
    resource_tracker.register(pool_subfolder, "folder")
  File "C:\Users\8prab\AppData\Roaming\Python\Python38\site-packages\joblib\externals\loky\backend\resource_tracker.py", line 190, in register
    self.ensure_running()
  File "C:\Users\8prab\AppData\Roaming\Python\Python38\site-packages\joblib\externals\loky\backend\resource_tracker.py", line 102, in ensure_running
    if self._check_alive():
  File "C:\Users\8prab\AppData\Roaming\Python\Python38\site-packages\joblib\externals\loky\backend\resource_tracker.py", line 182, in _check_alive
    self._send('PROBE', '', '')
  File "C:\Users\8prab\AppData\Roaming\Python\Python38\site-packages\joblib\externals\loky\backend\resource_tracker.py", line 209, in _send
    nbytes = os.write(self._fd, msg)
OSError: [Errno 22] Invalid argument

During handling of the above exception, another exception occurred:

Traceback (most recent call last):
  File "C:\Users\8prab\.conda\envs\ee\lib\site-packages\pycaret\internal\tabular.py", line 2212, in compare_models
    model, model_fit_time = create_model_supervised(**create_model_args)
  File "C:\Users\8prab\.conda\envs\ee\lib\site-packages\pycaret\internal\tabular.py", line 3200, in create_model_supervised
    scores = cross_validate(
  File "C:\Users\8prab\.conda\envs\ee\lib\site-packages\sklearn\utils\validation.py", line 72, in inner_f
    return f(**kwargs)
  File "C:\Users\8prab\.conda\envs\ee\lib\site-packages\sklearn\model_selection\_validation.py", line 242, in cross_validate
    scores = parallel(
  File "C:\Users\8prab\AppData\Roaming\Python\Python38\site-packages\joblib\parallel.py", line 968, in __call__
    n_jobs = self._initialize_backend()
  File "C:\Users\8prab\AppData\Roaming\Python\Python38\site-packages\joblib\parallel.py", line 735, in _initialize_backend
    n_jobs = self._backend.configure(n_jobs=self.n_jobs, parallel=self,
  File "C:\Users\8prab\AppData\Roaming\Python\Python38\site-packages\joblib\_parallel_backends.py", line 494, in configure
    self._workers = get_memmapping_executor(
  File "C:\Users\8prab\AppData\Roaming\Python\Python38\site-packages\joblib\executor.py", line 20, in get_memmapping_executor
    return MemmappingExecutor.get_memmapping_executor(n_jobs, **kwargs)
  File "C:\Users\8prab\AppData\Roaming\Python\Python38\site-packages\joblib\executor.py", line 42, in get_memmapping_executor
    manager = TemporaryResourcesManager(temp_folder)
  File "C:\Users\8prab\AppData\Roaming\Python\Python38\site-packages\joblib\_memmapping_reducer.py", line 531, in __init__
    self.set_current_context(context_id)
  File "C:\Users\8prab\AppData\Roaming\Python\Python38\site-packages\joblib\_memmapping_reducer.py", line 535, in set_current_context
    self.register_new_context(context_id)
  File "C:\Users\8prab\AppData\Roaming\Python\Python38\site-packages\joblib\_memmapping_reducer.py", line 560, in register_new_context
    self.register_folder_finalizer(new_folder_path, context_id)
  File "C:\Users\8prab\AppData\Roaming\Python\Python38\site-packages\joblib\_memmapping_reducer.py", line 590, in register_folder_finalizer
    resource_tracker.register(pool_subfolder, "folder")
  File "C:\Users\8prab\AppData\Roaming\Python\Python38\site-packages\joblib\externals\loky\backend\resource_tracker.py", line 190, in register
    self.ensure_running()
  File "C:\Users\8prab\AppData\Roaming\Python\Python38\site-packages\joblib\externals\loky\backend\resource_tracker.py", line 102, in ensure_running
    if self._check_alive():
  File "C:\Users\8prab\AppData\Roaming\Python\Python38\site-packages\joblib\externals\loky\backend\resource_tracker.py", line 182, in _check_alive
    self._send('PROBE', '', '')
  File "C:\Users\8prab\AppData\Roaming\Python\Python38\site-packages\joblib\externals\loky\backend\resource_tracker.py", line 209, in _send
    nbytes = os.write(self._fd, msg)
OSError: [Errno 22] Invalid argument

2022-04-17 19:24:23,210:INFO:Initializing Ridge Classifier
2022-04-17 19:24:23,212:INFO:Total runtime is 0.04472773869832356 minutes
2022-04-17 19:24:23,244:INFO:SubProcess create_model() called ==================================
2022-04-17 19:24:23,248:INFO:Initializing create_model()
2022-04-17 19:24:23,257:INFO:create_model(estimator=ridge, fold=StratifiedKFold(n_splits=10, random_state=None, shuffle=False), round=4, cross_validation=True, predict=True, fit_kwargs={}, groups=None, refit=False, verbose=False, system=False, metrics=None, experiment_custom_tags=None, add_to_model_list=True, probability_threshold=None, display=<pycaret.internal.Display.Display object at 0x000001D75ACFC490>, return_train_score=False, kwargs={})
2022-04-17 19:24:23,261:INFO:Checking exceptions
2022-04-17 19:24:23,263:INFO:Importing libraries
2022-04-17 19:24:23,265:INFO:Copying training dataset
2022-04-17 19:24:23,425:INFO:Defining folds
2022-04-17 19:24:23,426:INFO:Declaring metric variables
2022-04-17 19:24:23,488:INFO:Importing untrained model
2022-04-17 19:24:23,515:INFO:Ridge Classifier Imported succesfully
2022-04-17 19:24:23,573:INFO:Starting cross validation
2022-04-17 19:24:23,578:INFO:Cross validating with StratifiedKFold(n_splits=10, random_state=None, shuffle=False), n_jobs=-1
2022-04-17 19:24:23,610:WARNING:create_model() for ridge raised an exception or returned all 0.0, trying without fit_kwargs:
2022-04-17 19:24:23,613:WARNING:Traceback (most recent call last):
  File "C:\Users\8prab\.conda\envs\ee\lib\site-packages\pycaret\internal\tabular.py", line 2203, in compare_models
    model, model_fit_time = create_model_supervised(**create_model_args)
  File "C:\Users\8prab\.conda\envs\ee\lib\site-packages\pycaret\internal\tabular.py", line 3200, in create_model_supervised
    scores = cross_validate(
  File "C:\Users\8prab\.conda\envs\ee\lib\site-packages\sklearn\utils\validation.py", line 72, in inner_f
    return f(**kwargs)
  File "C:\Users\8prab\.conda\envs\ee\lib\site-packages\sklearn\model_selection\_validation.py", line 242, in cross_validate
    scores = parallel(
  File "C:\Users\8prab\AppData\Roaming\Python\Python38\site-packages\joblib\parallel.py", line 968, in __call__
    n_jobs = self._initialize_backend()
  File "C:\Users\8prab\AppData\Roaming\Python\Python38\site-packages\joblib\parallel.py", line 735, in _initialize_backend
    n_jobs = self._backend.configure(n_jobs=self.n_jobs, parallel=self,
  File "C:\Users\8prab\AppData\Roaming\Python\Python38\site-packages\joblib\_parallel_backends.py", line 494, in configure
    self._workers = get_memmapping_executor(
  File "C:\Users\8prab\AppData\Roaming\Python\Python38\site-packages\joblib\executor.py", line 20, in get_memmapping_executor
    return MemmappingExecutor.get_memmapping_executor(n_jobs, **kwargs)
  File "C:\Users\8prab\AppData\Roaming\Python\Python38\site-packages\joblib\executor.py", line 42, in get_memmapping_executor
    manager = TemporaryResourcesManager(temp_folder)
  File "C:\Users\8prab\AppData\Roaming\Python\Python38\site-packages\joblib\_memmapping_reducer.py", line 531, in __init__
    self.set_current_context(context_id)
  File "C:\Users\8prab\AppData\Roaming\Python\Python38\site-packages\joblib\_memmapping_reducer.py", line 535, in set_current_context
    self.register_new_context(context_id)
  File "C:\Users\8prab\AppData\Roaming\Python\Python38\site-packages\joblib\_memmapping_reducer.py", line 560, in register_new_context
    self.register_folder_finalizer(new_folder_path, context_id)
  File "C:\Users\8prab\AppData\Roaming\Python\Python38\site-packages\joblib\_memmapping_reducer.py", line 590, in register_folder_finalizer
    resource_tracker.register(pool_subfolder, "folder")
  File "C:\Users\8prab\AppData\Roaming\Python\Python38\site-packages\joblib\externals\loky\backend\resource_tracker.py", line 190, in register
    self.ensure_running()
  File "C:\Users\8prab\AppData\Roaming\Python\Python38\site-packages\joblib\externals\loky\backend\resource_tracker.py", line 102, in ensure_running
    if self._check_alive():
  File "C:\Users\8prab\AppData\Roaming\Python\Python38\site-packages\joblib\externals\loky\backend\resource_tracker.py", line 182, in _check_alive
    self._send('PROBE', '', '')
  File "C:\Users\8prab\AppData\Roaming\Python\Python38\site-packages\joblib\externals\loky\backend\resource_tracker.py", line 209, in _send
    nbytes = os.write(self._fd, msg)
OSError: [Errno 22] Invalid argument

2022-04-17 19:24:23,616:INFO:Initializing create_model()
2022-04-17 19:24:23,621:INFO:create_model(estimator=ridge, fold=StratifiedKFold(n_splits=10, random_state=None, shuffle=False), round=4, cross_validation=True, predict=True, fit_kwargs={}, groups=None, refit=False, verbose=False, system=False, metrics=None, experiment_custom_tags=None, add_to_model_list=True, probability_threshold=None, display=<pycaret.internal.Display.Display object at 0x000001D75ACFC490>, return_train_score=False, kwargs={})
2022-04-17 19:24:23,625:INFO:Checking exceptions
2022-04-17 19:24:23,628:INFO:Importing libraries
2022-04-17 19:24:23,630:INFO:Copying training dataset
2022-04-17 19:24:23,810:INFO:Defining folds
2022-04-17 19:24:23,812:INFO:Declaring metric variables
2022-04-17 19:24:23,839:INFO:Importing untrained model
2022-04-17 19:24:23,867:INFO:Ridge Classifier Imported succesfully
2022-04-17 19:24:23,917:INFO:Starting cross validation
2022-04-17 19:24:23,923:INFO:Cross validating with StratifiedKFold(n_splits=10, random_state=None, shuffle=False), n_jobs=-1
2022-04-17 19:24:23,928:ERROR:create_model() for ridge raised an exception or returned all 0.0:
2022-04-17 19:24:23,933:ERROR:Traceback (most recent call last):
  File "C:\Users\8prab\.conda\envs\ee\lib\site-packages\pycaret\internal\tabular.py", line 2203, in compare_models
    model, model_fit_time = create_model_supervised(**create_model_args)
  File "C:\Users\8prab\.conda\envs\ee\lib\site-packages\pycaret\internal\tabular.py", line 3200, in create_model_supervised
    scores = cross_validate(
  File "C:\Users\8prab\.conda\envs\ee\lib\site-packages\sklearn\utils\validation.py", line 72, in inner_f
    return f(**kwargs)
  File "C:\Users\8prab\.conda\envs\ee\lib\site-packages\sklearn\model_selection\_validation.py", line 242, in cross_validate
    scores = parallel(
  File "C:\Users\8prab\AppData\Roaming\Python\Python38\site-packages\joblib\parallel.py", line 968, in __call__
    n_jobs = self._initialize_backend()
  File "C:\Users\8prab\AppData\Roaming\Python\Python38\site-packages\joblib\parallel.py", line 735, in _initialize_backend
    n_jobs = self._backend.configure(n_jobs=self.n_jobs, parallel=self,
  File "C:\Users\8prab\AppData\Roaming\Python\Python38\site-packages\joblib\_parallel_backends.py", line 494, in configure
    self._workers = get_memmapping_executor(
  File "C:\Users\8prab\AppData\Roaming\Python\Python38\site-packages\joblib\executor.py", line 20, in get_memmapping_executor
    return MemmappingExecutor.get_memmapping_executor(n_jobs, **kwargs)
  File "C:\Users\8prab\AppData\Roaming\Python\Python38\site-packages\joblib\executor.py", line 42, in get_memmapping_executor
    manager = TemporaryResourcesManager(temp_folder)
  File "C:\Users\8prab\AppData\Roaming\Python\Python38\site-packages\joblib\_memmapping_reducer.py", line 531, in __init__
    self.set_current_context(context_id)
  File "C:\Users\8prab\AppData\Roaming\Python\Python38\site-packages\joblib\_memmapping_reducer.py", line 535, in set_current_context
    self.register_new_context(context_id)
  File "C:\Users\8prab\AppData\Roaming\Python\Python38\site-packages\joblib\_memmapping_reducer.py", line 560, in register_new_context
    self.register_folder_finalizer(new_folder_path, context_id)
  File "C:\Users\8prab\AppData\Roaming\Python\Python38\site-packages\joblib\_memmapping_reducer.py", line 590, in register_folder_finalizer
    resource_tracker.register(pool_subfolder, "folder")
  File "C:\Users\8prab\AppData\Roaming\Python\Python38\site-packages\joblib\externals\loky\backend\resource_tracker.py", line 190, in register
    self.ensure_running()
  File "C:\Users\8prab\AppData\Roaming\Python\Python38\site-packages\joblib\externals\loky\backend\resource_tracker.py", line 102, in ensure_running
    if self._check_alive():
  File "C:\Users\8prab\AppData\Roaming\Python\Python38\site-packages\joblib\externals\loky\backend\resource_tracker.py", line 182, in _check_alive
    self._send('PROBE', '', '')
  File "C:\Users\8prab\AppData\Roaming\Python\Python38\site-packages\joblib\externals\loky\backend\resource_tracker.py", line 209, in _send
    nbytes = os.write(self._fd, msg)
OSError: [Errno 22] Invalid argument

During handling of the above exception, another exception occurred:

Traceback (most recent call last):
  File "C:\Users\8prab\.conda\envs\ee\lib\site-packages\pycaret\internal\tabular.py", line 2212, in compare_models
    model, model_fit_time = create_model_supervised(**create_model_args)
  File "C:\Users\8prab\.conda\envs\ee\lib\site-packages\pycaret\internal\tabular.py", line 3200, in create_model_supervised
    scores = cross_validate(
  File "C:\Users\8prab\.conda\envs\ee\lib\site-packages\sklearn\utils\validation.py", line 72, in inner_f
    return f(**kwargs)
  File "C:\Users\8prab\.conda\envs\ee\lib\site-packages\sklearn\model_selection\_validation.py", line 242, in cross_validate
    scores = parallel(
  File "C:\Users\8prab\AppData\Roaming\Python\Python38\site-packages\joblib\parallel.py", line 968, in __call__
    n_jobs = self._initialize_backend()
  File "C:\Users\8prab\AppData\Roaming\Python\Python38\site-packages\joblib\parallel.py", line 735, in _initialize_backend
    n_jobs = self._backend.configure(n_jobs=self.n_jobs, parallel=self,
  File "C:\Users\8prab\AppData\Roaming\Python\Python38\site-packages\joblib\_parallel_backends.py", line 494, in configure
    self._workers = get_memmapping_executor(
  File "C:\Users\8prab\AppData\Roaming\Python\Python38\site-packages\joblib\executor.py", line 20, in get_memmapping_executor
    return MemmappingExecutor.get_memmapping_executor(n_jobs, **kwargs)
  File "C:\Users\8prab\AppData\Roaming\Python\Python38\site-packages\joblib\executor.py", line 42, in get_memmapping_executor
    manager = TemporaryResourcesManager(temp_folder)
  File "C:\Users\8prab\AppData\Roaming\Python\Python38\site-packages\joblib\_memmapping_reducer.py", line 531, in __init__
    self.set_current_context(context_id)
  File "C:\Users\8prab\AppData\Roaming\Python\Python38\site-packages\joblib\_memmapping_reducer.py", line 535, in set_current_context
    self.register_new_context(context_id)
  File "C:\Users\8prab\AppData\Roaming\Python\Python38\site-packages\joblib\_memmapping_reducer.py", line 560, in register_new_context
    self.register_folder_finalizer(new_folder_path, context_id)
  File "C:\Users\8prab\AppData\Roaming\Python\Python38\site-packages\joblib\_memmapping_reducer.py", line 590, in register_folder_finalizer
    resource_tracker.register(pool_subfolder, "folder")
  File "C:\Users\8prab\AppData\Roaming\Python\Python38\site-packages\joblib\externals\loky\backend\resource_tracker.py", line 190, in register
    self.ensure_running()
  File "C:\Users\8prab\AppData\Roaming\Python\Python38\site-packages\joblib\externals\loky\backend\resource_tracker.py", line 102, in ensure_running
    if self._check_alive():
  File "C:\Users\8prab\AppData\Roaming\Python\Python38\site-packages\joblib\externals\loky\backend\resource_tracker.py", line 182, in _check_alive
    self._send('PROBE', '', '')
  File "C:\Users\8prab\AppData\Roaming\Python\Python38\site-packages\joblib\externals\loky\backend\resource_tracker.py", line 209, in _send
    nbytes = os.write(self._fd, msg)
OSError: [Errno 22] Invalid argument

2022-04-17 19:24:23,966:INFO:Initializing Random Forest Classifier
2022-04-17 19:24:23,970:INFO:Total runtime is 0.05737540324529011 minutes
2022-04-17 19:24:23,998:INFO:SubProcess create_model() called ==================================
2022-04-17 19:24:23,999:INFO:Initializing create_model()
2022-04-17 19:24:24,002:INFO:create_model(estimator=rf, fold=StratifiedKFold(n_splits=10, random_state=None, shuffle=False), round=4, cross_validation=True, predict=True, fit_kwargs={}, groups=None, refit=False, verbose=False, system=False, metrics=None, experiment_custom_tags=None, add_to_model_list=True, probability_threshold=None, display=<pycaret.internal.Display.Display object at 0x000001D75ACFC490>, return_train_score=False, kwargs={})
2022-04-17 19:24:24,005:INFO:Checking exceptions
2022-04-17 19:24:24,008:INFO:Importing libraries
2022-04-17 19:24:24,010:INFO:Copying training dataset
2022-04-17 19:24:24,105:INFO:Defining folds
2022-04-17 19:24:24,107:INFO:Declaring metric variables
2022-04-17 19:24:24,130:INFO:Importing untrained model
2022-04-17 19:24:24,152:INFO:Random Forest Classifier Imported succesfully
2022-04-17 19:24:24,207:INFO:Starting cross validation
2022-04-17 19:24:24,210:INFO:Cross validating with StratifiedKFold(n_splits=10, random_state=None, shuffle=False), n_jobs=-1
2022-04-17 19:24:24,213:WARNING:create_model() for rf raised an exception or returned all 0.0, trying without fit_kwargs:
2022-04-17 19:24:24,219:WARNING:Traceback (most recent call last):
  File "C:\Users\8prab\.conda\envs\ee\lib\site-packages\pycaret\internal\tabular.py", line 2203, in compare_models
    model, model_fit_time = create_model_supervised(**create_model_args)
  File "C:\Users\8prab\.conda\envs\ee\lib\site-packages\pycaret\internal\tabular.py", line 3200, in create_model_supervised
    scores = cross_validate(
  File "C:\Users\8prab\.conda\envs\ee\lib\site-packages\sklearn\utils\validation.py", line 72, in inner_f
    return f(**kwargs)
  File "C:\Users\8prab\.conda\envs\ee\lib\site-packages\sklearn\model_selection\_validation.py", line 242, in cross_validate
    scores = parallel(
  File "C:\Users\8prab\AppData\Roaming\Python\Python38\site-packages\joblib\parallel.py", line 968, in __call__
    n_jobs = self._initialize_backend()
  File "C:\Users\8prab\AppData\Roaming\Python\Python38\site-packages\joblib\parallel.py", line 735, in _initialize_backend
    n_jobs = self._backend.configure(n_jobs=self.n_jobs, parallel=self,
  File "C:\Users\8prab\AppData\Roaming\Python\Python38\site-packages\joblib\_parallel_backends.py", line 494, in configure
    self._workers = get_memmapping_executor(
  File "C:\Users\8prab\AppData\Roaming\Python\Python38\site-packages\joblib\executor.py", line 20, in get_memmapping_executor
    return MemmappingExecutor.get_memmapping_executor(n_jobs, **kwargs)
  File "C:\Users\8prab\AppData\Roaming\Python\Python38\site-packages\joblib\executor.py", line 42, in get_memmapping_executor
    manager = TemporaryResourcesManager(temp_folder)
  File "C:\Users\8prab\AppData\Roaming\Python\Python38\site-packages\joblib\_memmapping_reducer.py", line 531, in __init__
    self.set_current_context(context_id)
  File "C:\Users\8prab\AppData\Roaming\Python\Python38\site-packages\joblib\_memmapping_reducer.py", line 535, in set_current_context
    self.register_new_context(context_id)
  File "C:\Users\8prab\AppData\Roaming\Python\Python38\site-packages\joblib\_memmapping_reducer.py", line 560, in register_new_context
    self.register_folder_finalizer(new_folder_path, context_id)
  File "C:\Users\8prab\AppData\Roaming\Python\Python38\site-packages\joblib\_memmapping_reducer.py", line 590, in register_folder_finalizer
    resource_tracker.register(pool_subfolder, "folder")
  File "C:\Users\8prab\AppData\Roaming\Python\Python38\site-packages\joblib\externals\loky\backend\resource_tracker.py", line 190, in register
    self.ensure_running()
  File "C:\Users\8prab\AppData\Roaming\Python\Python38\site-packages\joblib\externals\loky\backend\resource_tracker.py", line 102, in ensure_running
    if self._check_alive():
  File "C:\Users\8prab\AppData\Roaming\Python\Python38\site-packages\joblib\externals\loky\backend\resource_tracker.py", line 182, in _check_alive
    self._send('PROBE', '', '')
  File "C:\Users\8prab\AppData\Roaming\Python\Python38\site-packages\joblib\externals\loky\backend\resource_tracker.py", line 209, in _send
    nbytes = os.write(self._fd, msg)
OSError: [Errno 22] Invalid argument

2022-04-17 19:24:24,223:INFO:Initializing create_model()
2022-04-17 19:24:24,224:INFO:create_model(estimator=rf, fold=StratifiedKFold(n_splits=10, random_state=None, shuffle=False), round=4, cross_validation=True, predict=True, fit_kwargs={}, groups=None, refit=False, verbose=False, system=False, metrics=None, experiment_custom_tags=None, add_to_model_list=True, probability_threshold=None, display=<pycaret.internal.Display.Display object at 0x000001D75ACFC490>, return_train_score=False, kwargs={})
2022-04-17 19:24:24,225:INFO:Checking exceptions
2022-04-17 19:24:24,227:INFO:Importing libraries
2022-04-17 19:24:24,228:INFO:Copying training dataset
2022-04-17 19:24:24,390:INFO:Defining folds
2022-04-17 19:24:24,391:INFO:Declaring metric variables
2022-04-17 19:24:24,418:INFO:Importing untrained model
2022-04-17 19:24:24,455:INFO:Random Forest Classifier Imported succesfully
2022-04-17 19:24:24,504:INFO:Starting cross validation
2022-04-17 19:24:24,509:INFO:Cross validating with StratifiedKFold(n_splits=10, random_state=None, shuffle=False), n_jobs=-1
2022-04-17 19:24:24,513:ERROR:create_model() for rf raised an exception or returned all 0.0:
2022-04-17 19:24:24,519:ERROR:Traceback (most recent call last):
  File "C:\Users\8prab\.conda\envs\ee\lib\site-packages\pycaret\internal\tabular.py", line 2203, in compare_models
    model, model_fit_time = create_model_supervised(**create_model_args)
  File "C:\Users\8prab\.conda\envs\ee\lib\site-packages\pycaret\internal\tabular.py", line 3200, in create_model_supervised
    scores = cross_validate(
  File "C:\Users\8prab\.conda\envs\ee\lib\site-packages\sklearn\utils\validation.py", line 72, in inner_f
    return f(**kwargs)
  File "C:\Users\8prab\.conda\envs\ee\lib\site-packages\sklearn\model_selection\_validation.py", line 242, in cross_validate
    scores = parallel(
  File "C:\Users\8prab\AppData\Roaming\Python\Python38\site-packages\joblib\parallel.py", line 968, in __call__
    n_jobs = self._initialize_backend()
  File "C:\Users\8prab\AppData\Roaming\Python\Python38\site-packages\joblib\parallel.py", line 735, in _initialize_backend
    n_jobs = self._backend.configure(n_jobs=self.n_jobs, parallel=self,
  File "C:\Users\8prab\AppData\Roaming\Python\Python38\site-packages\joblib\_parallel_backends.py", line 494, in configure
    self._workers = get_memmapping_executor(
  File "C:\Users\8prab\AppData\Roaming\Python\Python38\site-packages\joblib\executor.py", line 20, in get_memmapping_executor
    return MemmappingExecutor.get_memmapping_executor(n_jobs, **kwargs)
  File "C:\Users\8prab\AppData\Roaming\Python\Python38\site-packages\joblib\executor.py", line 42, in get_memmapping_executor
    manager = TemporaryResourcesManager(temp_folder)
  File "C:\Users\8prab\AppData\Roaming\Python\Python38\site-packages\joblib\_memmapping_reducer.py", line 531, in __init__
    self.set_current_context(context_id)
  File "C:\Users\8prab\AppData\Roaming\Python\Python38\site-packages\joblib\_memmapping_reducer.py", line 535, in set_current_context
    self.register_new_context(context_id)
  File "C:\Users\8prab\AppData\Roaming\Python\Python38\site-packages\joblib\_memmapping_reducer.py", line 560, in register_new_context
    self.register_folder_finalizer(new_folder_path, context_id)
  File "C:\Users\8prab\AppData\Roaming\Python\Python38\site-packages\joblib\_memmapping_reducer.py", line 590, in register_folder_finalizer
    resource_tracker.register(pool_subfolder, "folder")
  File "C:\Users\8prab\AppData\Roaming\Python\Python38\site-packages\joblib\externals\loky\backend\resource_tracker.py", line 190, in register
    self.ensure_running()
  File "C:\Users\8prab\AppData\Roaming\Python\Python38\site-packages\joblib\externals\loky\backend\resource_tracker.py", line 102, in ensure_running
    if self._check_alive():
  File "C:\Users\8prab\AppData\Roaming\Python\Python38\site-packages\joblib\externals\loky\backend\resource_tracker.py", line 182, in _check_alive
    self._send('PROBE', '', '')
  File "C:\Users\8prab\AppData\Roaming\Python\Python38\site-packages\joblib\externals\loky\backend\resource_tracker.py", line 209, in _send
    nbytes = os.write(self._fd, msg)
OSError: [Errno 22] Invalid argument

During handling of the above exception, another exception occurred:

Traceback (most recent call last):
  File "C:\Users\8prab\.conda\envs\ee\lib\site-packages\pycaret\internal\tabular.py", line 2212, in compare_models
    model, model_fit_time = create_model_supervised(**create_model_args)
  File "C:\Users\8prab\.conda\envs\ee\lib\site-packages\pycaret\internal\tabular.py", line 3200, in create_model_supervised
    scores = cross_validate(
  File "C:\Users\8prab\.conda\envs\ee\lib\site-packages\sklearn\utils\validation.py", line 72, in inner_f
    return f(**kwargs)
  File "C:\Users\8prab\.conda\envs\ee\lib\site-packages\sklearn\model_selection\_validation.py", line 242, in cross_validate
    scores = parallel(
  File "C:\Users\8prab\AppData\Roaming\Python\Python38\site-packages\joblib\parallel.py", line 968, in __call__
    n_jobs = self._initialize_backend()
  File "C:\Users\8prab\AppData\Roaming\Python\Python38\site-packages\joblib\parallel.py", line 735, in _initialize_backend
    n_jobs = self._backend.configure(n_jobs=self.n_jobs, parallel=self,
  File "C:\Users\8prab\AppData\Roaming\Python\Python38\site-packages\joblib\_parallel_backends.py", line 494, in configure
    self._workers = get_memmapping_executor(
  File "C:\Users\8prab\AppData\Roaming\Python\Python38\site-packages\joblib\executor.py", line 20, in get_memmapping_executor
    return MemmappingExecutor.get_memmapping_executor(n_jobs, **kwargs)
  File "C:\Users\8prab\AppData\Roaming\Python\Python38\site-packages\joblib\executor.py", line 42, in get_memmapping_executor
    manager = TemporaryResourcesManager(temp_folder)
  File "C:\Users\8prab\AppData\Roaming\Python\Python38\site-packages\joblib\_memmapping_reducer.py", line 531, in __init__
    self.set_current_context(context_id)
  File "C:\Users\8prab\AppData\Roaming\Python\Python38\site-packages\joblib\_memmapping_reducer.py", line 535, in set_current_context
    self.register_new_context(context_id)
  File "C:\Users\8prab\AppData\Roaming\Python\Python38\site-packages\joblib\_memmapping_reducer.py", line 560, in register_new_context
    self.register_folder_finalizer(new_folder_path, context_id)
  File "C:\Users\8prab\AppData\Roaming\Python\Python38\site-packages\joblib\_memmapping_reducer.py", line 590, in register_folder_finalizer
    resource_tracker.register(pool_subfolder, "folder")
  File "C:\Users\8prab\AppData\Roaming\Python\Python38\site-packages\joblib\externals\loky\backend\resource_tracker.py", line 190, in register
    self.ensure_running()
  File "C:\Users\8prab\AppData\Roaming\Python\Python38\site-packages\joblib\externals\loky\backend\resource_tracker.py", line 102, in ensure_running
    if self._check_alive():
  File "C:\Users\8prab\AppData\Roaming\Python\Python38\site-packages\joblib\externals\loky\backend\resource_tracker.py", line 182, in _check_alive
    self._send('PROBE', '', '')
  File "C:\Users\8prab\AppData\Roaming\Python\Python38\site-packages\joblib\externals\loky\backend\resource_tracker.py", line 209, in _send
    nbytes = os.write(self._fd, msg)
OSError: [Errno 22] Invalid argument

2022-04-17 19:24:24,558:INFO:Initializing Quadratic Discriminant Analysis
2022-04-17 19:24:24,560:INFO:Total runtime is 0.0671988844871521 minutes
2022-04-17 19:24:24,582:INFO:SubProcess create_model() called ==================================
2022-04-17 19:24:24,587:INFO:Initializing create_model()
2022-04-17 19:24:24,590:INFO:create_model(estimator=qda, fold=StratifiedKFold(n_splits=10, random_state=None, shuffle=False), round=4, cross_validation=True, predict=True, fit_kwargs={}, groups=None, refit=False, verbose=False, system=False, metrics=None, experiment_custom_tags=None, add_to_model_list=True, probability_threshold=None, display=<pycaret.internal.Display.Display object at 0x000001D75ACFC490>, return_train_score=False, kwargs={})
2022-04-17 19:24:24,593:INFO:Checking exceptions
2022-04-17 19:24:24,596:INFO:Importing libraries
2022-04-17 19:24:24,598:INFO:Copying training dataset
2022-04-17 19:24:24,674:INFO:Defining folds
2022-04-17 19:24:24,675:INFO:Declaring metric variables
2022-04-17 19:24:24,692:INFO:Importing untrained model
2022-04-17 19:24:24,742:INFO:Quadratic Discriminant Analysis Imported succesfully
2022-04-17 19:24:24,823:INFO:Starting cross validation
2022-04-17 19:24:24,828:INFO:Cross validating with StratifiedKFold(n_splits=10, random_state=None, shuffle=False), n_jobs=-1
2022-04-17 19:24:24,832:WARNING:create_model() for qda raised an exception or returned all 0.0, trying without fit_kwargs:
2022-04-17 19:24:24,836:WARNING:Traceback (most recent call last):
  File "C:\Users\8prab\.conda\envs\ee\lib\site-packages\pycaret\internal\tabular.py", line 2203, in compare_models
    model, model_fit_time = create_model_supervised(**create_model_args)
  File "C:\Users\8prab\.conda\envs\ee\lib\site-packages\pycaret\internal\tabular.py", line 3200, in create_model_supervised
    scores = cross_validate(
  File "C:\Users\8prab\.conda\envs\ee\lib\site-packages\sklearn\utils\validation.py", line 72, in inner_f
    return f(**kwargs)
  File "C:\Users\8prab\.conda\envs\ee\lib\site-packages\sklearn\model_selection\_validation.py", line 242, in cross_validate
    scores = parallel(
  File "C:\Users\8prab\AppData\Roaming\Python\Python38\site-packages\joblib\parallel.py", line 968, in __call__
    n_jobs = self._initialize_backend()
  File "C:\Users\8prab\AppData\Roaming\Python\Python38\site-packages\joblib\parallel.py", line 735, in _initialize_backend
    n_jobs = self._backend.configure(n_jobs=self.n_jobs, parallel=self,
  File "C:\Users\8prab\AppData\Roaming\Python\Python38\site-packages\joblib\_parallel_backends.py", line 494, in configure
    self._workers = get_memmapping_executor(
  File "C:\Users\8prab\AppData\Roaming\Python\Python38\site-packages\joblib\executor.py", line 20, in get_memmapping_executor
    return MemmappingExecutor.get_memmapping_executor(n_jobs, **kwargs)
  File "C:\Users\8prab\AppData\Roaming\Python\Python38\site-packages\joblib\executor.py", line 42, in get_memmapping_executor
    manager = TemporaryResourcesManager(temp_folder)
  File "C:\Users\8prab\AppData\Roaming\Python\Python38\site-packages\joblib\_memmapping_reducer.py", line 531, in __init__
    self.set_current_context(context_id)
  File "C:\Users\8prab\AppData\Roaming\Python\Python38\site-packages\joblib\_memmapping_reducer.py", line 535, in set_current_context
    self.register_new_context(context_id)
  File "C:\Users\8prab\AppData\Roaming\Python\Python38\site-packages\joblib\_memmapping_reducer.py", line 560, in register_new_context
    self.register_folder_finalizer(new_folder_path, context_id)
  File "C:\Users\8prab\AppData\Roaming\Python\Python38\site-packages\joblib\_memmapping_reducer.py", line 590, in register_folder_finalizer
    resource_tracker.register(pool_subfolder, "folder")
  File "C:\Users\8prab\AppData\Roaming\Python\Python38\site-packages\joblib\externals\loky\backend\resource_tracker.py", line 190, in register
    self.ensure_running()
  File "C:\Users\8prab\AppData\Roaming\Python\Python38\site-packages\joblib\externals\loky\backend\resource_tracker.py", line 102, in ensure_running
    if self._check_alive():
  File "C:\Users\8prab\AppData\Roaming\Python\Python38\site-packages\joblib\externals\loky\backend\resource_tracker.py", line 182, in _check_alive
    self._send('PROBE', '', '')
  File "C:\Users\8prab\AppData\Roaming\Python\Python38\site-packages\joblib\externals\loky\backend\resource_tracker.py", line 209, in _send
    nbytes = os.write(self._fd, msg)
OSError: [Errno 22] Invalid argument

2022-04-17 19:24:24,844:INFO:Initializing create_model()
2022-04-17 19:24:24,847:INFO:create_model(estimator=qda, fold=StratifiedKFold(n_splits=10, random_state=None, shuffle=False), round=4, cross_validation=True, predict=True, fit_kwargs={}, groups=None, refit=False, verbose=False, system=False, metrics=None, experiment_custom_tags=None, add_to_model_list=True, probability_threshold=None, display=<pycaret.internal.Display.Display object at 0x000001D75ACFC490>, return_train_score=False, kwargs={})
2022-04-17 19:24:24,851:INFO:Checking exceptions
2022-04-17 19:24:24,853:INFO:Importing libraries
2022-04-17 19:24:24,858:INFO:Copying training dataset
2022-04-17 19:24:25,080:INFO:Defining folds
2022-04-17 19:24:25,082:INFO:Declaring metric variables
2022-04-17 19:24:25,111:INFO:Importing untrained model
2022-04-17 19:24:25,154:INFO:Quadratic Discriminant Analysis Imported succesfully
2022-04-17 19:24:25,227:INFO:Starting cross validation
2022-04-17 19:24:25,230:INFO:Cross validating with StratifiedKFold(n_splits=10, random_state=None, shuffle=False), n_jobs=-1
2022-04-17 19:24:25,261:ERROR:create_model() for qda raised an exception or returned all 0.0:
2022-04-17 19:24:25,268:ERROR:Traceback (most recent call last):
  File "C:\Users\8prab\.conda\envs\ee\lib\site-packages\pycaret\internal\tabular.py", line 2203, in compare_models
    model, model_fit_time = create_model_supervised(**create_model_args)
  File "C:\Users\8prab\.conda\envs\ee\lib\site-packages\pycaret\internal\tabular.py", line 3200, in create_model_supervised
    scores = cross_validate(
  File "C:\Users\8prab\.conda\envs\ee\lib\site-packages\sklearn\utils\validation.py", line 72, in inner_f
    return f(**kwargs)
  File "C:\Users\8prab\.conda\envs\ee\lib\site-packages\sklearn\model_selection\_validation.py", line 242, in cross_validate
    scores = parallel(
  File "C:\Users\8prab\AppData\Roaming\Python\Python38\site-packages\joblib\parallel.py", line 968, in __call__
    n_jobs = self._initialize_backend()
  File "C:\Users\8prab\AppData\Roaming\Python\Python38\site-packages\joblib\parallel.py", line 735, in _initialize_backend
    n_jobs = self._backend.configure(n_jobs=self.n_jobs, parallel=self,
  File "C:\Users\8prab\AppData\Roaming\Python\Python38\site-packages\joblib\_parallel_backends.py", line 494, in configure
    self._workers = get_memmapping_executor(
  File "C:\Users\8prab\AppData\Roaming\Python\Python38\site-packages\joblib\executor.py", line 20, in get_memmapping_executor
    return MemmappingExecutor.get_memmapping_executor(n_jobs, **kwargs)
  File "C:\Users\8prab\AppData\Roaming\Python\Python38\site-packages\joblib\executor.py", line 42, in get_memmapping_executor
    manager = TemporaryResourcesManager(temp_folder)
  File "C:\Users\8prab\AppData\Roaming\Python\Python38\site-packages\joblib\_memmapping_reducer.py", line 531, in __init__
    self.set_current_context(context_id)
  File "C:\Users\8prab\AppData\Roaming\Python\Python38\site-packages\joblib\_memmapping_reducer.py", line 535, in set_current_context
    self.register_new_context(context_id)
  File "C:\Users\8prab\AppData\Roaming\Python\Python38\site-packages\joblib\_memmapping_reducer.py", line 560, in register_new_context
    self.register_folder_finalizer(new_folder_path, context_id)
  File "C:\Users\8prab\AppData\Roaming\Python\Python38\site-packages\joblib\_memmapping_reducer.py", line 590, in register_folder_finalizer
    resource_tracker.register(pool_subfolder, "folder")
  File "C:\Users\8prab\AppData\Roaming\Python\Python38\site-packages\joblib\externals\loky\backend\resource_tracker.py", line 190, in register
    self.ensure_running()
  File "C:\Users\8prab\AppData\Roaming\Python\Python38\site-packages\joblib\externals\loky\backend\resource_tracker.py", line 102, in ensure_running
    if self._check_alive():
  File "C:\Users\8prab\AppData\Roaming\Python\Python38\site-packages\joblib\externals\loky\backend\resource_tracker.py", line 182, in _check_alive
    self._send('PROBE', '', '')
  File "C:\Users\8prab\AppData\Roaming\Python\Python38\site-packages\joblib\externals\loky\backend\resource_tracker.py", line 209, in _send
    nbytes = os.write(self._fd, msg)
OSError: [Errno 22] Invalid argument

During handling of the above exception, another exception occurred:

Traceback (most recent call last):
  File "C:\Users\8prab\.conda\envs\ee\lib\site-packages\pycaret\internal\tabular.py", line 2212, in compare_models
    model, model_fit_time = create_model_supervised(**create_model_args)
  File "C:\Users\8prab\.conda\envs\ee\lib\site-packages\pycaret\internal\tabular.py", line 3200, in create_model_supervised
    scores = cross_validate(
  File "C:\Users\8prab\.conda\envs\ee\lib\site-packages\sklearn\utils\validation.py", line 72, in inner_f
    return f(**kwargs)
  File "C:\Users\8prab\.conda\envs\ee\lib\site-packages\sklearn\model_selection\_validation.py", line 242, in cross_validate
    scores = parallel(
  File "C:\Users\8prab\AppData\Roaming\Python\Python38\site-packages\joblib\parallel.py", line 968, in __call__
    n_jobs = self._initialize_backend()
  File "C:\Users\8prab\AppData\Roaming\Python\Python38\site-packages\joblib\parallel.py", line 735, in _initialize_backend
    n_jobs = self._backend.configure(n_jobs=self.n_jobs, parallel=self,
  File "C:\Users\8prab\AppData\Roaming\Python\Python38\site-packages\joblib\_parallel_backends.py", line 494, in configure
    self._workers = get_memmapping_executor(
  File "C:\Users\8prab\AppData\Roaming\Python\Python38\site-packages\joblib\executor.py", line 20, in get_memmapping_executor
    return MemmappingExecutor.get_memmapping_executor(n_jobs, **kwargs)
  File "C:\Users\8prab\AppData\Roaming\Python\Python38\site-packages\joblib\executor.py", line 42, in get_memmapping_executor
    manager = TemporaryResourcesManager(temp_folder)
  File "C:\Users\8prab\AppData\Roaming\Python\Python38\site-packages\joblib\_memmapping_reducer.py", line 531, in __init__
    self.set_current_context(context_id)
  File "C:\Users\8prab\AppData\Roaming\Python\Python38\site-packages\joblib\_memmapping_reducer.py", line 535, in set_current_context
    self.register_new_context(context_id)
  File "C:\Users\8prab\AppData\Roaming\Python\Python38\site-packages\joblib\_memmapping_reducer.py", line 560, in register_new_context
    self.register_folder_finalizer(new_folder_path, context_id)
  File "C:\Users\8prab\AppData\Roaming\Python\Python38\site-packages\joblib\_memmapping_reducer.py", line 590, in register_folder_finalizer
    resource_tracker.register(pool_subfolder, "folder")
  File "C:\Users\8prab\AppData\Roaming\Python\Python38\site-packages\joblib\externals\loky\backend\resource_tracker.py", line 190, in register
    self.ensure_running()
  File "C:\Users\8prab\AppData\Roaming\Python\Python38\site-packages\joblib\externals\loky\backend\resource_tracker.py", line 102, in ensure_running
    if self._check_alive():
  File "C:\Users\8prab\AppData\Roaming\Python\Python38\site-packages\joblib\externals\loky\backend\resource_tracker.py", line 182, in _check_alive
    self._send('PROBE', '', '')
  File "C:\Users\8prab\AppData\Roaming\Python\Python38\site-packages\joblib\externals\loky\backend\resource_tracker.py", line 209, in _send
    nbytes = os.write(self._fd, msg)
OSError: [Errno 22] Invalid argument

2022-04-17 19:24:25,317:INFO:Initializing Ada Boost Classifier
2022-04-17 19:24:25,319:INFO:Total runtime is 0.07985309362411498 minutes
2022-04-17 19:24:25,354:INFO:SubProcess create_model() called ==================================
2022-04-17 19:24:25,364:INFO:Initializing create_model()
2022-04-17 19:24:25,366:INFO:create_model(estimator=ada, fold=StratifiedKFold(n_splits=10, random_state=None, shuffle=False), round=4, cross_validation=True, predict=True, fit_kwargs={}, groups=None, refit=False, verbose=False, system=False, metrics=None, experiment_custom_tags=None, add_to_model_list=True, probability_threshold=None, display=<pycaret.internal.Display.Display object at 0x000001D75ACFC490>, return_train_score=False, kwargs={})
2022-04-17 19:24:25,368:INFO:Checking exceptions
2022-04-17 19:24:25,370:INFO:Importing libraries
2022-04-17 19:24:25,378:INFO:Copying training dataset
2022-04-17 19:24:25,469:INFO:Defining folds
2022-04-17 19:24:25,475:INFO:Declaring metric variables
2022-04-17 19:24:25,502:INFO:Importing untrained model
2022-04-17 19:24:25,528:INFO:Ada Boost Classifier Imported succesfully
2022-04-17 19:24:25,595:INFO:Starting cross validation
2022-04-17 19:24:25,599:INFO:Cross validating with StratifiedKFold(n_splits=10, random_state=None, shuffle=False), n_jobs=-1
2022-04-17 19:24:25,603:WARNING:create_model() for ada raised an exception or returned all 0.0, trying without fit_kwargs:
2022-04-17 19:24:25,613:WARNING:Traceback (most recent call last):
  File "C:\Users\8prab\.conda\envs\ee\lib\site-packages\pycaret\internal\tabular.py", line 2203, in compare_models
    model, model_fit_time = create_model_supervised(**create_model_args)
  File "C:\Users\8prab\.conda\envs\ee\lib\site-packages\pycaret\internal\tabular.py", line 3200, in create_model_supervised
    scores = cross_validate(
  File "C:\Users\8prab\.conda\envs\ee\lib\site-packages\sklearn\utils\validation.py", line 72, in inner_f
    return f(**kwargs)
  File "C:\Users\8prab\.conda\envs\ee\lib\site-packages\sklearn\model_selection\_validation.py", line 242, in cross_validate
    scores = parallel(
  File "C:\Users\8prab\AppData\Roaming\Python\Python38\site-packages\joblib\parallel.py", line 968, in __call__
    n_jobs = self._initialize_backend()
  File "C:\Users\8prab\AppData\Roaming\Python\Python38\site-packages\joblib\parallel.py", line 735, in _initialize_backend
    n_jobs = self._backend.configure(n_jobs=self.n_jobs, parallel=self,
  File "C:\Users\8prab\AppData\Roaming\Python\Python38\site-packages\joblib\_parallel_backends.py", line 494, in configure
    self._workers = get_memmapping_executor(
  File "C:\Users\8prab\AppData\Roaming\Python\Python38\site-packages\joblib\executor.py", line 20, in get_memmapping_executor
    return MemmappingExecutor.get_memmapping_executor(n_jobs, **kwargs)
  File "C:\Users\8prab\AppData\Roaming\Python\Python38\site-packages\joblib\executor.py", line 42, in get_memmapping_executor
    manager = TemporaryResourcesManager(temp_folder)
  File "C:\Users\8prab\AppData\Roaming\Python\Python38\site-packages\joblib\_memmapping_reducer.py", line 531, in __init__
    self.set_current_context(context_id)
  File "C:\Users\8prab\AppData\Roaming\Python\Python38\site-packages\joblib\_memmapping_reducer.py", line 535, in set_current_context
    self.register_new_context(context_id)
  File "C:\Users\8prab\AppData\Roaming\Python\Python38\site-packages\joblib\_memmapping_reducer.py", line 560, in register_new_context
    self.register_folder_finalizer(new_folder_path, context_id)
  File "C:\Users\8prab\AppData\Roaming\Python\Python38\site-packages\joblib\_memmapping_reducer.py", line 590, in register_folder_finalizer
    resource_tracker.register(pool_subfolder, "folder")
  File "C:\Users\8prab\AppData\Roaming\Python\Python38\site-packages\joblib\externals\loky\backend\resource_tracker.py", line 190, in register
    self.ensure_running()
  File "C:\Users\8prab\AppData\Roaming\Python\Python38\site-packages\joblib\externals\loky\backend\resource_tracker.py", line 102, in ensure_running
    if self._check_alive():
  File "C:\Users\8prab\AppData\Roaming\Python\Python38\site-packages\joblib\externals\loky\backend\resource_tracker.py", line 182, in _check_alive
    self._send('PROBE', '', '')
  File "C:\Users\8prab\AppData\Roaming\Python\Python38\site-packages\joblib\externals\loky\backend\resource_tracker.py", line 209, in _send
    nbytes = os.write(self._fd, msg)
OSError: [Errno 22] Invalid argument

2022-04-17 19:24:25,616:INFO:Initializing create_model()
2022-04-17 19:24:25,617:INFO:create_model(estimator=ada, fold=StratifiedKFold(n_splits=10, random_state=None, shuffle=False), round=4, cross_validation=True, predict=True, fit_kwargs={}, groups=None, refit=False, verbose=False, system=False, metrics=None, experiment_custom_tags=None, add_to_model_list=True, probability_threshold=None, display=<pycaret.internal.Display.Display object at 0x000001D75ACFC490>, return_train_score=False, kwargs={})
2022-04-17 19:24:25,619:INFO:Checking exceptions
2022-04-17 19:24:25,624:INFO:Importing libraries
2022-04-17 19:24:25,628:INFO:Copying training dataset
2022-04-17 19:24:25,737:INFO:Defining folds
2022-04-17 19:24:25,741:INFO:Declaring metric variables
2022-04-17 19:24:25,767:INFO:Importing untrained model
2022-04-17 19:24:25,795:INFO:Ada Boost Classifier Imported succesfully
2022-04-17 19:24:25,861:INFO:Starting cross validation
2022-04-17 19:24:25,866:INFO:Cross validating with StratifiedKFold(n_splits=10, random_state=None, shuffle=False), n_jobs=-1
2022-04-17 19:24:25,870:ERROR:create_model() for ada raised an exception or returned all 0.0:
2022-04-17 19:24:25,882:ERROR:Traceback (most recent call last):
  File "C:\Users\8prab\.conda\envs\ee\lib\site-packages\pycaret\internal\tabular.py", line 2203, in compare_models
    model, model_fit_time = create_model_supervised(**create_model_args)
  File "C:\Users\8prab\.conda\envs\ee\lib\site-packages\pycaret\internal\tabular.py", line 3200, in create_model_supervised
    scores = cross_validate(
  File "C:\Users\8prab\.conda\envs\ee\lib\site-packages\sklearn\utils\validation.py", line 72, in inner_f
    return f(**kwargs)
  File "C:\Users\8prab\.conda\envs\ee\lib\site-packages\sklearn\model_selection\_validation.py", line 242, in cross_validate
    scores = parallel(
  File "C:\Users\8prab\AppData\Roaming\Python\Python38\site-packages\joblib\parallel.py", line 968, in __call__
    n_jobs = self._initialize_backend()
  File "C:\Users\8prab\AppData\Roaming\Python\Python38\site-packages\joblib\parallel.py", line 735, in _initialize_backend
    n_jobs = self._backend.configure(n_jobs=self.n_jobs, parallel=self,
  File "C:\Users\8prab\AppData\Roaming\Python\Python38\site-packages\joblib\_parallel_backends.py", line 494, in configure
    self._workers = get_memmapping_executor(
  File "C:\Users\8prab\AppData\Roaming\Python\Python38\site-packages\joblib\executor.py", line 20, in get_memmapping_executor
    return MemmappingExecutor.get_memmapping_executor(n_jobs, **kwargs)
  File "C:\Users\8prab\AppData\Roaming\Python\Python38\site-packages\joblib\executor.py", line 42, in get_memmapping_executor
    manager = TemporaryResourcesManager(temp_folder)
  File "C:\Users\8prab\AppData\Roaming\Python\Python38\site-packages\joblib\_memmapping_reducer.py", line 531, in __init__
    self.set_current_context(context_id)
  File "C:\Users\8prab\AppData\Roaming\Python\Python38\site-packages\joblib\_memmapping_reducer.py", line 535, in set_current_context
    self.register_new_context(context_id)
  File "C:\Users\8prab\AppData\Roaming\Python\Python38\site-packages\joblib\_memmapping_reducer.py", line 560, in register_new_context
    self.register_folder_finalizer(new_folder_path, context_id)
  File "C:\Users\8prab\AppData\Roaming\Python\Python38\site-packages\joblib\_memmapping_reducer.py", line 590, in register_folder_finalizer
    resource_tracker.register(pool_subfolder, "folder")
  File "C:\Users\8prab\AppData\Roaming\Python\Python38\site-packages\joblib\externals\loky\backend\resource_tracker.py", line 190, in register
    self.ensure_running()
  File "C:\Users\8prab\AppData\Roaming\Python\Python38\site-packages\joblib\externals\loky\backend\resource_tracker.py", line 102, in ensure_running
    if self._check_alive():
  File "C:\Users\8prab\AppData\Roaming\Python\Python38\site-packages\joblib\externals\loky\backend\resource_tracker.py", line 182, in _check_alive
    self._send('PROBE', '', '')
  File "C:\Users\8prab\AppData\Roaming\Python\Python38\site-packages\joblib\externals\loky\backend\resource_tracker.py", line 209, in _send
    nbytes = os.write(self._fd, msg)
OSError: [Errno 22] Invalid argument

During handling of the above exception, another exception occurred:

Traceback (most recent call last):
  File "C:\Users\8prab\.conda\envs\ee\lib\site-packages\pycaret\internal\tabular.py", line 2212, in compare_models
    model, model_fit_time = create_model_supervised(**create_model_args)
  File "C:\Users\8prab\.conda\envs\ee\lib\site-packages\pycaret\internal\tabular.py", line 3200, in create_model_supervised
    scores = cross_validate(
  File "C:\Users\8prab\.conda\envs\ee\lib\site-packages\sklearn\utils\validation.py", line 72, in inner_f
    return f(**kwargs)
  File "C:\Users\8prab\.conda\envs\ee\lib\site-packages\sklearn\model_selection\_validation.py", line 242, in cross_validate
    scores = parallel(
  File "C:\Users\8prab\AppData\Roaming\Python\Python38\site-packages\joblib\parallel.py", line 968, in __call__
    n_jobs = self._initialize_backend()
  File "C:\Users\8prab\AppData\Roaming\Python\Python38\site-packages\joblib\parallel.py", line 735, in _initialize_backend
    n_jobs = self._backend.configure(n_jobs=self.n_jobs, parallel=self,
  File "C:\Users\8prab\AppData\Roaming\Python\Python38\site-packages\joblib\_parallel_backends.py", line 494, in configure
    self._workers = get_memmapping_executor(
  File "C:\Users\8prab\AppData\Roaming\Python\Python38\site-packages\joblib\executor.py", line 20, in get_memmapping_executor
    return MemmappingExecutor.get_memmapping_executor(n_jobs, **kwargs)
  File "C:\Users\8prab\AppData\Roaming\Python\Python38\site-packages\joblib\executor.py", line 42, in get_memmapping_executor
    manager = TemporaryResourcesManager(temp_folder)
  File "C:\Users\8prab\AppData\Roaming\Python\Python38\site-packages\joblib\_memmapping_reducer.py", line 531, in __init__
    self.set_current_context(context_id)
  File "C:\Users\8prab\AppData\Roaming\Python\Python38\site-packages\joblib\_memmapping_reducer.py", line 535, in set_current_context
    self.register_new_context(context_id)
  File "C:\Users\8prab\AppData\Roaming\Python\Python38\site-packages\joblib\_memmapping_reducer.py", line 560, in register_new_context
    self.register_folder_finalizer(new_folder_path, context_id)
  File "C:\Users\8prab\AppData\Roaming\Python\Python38\site-packages\joblib\_memmapping_reducer.py", line 590, in register_folder_finalizer
    resource_tracker.register(pool_subfolder, "folder")
  File "C:\Users\8prab\AppData\Roaming\Python\Python38\site-packages\joblib\externals\loky\backend\resource_tracker.py", line 190, in register
    self.ensure_running()
  File "C:\Users\8prab\AppData\Roaming\Python\Python38\site-packages\joblib\externals\loky\backend\resource_tracker.py", line 102, in ensure_running
    if self._check_alive():
  File "C:\Users\8prab\AppData\Roaming\Python\Python38\site-packages\joblib\externals\loky\backend\resource_tracker.py", line 182, in _check_alive
    self._send('PROBE', '', '')
  File "C:\Users\8prab\AppData\Roaming\Python\Python38\site-packages\joblib\externals\loky\backend\resource_tracker.py", line 209, in _send
    nbytes = os.write(self._fd, msg)
OSError: [Errno 22] Invalid argument

2022-04-17 19:24:25,917:INFO:Initializing Gradient Boosting Classifier
2022-04-17 19:24:25,920:INFO:Total runtime is 0.08987631400426228 minutes
2022-04-17 19:24:25,961:INFO:SubProcess create_model() called ==================================
2022-04-17 19:24:25,964:INFO:Initializing create_model()
2022-04-17 19:24:25,967:INFO:create_model(estimator=gbc, fold=StratifiedKFold(n_splits=10, random_state=None, shuffle=False), round=4, cross_validation=True, predict=True, fit_kwargs={}, groups=None, refit=False, verbose=False, system=False, metrics=None, experiment_custom_tags=None, add_to_model_list=True, probability_threshold=None, display=<pycaret.internal.Display.Display object at 0x000001D75ACFC490>, return_train_score=False, kwargs={})
2022-04-17 19:24:25,969:INFO:Checking exceptions
2022-04-17 19:24:25,972:INFO:Importing libraries
2022-04-17 19:24:25,977:INFO:Copying training dataset
2022-04-17 19:24:26,066:INFO:Defining folds
2022-04-17 19:24:26,070:INFO:Declaring metric variables
2022-04-17 19:24:26,120:INFO:Importing untrained model
2022-04-17 19:24:26,229:INFO:Gradient Boosting Classifier Imported succesfully
2022-04-17 19:24:26,325:INFO:Starting cross validation
2022-04-17 19:24:26,330:INFO:Cross validating with StratifiedKFold(n_splits=10, random_state=None, shuffle=False), n_jobs=-1
2022-04-17 19:24:26,335:WARNING:create_model() for gbc raised an exception or returned all 0.0, trying without fit_kwargs:
2022-04-17 19:24:26,341:WARNING:Traceback (most recent call last):
  File "C:\Users\8prab\.conda\envs\ee\lib\site-packages\pycaret\internal\tabular.py", line 2203, in compare_models
    model, model_fit_time = create_model_supervised(**create_model_args)
  File "C:\Users\8prab\.conda\envs\ee\lib\site-packages\pycaret\internal\tabular.py", line 3200, in create_model_supervised
    scores = cross_validate(
  File "C:\Users\8prab\.conda\envs\ee\lib\site-packages\sklearn\utils\validation.py", line 72, in inner_f
    return f(**kwargs)
  File "C:\Users\8prab\.conda\envs\ee\lib\site-packages\sklearn\model_selection\_validation.py", line 242, in cross_validate
    scores = parallel(
  File "C:\Users\8prab\AppData\Roaming\Python\Python38\site-packages\joblib\parallel.py", line 968, in __call__
    n_jobs = self._initialize_backend()
  File "C:\Users\8prab\AppData\Roaming\Python\Python38\site-packages\joblib\parallel.py", line 735, in _initialize_backend
    n_jobs = self._backend.configure(n_jobs=self.n_jobs, parallel=self,
  File "C:\Users\8prab\AppData\Roaming\Python\Python38\site-packages\joblib\_parallel_backends.py", line 494, in configure
    self._workers = get_memmapping_executor(
  File "C:\Users\8prab\AppData\Roaming\Python\Python38\site-packages\joblib\executor.py", line 20, in get_memmapping_executor
    return MemmappingExecutor.get_memmapping_executor(n_jobs, **kwargs)
  File "C:\Users\8prab\AppData\Roaming\Python\Python38\site-packages\joblib\executor.py", line 42, in get_memmapping_executor
    manager = TemporaryResourcesManager(temp_folder)
  File "C:\Users\8prab\AppData\Roaming\Python\Python38\site-packages\joblib\_memmapping_reducer.py", line 531, in __init__
    self.set_current_context(context_id)
  File "C:\Users\8prab\AppData\Roaming\Python\Python38\site-packages\joblib\_memmapping_reducer.py", line 535, in set_current_context
    self.register_new_context(context_id)
  File "C:\Users\8prab\AppData\Roaming\Python\Python38\site-packages\joblib\_memmapping_reducer.py", line 560, in register_new_context
    self.register_folder_finalizer(new_folder_path, context_id)
  File "C:\Users\8prab\AppData\Roaming\Python\Python38\site-packages\joblib\_memmapping_reducer.py", line 590, in register_folder_finalizer
    resource_tracker.register(pool_subfolder, "folder")
  File "C:\Users\8prab\AppData\Roaming\Python\Python38\site-packages\joblib\externals\loky\backend\resource_tracker.py", line 190, in register
    self.ensure_running()
  File "C:\Users\8prab\AppData\Roaming\Python\Python38\site-packages\joblib\externals\loky\backend\resource_tracker.py", line 102, in ensure_running
    if self._check_alive():
  File "C:\Users\8prab\AppData\Roaming\Python\Python38\site-packages\joblib\externals\loky\backend\resource_tracker.py", line 182, in _check_alive
    self._send('PROBE', '', '')
  File "C:\Users\8prab\AppData\Roaming\Python\Python38\site-packages\joblib\externals\loky\backend\resource_tracker.py", line 209, in _send
    nbytes = os.write(self._fd, msg)
OSError: [Errno 22] Invalid argument

2022-04-17 19:24:26,346:INFO:Initializing create_model()
2022-04-17 19:24:26,348:INFO:create_model(estimator=gbc, fold=StratifiedKFold(n_splits=10, random_state=None, shuffle=False), round=4, cross_validation=True, predict=True, fit_kwargs={}, groups=None, refit=False, verbose=False, system=False, metrics=None, experiment_custom_tags=None, add_to_model_list=True, probability_threshold=None, display=<pycaret.internal.Display.Display object at 0x000001D75ACFC490>, return_train_score=False, kwargs={})
2022-04-17 19:24:26,349:INFO:Checking exceptions
2022-04-17 19:24:26,350:INFO:Importing libraries
2022-04-17 19:24:26,352:INFO:Copying training dataset
2022-04-17 19:24:26,570:INFO:Defining folds
2022-04-17 19:24:26,576:INFO:Declaring metric variables
2022-04-17 19:24:26,604:INFO:Importing untrained model
2022-04-17 19:24:26,635:INFO:Gradient Boosting Classifier Imported succesfully
2022-04-17 19:24:26,699:INFO:Starting cross validation
2022-04-17 19:24:26,702:INFO:Cross validating with StratifiedKFold(n_splits=10, random_state=None, shuffle=False), n_jobs=-1
2022-04-17 19:24:26,707:ERROR:create_model() for gbc raised an exception or returned all 0.0:
2022-04-17 19:24:26,716:ERROR:Traceback (most recent call last):
  File "C:\Users\8prab\.conda\envs\ee\lib\site-packages\pycaret\internal\tabular.py", line 2203, in compare_models
    model, model_fit_time = create_model_supervised(**create_model_args)
  File "C:\Users\8prab\.conda\envs\ee\lib\site-packages\pycaret\internal\tabular.py", line 3200, in create_model_supervised
    scores = cross_validate(
  File "C:\Users\8prab\.conda\envs\ee\lib\site-packages\sklearn\utils\validation.py", line 72, in inner_f
    return f(**kwargs)
  File "C:\Users\8prab\.conda\envs\ee\lib\site-packages\sklearn\model_selection\_validation.py", line 242, in cross_validate
    scores = parallel(
  File "C:\Users\8prab\AppData\Roaming\Python\Python38\site-packages\joblib\parallel.py", line 968, in __call__
    n_jobs = self._initialize_backend()
  File "C:\Users\8prab\AppData\Roaming\Python\Python38\site-packages\joblib\parallel.py", line 735, in _initialize_backend
    n_jobs = self._backend.configure(n_jobs=self.n_jobs, parallel=self,
  File "C:\Users\8prab\AppData\Roaming\Python\Python38\site-packages\joblib\_parallel_backends.py", line 494, in configure
    self._workers = get_memmapping_executor(
  File "C:\Users\8prab\AppData\Roaming\Python\Python38\site-packages\joblib\executor.py", line 20, in get_memmapping_executor
    return MemmappingExecutor.get_memmapping_executor(n_jobs, **kwargs)
  File "C:\Users\8prab\AppData\Roaming\Python\Python38\site-packages\joblib\executor.py", line 42, in get_memmapping_executor
    manager = TemporaryResourcesManager(temp_folder)
  File "C:\Users\8prab\AppData\Roaming\Python\Python38\site-packages\joblib\_memmapping_reducer.py", line 531, in __init__
    self.set_current_context(context_id)
  File "C:\Users\8prab\AppData\Roaming\Python\Python38\site-packages\joblib\_memmapping_reducer.py", line 535, in set_current_context
    self.register_new_context(context_id)
  File "C:\Users\8prab\AppData\Roaming\Python\Python38\site-packages\joblib\_memmapping_reducer.py", line 560, in register_new_context
    self.register_folder_finalizer(new_folder_path, context_id)
  File "C:\Users\8prab\AppData\Roaming\Python\Python38\site-packages\joblib\_memmapping_reducer.py", line 590, in register_folder_finalizer
    resource_tracker.register(pool_subfolder, "folder")
  File "C:\Users\8prab\AppData\Roaming\Python\Python38\site-packages\joblib\externals\loky\backend\resource_tracker.py", line 190, in register
    self.ensure_running()
  File "C:\Users\8prab\AppData\Roaming\Python\Python38\site-packages\joblib\externals\loky\backend\resource_tracker.py", line 102, in ensure_running
    if self._check_alive():
  File "C:\Users\8prab\AppData\Roaming\Python\Python38\site-packages\joblib\externals\loky\backend\resource_tracker.py", line 182, in _check_alive
    self._send('PROBE', '', '')
  File "C:\Users\8prab\AppData\Roaming\Python\Python38\site-packages\joblib\externals\loky\backend\resource_tracker.py", line 209, in _send
    nbytes = os.write(self._fd, msg)
OSError: [Errno 22] Invalid argument

During handling of the above exception, another exception occurred:

Traceback (most recent call last):
  File "C:\Users\8prab\.conda\envs\ee\lib\site-packages\pycaret\internal\tabular.py", line 2212, in compare_models
    model, model_fit_time = create_model_supervised(**create_model_args)
  File "C:\Users\8prab\.conda\envs\ee\lib\site-packages\pycaret\internal\tabular.py", line 3200, in create_model_supervised
    scores = cross_validate(
  File "C:\Users\8prab\.conda\envs\ee\lib\site-packages\sklearn\utils\validation.py", line 72, in inner_f
    return f(**kwargs)
  File "C:\Users\8prab\.conda\envs\ee\lib\site-packages\sklearn\model_selection\_validation.py", line 242, in cross_validate
    scores = parallel(
  File "C:\Users\8prab\AppData\Roaming\Python\Python38\site-packages\joblib\parallel.py", line 968, in __call__
    n_jobs = self._initialize_backend()
  File "C:\Users\8prab\AppData\Roaming\Python\Python38\site-packages\joblib\parallel.py", line 735, in _initialize_backend
    n_jobs = self._backend.configure(n_jobs=self.n_jobs, parallel=self,
  File "C:\Users\8prab\AppData\Roaming\Python\Python38\site-packages\joblib\_parallel_backends.py", line 494, in configure
    self._workers = get_memmapping_executor(
  File "C:\Users\8prab\AppData\Roaming\Python\Python38\site-packages\joblib\executor.py", line 20, in get_memmapping_executor
    return MemmappingExecutor.get_memmapping_executor(n_jobs, **kwargs)
  File "C:\Users\8prab\AppData\Roaming\Python\Python38\site-packages\joblib\executor.py", line 42, in get_memmapping_executor
    manager = TemporaryResourcesManager(temp_folder)
  File "C:\Users\8prab\AppData\Roaming\Python\Python38\site-packages\joblib\_memmapping_reducer.py", line 531, in __init__
    self.set_current_context(context_id)
  File "C:\Users\8prab\AppData\Roaming\Python\Python38\site-packages\joblib\_memmapping_reducer.py", line 535, in set_current_context
    self.register_new_context(context_id)
  File "C:\Users\8prab\AppData\Roaming\Python\Python38\site-packages\joblib\_memmapping_reducer.py", line 560, in register_new_context
    self.register_folder_finalizer(new_folder_path, context_id)
  File "C:\Users\8prab\AppData\Roaming\Python\Python38\site-packages\joblib\_memmapping_reducer.py", line 590, in register_folder_finalizer
    resource_tracker.register(pool_subfolder, "folder")
  File "C:\Users\8prab\AppData\Roaming\Python\Python38\site-packages\joblib\externals\loky\backend\resource_tracker.py", line 190, in register
    self.ensure_running()
  File "C:\Users\8prab\AppData\Roaming\Python\Python38\site-packages\joblib\externals\loky\backend\resource_tracker.py", line 102, in ensure_running
    if self._check_alive():
  File "C:\Users\8prab\AppData\Roaming\Python\Python38\site-packages\joblib\externals\loky\backend\resource_tracker.py", line 182, in _check_alive
    self._send('PROBE', '', '')
  File "C:\Users\8prab\AppData\Roaming\Python\Python38\site-packages\joblib\externals\loky\backend\resource_tracker.py", line 209, in _send
    nbytes = os.write(self._fd, msg)
OSError: [Errno 22] Invalid argument

2022-04-17 19:24:26,760:INFO:Initializing Linear Discriminant Analysis
2022-04-17 19:24:26,762:INFO:Total runtime is 0.10390538771947225 minutes
2022-04-17 19:24:26,795:INFO:SubProcess create_model() called ==================================
2022-04-17 19:24:26,798:INFO:Initializing create_model()
2022-04-17 19:24:26,800:INFO:create_model(estimator=lda, fold=StratifiedKFold(n_splits=10, random_state=None, shuffle=False), round=4, cross_validation=True, predict=True, fit_kwargs={}, groups=None, refit=False, verbose=False, system=False, metrics=None, experiment_custom_tags=None, add_to_model_list=True, probability_threshold=None, display=<pycaret.internal.Display.Display object at 0x000001D75ACFC490>, return_train_score=False, kwargs={})
2022-04-17 19:24:26,802:INFO:Checking exceptions
2022-04-17 19:24:26,803:INFO:Importing libraries
2022-04-17 19:24:26,805:INFO:Copying training dataset
2022-04-17 19:24:26,901:INFO:Defining folds
2022-04-17 19:24:26,903:INFO:Declaring metric variables
2022-04-17 19:24:26,938:INFO:Importing untrained model
2022-04-17 19:24:26,971:INFO:Linear Discriminant Analysis Imported succesfully
2022-04-17 19:24:27,029:INFO:Starting cross validation
2022-04-17 19:24:27,031:INFO:Cross validating with StratifiedKFold(n_splits=10, random_state=None, shuffle=False), n_jobs=-1
2022-04-17 19:24:27,034:WARNING:create_model() for lda raised an exception or returned all 0.0, trying without fit_kwargs:
2022-04-17 19:24:27,042:WARNING:Traceback (most recent call last):
  File "C:\Users\8prab\.conda\envs\ee\lib\site-packages\pycaret\internal\tabular.py", line 2203, in compare_models
    model, model_fit_time = create_model_supervised(**create_model_args)
  File "C:\Users\8prab\.conda\envs\ee\lib\site-packages\pycaret\internal\tabular.py", line 3200, in create_model_supervised
    scores = cross_validate(
  File "C:\Users\8prab\.conda\envs\ee\lib\site-packages\sklearn\utils\validation.py", line 72, in inner_f
    return f(**kwargs)
  File "C:\Users\8prab\.conda\envs\ee\lib\site-packages\sklearn\model_selection\_validation.py", line 242, in cross_validate
    scores = parallel(
  File "C:\Users\8prab\AppData\Roaming\Python\Python38\site-packages\joblib\parallel.py", line 968, in __call__
    n_jobs = self._initialize_backend()
  File "C:\Users\8prab\AppData\Roaming\Python\Python38\site-packages\joblib\parallel.py", line 735, in _initialize_backend
    n_jobs = self._backend.configure(n_jobs=self.n_jobs, parallel=self,
  File "C:\Users\8prab\AppData\Roaming\Python\Python38\site-packages\joblib\_parallel_backends.py", line 494, in configure
    self._workers = get_memmapping_executor(
  File "C:\Users\8prab\AppData\Roaming\Python\Python38\site-packages\joblib\executor.py", line 20, in get_memmapping_executor
    return MemmappingExecutor.get_memmapping_executor(n_jobs, **kwargs)
  File "C:\Users\8prab\AppData\Roaming\Python\Python38\site-packages\joblib\executor.py", line 42, in get_memmapping_executor
    manager = TemporaryResourcesManager(temp_folder)
  File "C:\Users\8prab\AppData\Roaming\Python\Python38\site-packages\joblib\_memmapping_reducer.py", line 531, in __init__
    self.set_current_context(context_id)
  File "C:\Users\8prab\AppData\Roaming\Python\Python38\site-packages\joblib\_memmapping_reducer.py", line 535, in set_current_context
    self.register_new_context(context_id)
  File "C:\Users\8prab\AppData\Roaming\Python\Python38\site-packages\joblib\_memmapping_reducer.py", line 560, in register_new_context
    self.register_folder_finalizer(new_folder_path, context_id)
  File "C:\Users\8prab\AppData\Roaming\Python\Python38\site-packages\joblib\_memmapping_reducer.py", line 590, in register_folder_finalizer
    resource_tracker.register(pool_subfolder, "folder")
  File "C:\Users\8prab\AppData\Roaming\Python\Python38\site-packages\joblib\externals\loky\backend\resource_tracker.py", line 190, in register
    self.ensure_running()
  File "C:\Users\8prab\AppData\Roaming\Python\Python38\site-packages\joblib\externals\loky\backend\resource_tracker.py", line 102, in ensure_running
    if self._check_alive():
  File "C:\Users\8prab\AppData\Roaming\Python\Python38\site-packages\joblib\externals\loky\backend\resource_tracker.py", line 182, in _check_alive
    self._send('PROBE', '', '')
  File "C:\Users\8prab\AppData\Roaming\Python\Python38\site-packages\joblib\externals\loky\backend\resource_tracker.py", line 209, in _send
    nbytes = os.write(self._fd, msg)
OSError: [Errno 22] Invalid argument

2022-04-17 19:24:27,045:INFO:Initializing create_model()
2022-04-17 19:24:27,047:INFO:create_model(estimator=lda, fold=StratifiedKFold(n_splits=10, random_state=None, shuffle=False), round=4, cross_validation=True, predict=True, fit_kwargs={}, groups=None, refit=False, verbose=False, system=False, metrics=None, experiment_custom_tags=None, add_to_model_list=True, probability_threshold=None, display=<pycaret.internal.Display.Display object at 0x000001D75ACFC490>, return_train_score=False, kwargs={})
2022-04-17 19:24:27,048:INFO:Checking exceptions
2022-04-17 19:24:27,065:INFO:Importing libraries
2022-04-17 19:24:27,067:INFO:Copying training dataset
2022-04-17 19:24:27,166:INFO:Defining folds
2022-04-17 19:24:27,168:INFO:Declaring metric variables
2022-04-17 19:24:27,194:INFO:Importing untrained model
2022-04-17 19:24:27,218:INFO:Linear Discriminant Analysis Imported succesfully
2022-04-17 19:24:27,271:INFO:Starting cross validation
2022-04-17 19:24:27,275:INFO:Cross validating with StratifiedKFold(n_splits=10, random_state=None, shuffle=False), n_jobs=-1
2022-04-17 19:24:27,282:ERROR:create_model() for lda raised an exception or returned all 0.0:
2022-04-17 19:24:27,288:ERROR:Traceback (most recent call last):
  File "C:\Users\8prab\.conda\envs\ee\lib\site-packages\pycaret\internal\tabular.py", line 2203, in compare_models
    model, model_fit_time = create_model_supervised(**create_model_args)
  File "C:\Users\8prab\.conda\envs\ee\lib\site-packages\pycaret\internal\tabular.py", line 3200, in create_model_supervised
    scores = cross_validate(
  File "C:\Users\8prab\.conda\envs\ee\lib\site-packages\sklearn\utils\validation.py", line 72, in inner_f
    return f(**kwargs)
  File "C:\Users\8prab\.conda\envs\ee\lib\site-packages\sklearn\model_selection\_validation.py", line 242, in cross_validate
    scores = parallel(
  File "C:\Users\8prab\AppData\Roaming\Python\Python38\site-packages\joblib\parallel.py", line 968, in __call__
    n_jobs = self._initialize_backend()
  File "C:\Users\8prab\AppData\Roaming\Python\Python38\site-packages\joblib\parallel.py", line 735, in _initialize_backend
    n_jobs = self._backend.configure(n_jobs=self.n_jobs, parallel=self,
  File "C:\Users\8prab\AppData\Roaming\Python\Python38\site-packages\joblib\_parallel_backends.py", line 494, in configure
    self._workers = get_memmapping_executor(
  File "C:\Users\8prab\AppData\Roaming\Python\Python38\site-packages\joblib\executor.py", line 20, in get_memmapping_executor
    return MemmappingExecutor.get_memmapping_executor(n_jobs, **kwargs)
  File "C:\Users\8prab\AppData\Roaming\Python\Python38\site-packages\joblib\executor.py", line 42, in get_memmapping_executor
    manager = TemporaryResourcesManager(temp_folder)
  File "C:\Users\8prab\AppData\Roaming\Python\Python38\site-packages\joblib\_memmapping_reducer.py", line 531, in __init__
    self.set_current_context(context_id)
  File "C:\Users\8prab\AppData\Roaming\Python\Python38\site-packages\joblib\_memmapping_reducer.py", line 535, in set_current_context
    self.register_new_context(context_id)
  File "C:\Users\8prab\AppData\Roaming\Python\Python38\site-packages\joblib\_memmapping_reducer.py", line 560, in register_new_context
    self.register_folder_finalizer(new_folder_path, context_id)
  File "C:\Users\8prab\AppData\Roaming\Python\Python38\site-packages\joblib\_memmapping_reducer.py", line 590, in register_folder_finalizer
    resource_tracker.register(pool_subfolder, "folder")
  File "C:\Users\8prab\AppData\Roaming\Python\Python38\site-packages\joblib\externals\loky\backend\resource_tracker.py", line 190, in register
    self.ensure_running()
  File "C:\Users\8prab\AppData\Roaming\Python\Python38\site-packages\joblib\externals\loky\backend\resource_tracker.py", line 102, in ensure_running
    if self._check_alive():
  File "C:\Users\8prab\AppData\Roaming\Python\Python38\site-packages\joblib\externals\loky\backend\resource_tracker.py", line 182, in _check_alive
    self._send('PROBE', '', '')
  File "C:\Users\8prab\AppData\Roaming\Python\Python38\site-packages\joblib\externals\loky\backend\resource_tracker.py", line 209, in _send
    nbytes = os.write(self._fd, msg)
OSError: [Errno 22] Invalid argument

During handling of the above exception, another exception occurred:

Traceback (most recent call last):
  File "C:\Users\8prab\.conda\envs\ee\lib\site-packages\pycaret\internal\tabular.py", line 2212, in compare_models
    model, model_fit_time = create_model_supervised(**create_model_args)
  File "C:\Users\8prab\.conda\envs\ee\lib\site-packages\pycaret\internal\tabular.py", line 3200, in create_model_supervised
    scores = cross_validate(
  File "C:\Users\8prab\.conda\envs\ee\lib\site-packages\sklearn\utils\validation.py", line 72, in inner_f
    return f(**kwargs)
  File "C:\Users\8prab\.conda\envs\ee\lib\site-packages\sklearn\model_selection\_validation.py", line 242, in cross_validate
    scores = parallel(
  File "C:\Users\8prab\AppData\Roaming\Python\Python38\site-packages\joblib\parallel.py", line 968, in __call__
    n_jobs = self._initialize_backend()
  File "C:\Users\8prab\AppData\Roaming\Python\Python38\site-packages\joblib\parallel.py", line 735, in _initialize_backend
    n_jobs = self._backend.configure(n_jobs=self.n_jobs, parallel=self,
  File "C:\Users\8prab\AppData\Roaming\Python\Python38\site-packages\joblib\_parallel_backends.py", line 494, in configure
    self._workers = get_memmapping_executor(
  File "C:\Users\8prab\AppData\Roaming\Python\Python38\site-packages\joblib\executor.py", line 20, in get_memmapping_executor
    return MemmappingExecutor.get_memmapping_executor(n_jobs, **kwargs)
  File "C:\Users\8prab\AppData\Roaming\Python\Python38\site-packages\joblib\executor.py", line 42, in get_memmapping_executor
    manager = TemporaryResourcesManager(temp_folder)
  File "C:\Users\8prab\AppData\Roaming\Python\Python38\site-packages\joblib\_memmapping_reducer.py", line 531, in __init__
    self.set_current_context(context_id)
  File "C:\Users\8prab\AppData\Roaming\Python\Python38\site-packages\joblib\_memmapping_reducer.py", line 535, in set_current_context
    self.register_new_context(context_id)
  File "C:\Users\8prab\AppData\Roaming\Python\Python38\site-packages\joblib\_memmapping_reducer.py", line 560, in register_new_context
    self.register_folder_finalizer(new_folder_path, context_id)
  File "C:\Users\8prab\AppData\Roaming\Python\Python38\site-packages\joblib\_memmapping_reducer.py", line 590, in register_folder_finalizer
    resource_tracker.register(pool_subfolder, "folder")
  File "C:\Users\8prab\AppData\Roaming\Python\Python38\site-packages\joblib\externals\loky\backend\resource_tracker.py", line 190, in register
    self.ensure_running()
  File "C:\Users\8prab\AppData\Roaming\Python\Python38\site-packages\joblib\externals\loky\backend\resource_tracker.py", line 102, in ensure_running
    if self._check_alive():
  File "C:\Users\8prab\AppData\Roaming\Python\Python38\site-packages\joblib\externals\loky\backend\resource_tracker.py", line 182, in _check_alive
    self._send('PROBE', '', '')
  File "C:\Users\8prab\AppData\Roaming\Python\Python38\site-packages\joblib\externals\loky\backend\resource_tracker.py", line 209, in _send
    nbytes = os.write(self._fd, msg)
OSError: [Errno 22] Invalid argument

2022-04-17 19:24:27,331:INFO:Initializing Extra Trees Classifier
2022-04-17 19:24:27,336:INFO:Total runtime is 0.11346938212712605 minutes
2022-04-17 19:24:27,375:INFO:SubProcess create_model() called ==================================
2022-04-17 19:24:27,377:INFO:Initializing create_model()
2022-04-17 19:24:27,379:INFO:create_model(estimator=et, fold=StratifiedKFold(n_splits=10, random_state=None, shuffle=False), round=4, cross_validation=True, predict=True, fit_kwargs={}, groups=None, refit=False, verbose=False, system=False, metrics=None, experiment_custom_tags=None, add_to_model_list=True, probability_threshold=None, display=<pycaret.internal.Display.Display object at 0x000001D75ACFC490>, return_train_score=False, kwargs={})
2022-04-17 19:24:27,380:INFO:Checking exceptions
2022-04-17 19:24:27,381:INFO:Importing libraries
2022-04-17 19:24:27,382:INFO:Copying training dataset
2022-04-17 19:24:27,537:INFO:Defining folds
2022-04-17 19:24:27,540:INFO:Declaring metric variables
2022-04-17 19:24:27,572:INFO:Importing untrained model
2022-04-17 19:24:27,633:INFO:Extra Trees Classifier Imported succesfully
2022-04-17 19:24:27,689:INFO:Starting cross validation
2022-04-17 19:24:27,694:INFO:Cross validating with StratifiedKFold(n_splits=10, random_state=None, shuffle=False), n_jobs=-1
2022-04-17 19:24:27,699:WARNING:create_model() for et raised an exception or returned all 0.0, trying without fit_kwargs:
2022-04-17 19:24:27,704:WARNING:Traceback (most recent call last):
  File "C:\Users\8prab\.conda\envs\ee\lib\site-packages\pycaret\internal\tabular.py", line 2203, in compare_models
    model, model_fit_time = create_model_supervised(**create_model_args)
  File "C:\Users\8prab\.conda\envs\ee\lib\site-packages\pycaret\internal\tabular.py", line 3200, in create_model_supervised
    scores = cross_validate(
  File "C:\Users\8prab\.conda\envs\ee\lib\site-packages\sklearn\utils\validation.py", line 72, in inner_f
    return f(**kwargs)
  File "C:\Users\8prab\.conda\envs\ee\lib\site-packages\sklearn\model_selection\_validation.py", line 242, in cross_validate
    scores = parallel(
  File "C:\Users\8prab\AppData\Roaming\Python\Python38\site-packages\joblib\parallel.py", line 968, in __call__
    n_jobs = self._initialize_backend()
  File "C:\Users\8prab\AppData\Roaming\Python\Python38\site-packages\joblib\parallel.py", line 735, in _initialize_backend
    n_jobs = self._backend.configure(n_jobs=self.n_jobs, parallel=self,
  File "C:\Users\8prab\AppData\Roaming\Python\Python38\site-packages\joblib\_parallel_backends.py", line 494, in configure
    self._workers = get_memmapping_executor(
  File "C:\Users\8prab\AppData\Roaming\Python\Python38\site-packages\joblib\executor.py", line 20, in get_memmapping_executor
    return MemmappingExecutor.get_memmapping_executor(n_jobs, **kwargs)
  File "C:\Users\8prab\AppData\Roaming\Python\Python38\site-packages\joblib\executor.py", line 42, in get_memmapping_executor
    manager = TemporaryResourcesManager(temp_folder)
  File "C:\Users\8prab\AppData\Roaming\Python\Python38\site-packages\joblib\_memmapping_reducer.py", line 531, in __init__
    self.set_current_context(context_id)
  File "C:\Users\8prab\AppData\Roaming\Python\Python38\site-packages\joblib\_memmapping_reducer.py", line 535, in set_current_context
    self.register_new_context(context_id)
  File "C:\Users\8prab\AppData\Roaming\Python\Python38\site-packages\joblib\_memmapping_reducer.py", line 560, in register_new_context
    self.register_folder_finalizer(new_folder_path, context_id)
  File "C:\Users\8prab\AppData\Roaming\Python\Python38\site-packages\joblib\_memmapping_reducer.py", line 590, in register_folder_finalizer
    resource_tracker.register(pool_subfolder, "folder")
  File "C:\Users\8prab\AppData\Roaming\Python\Python38\site-packages\joblib\externals\loky\backend\resource_tracker.py", line 190, in register
    self.ensure_running()
  File "C:\Users\8prab\AppData\Roaming\Python\Python38\site-packages\joblib\externals\loky\backend\resource_tracker.py", line 102, in ensure_running
    if self._check_alive():
  File "C:\Users\8prab\AppData\Roaming\Python\Python38\site-packages\joblib\externals\loky\backend\resource_tracker.py", line 182, in _check_alive
    self._send('PROBE', '', '')
  File "C:\Users\8prab\AppData\Roaming\Python\Python38\site-packages\joblib\externals\loky\backend\resource_tracker.py", line 209, in _send
    nbytes = os.write(self._fd, msg)
OSError: [Errno 22] Invalid argument

2022-04-17 19:24:27,707:INFO:Initializing create_model()
2022-04-17 19:24:27,728:INFO:create_model(estimator=et, fold=StratifiedKFold(n_splits=10, random_state=None, shuffle=False), round=4, cross_validation=True, predict=True, fit_kwargs={}, groups=None, refit=False, verbose=False, system=False, metrics=None, experiment_custom_tags=None, add_to_model_list=True, probability_threshold=None, display=<pycaret.internal.Display.Display object at 0x000001D75ACFC490>, return_train_score=False, kwargs={})
2022-04-17 19:24:27,734:INFO:Checking exceptions
2022-04-17 19:24:27,736:INFO:Importing libraries
2022-04-17 19:24:27,739:INFO:Copying training dataset
2022-04-17 19:24:27,837:INFO:Defining folds
2022-04-17 19:24:27,839:INFO:Declaring metric variables
2022-04-17 19:24:27,867:INFO:Importing untrained model
2022-04-17 19:24:27,897:INFO:Extra Trees Classifier Imported succesfully
2022-04-17 19:24:27,940:INFO:Starting cross validation
2022-04-17 19:24:27,945:INFO:Cross validating with StratifiedKFold(n_splits=10, random_state=None, shuffle=False), n_jobs=-1
2022-04-17 19:24:27,951:ERROR:create_model() for et raised an exception or returned all 0.0:
2022-04-17 19:24:27,959:ERROR:Traceback (most recent call last):
  File "C:\Users\8prab\.conda\envs\ee\lib\site-packages\pycaret\internal\tabular.py", line 2203, in compare_models
    model, model_fit_time = create_model_supervised(**create_model_args)
  File "C:\Users\8prab\.conda\envs\ee\lib\site-packages\pycaret\internal\tabular.py", line 3200, in create_model_supervised
    scores = cross_validate(
  File "C:\Users\8prab\.conda\envs\ee\lib\site-packages\sklearn\utils\validation.py", line 72, in inner_f
    return f(**kwargs)
  File "C:\Users\8prab\.conda\envs\ee\lib\site-packages\sklearn\model_selection\_validation.py", line 242, in cross_validate
    scores = parallel(
  File "C:\Users\8prab\AppData\Roaming\Python\Python38\site-packages\joblib\parallel.py", line 968, in __call__
    n_jobs = self._initialize_backend()
  File "C:\Users\8prab\AppData\Roaming\Python\Python38\site-packages\joblib\parallel.py", line 735, in _initialize_backend
    n_jobs = self._backend.configure(n_jobs=self.n_jobs, parallel=self,
  File "C:\Users\8prab\AppData\Roaming\Python\Python38\site-packages\joblib\_parallel_backends.py", line 494, in configure
    self._workers = get_memmapping_executor(
  File "C:\Users\8prab\AppData\Roaming\Python\Python38\site-packages\joblib\executor.py", line 20, in get_memmapping_executor
    return MemmappingExecutor.get_memmapping_executor(n_jobs, **kwargs)
  File "C:\Users\8prab\AppData\Roaming\Python\Python38\site-packages\joblib\executor.py", line 42, in get_memmapping_executor
    manager = TemporaryResourcesManager(temp_folder)
  File "C:\Users\8prab\AppData\Roaming\Python\Python38\site-packages\joblib\_memmapping_reducer.py", line 531, in __init__
    self.set_current_context(context_id)
  File "C:\Users\8prab\AppData\Roaming\Python\Python38\site-packages\joblib\_memmapping_reducer.py", line 535, in set_current_context
    self.register_new_context(context_id)
  File "C:\Users\8prab\AppData\Roaming\Python\Python38\site-packages\joblib\_memmapping_reducer.py", line 560, in register_new_context
    self.register_folder_finalizer(new_folder_path, context_id)
  File "C:\Users\8prab\AppData\Roaming\Python\Python38\site-packages\joblib\_memmapping_reducer.py", line 590, in register_folder_finalizer
    resource_tracker.register(pool_subfolder, "folder")
  File "C:\Users\8prab\AppData\Roaming\Python\Python38\site-packages\joblib\externals\loky\backend\resource_tracker.py", line 190, in register
    self.ensure_running()
  File "C:\Users\8prab\AppData\Roaming\Python\Python38\site-packages\joblib\externals\loky\backend\resource_tracker.py", line 102, in ensure_running
    if self._check_alive():
  File "C:\Users\8prab\AppData\Roaming\Python\Python38\site-packages\joblib\externals\loky\backend\resource_tracker.py", line 182, in _check_alive
    self._send('PROBE', '', '')
  File "C:\Users\8prab\AppData\Roaming\Python\Python38\site-packages\joblib\externals\loky\backend\resource_tracker.py", line 209, in _send
    nbytes = os.write(self._fd, msg)
OSError: [Errno 22] Invalid argument

During handling of the above exception, another exception occurred:

Traceback (most recent call last):
  File "C:\Users\8prab\.conda\envs\ee\lib\site-packages\pycaret\internal\tabular.py", line 2212, in compare_models
    model, model_fit_time = create_model_supervised(**create_model_args)
  File "C:\Users\8prab\.conda\envs\ee\lib\site-packages\pycaret\internal\tabular.py", line 3200, in create_model_supervised
    scores = cross_validate(
  File "C:\Users\8prab\.conda\envs\ee\lib\site-packages\sklearn\utils\validation.py", line 72, in inner_f
    return f(**kwargs)
  File "C:\Users\8prab\.conda\envs\ee\lib\site-packages\sklearn\model_selection\_validation.py", line 242, in cross_validate
    scores = parallel(
  File "C:\Users\8prab\AppData\Roaming\Python\Python38\site-packages\joblib\parallel.py", line 968, in __call__
    n_jobs = self._initialize_backend()
  File "C:\Users\8prab\AppData\Roaming\Python\Python38\site-packages\joblib\parallel.py", line 735, in _initialize_backend
    n_jobs = self._backend.configure(n_jobs=self.n_jobs, parallel=self,
  File "C:\Users\8prab\AppData\Roaming\Python\Python38\site-packages\joblib\_parallel_backends.py", line 494, in configure
    self._workers = get_memmapping_executor(
  File "C:\Users\8prab\AppData\Roaming\Python\Python38\site-packages\joblib\executor.py", line 20, in get_memmapping_executor
    return MemmappingExecutor.get_memmapping_executor(n_jobs, **kwargs)
  File "C:\Users\8prab\AppData\Roaming\Python\Python38\site-packages\joblib\executor.py", line 42, in get_memmapping_executor
    manager = TemporaryResourcesManager(temp_folder)
  File "C:\Users\8prab\AppData\Roaming\Python\Python38\site-packages\joblib\_memmapping_reducer.py", line 531, in __init__
    self.set_current_context(context_id)
  File "C:\Users\8prab\AppData\Roaming\Python\Python38\site-packages\joblib\_memmapping_reducer.py", line 535, in set_current_context
    self.register_new_context(context_id)
  File "C:\Users\8prab\AppData\Roaming\Python\Python38\site-packages\joblib\_memmapping_reducer.py", line 560, in register_new_context
    self.register_folder_finalizer(new_folder_path, context_id)
  File "C:\Users\8prab\AppData\Roaming\Python\Python38\site-packages\joblib\_memmapping_reducer.py", line 590, in register_folder_finalizer
    resource_tracker.register(pool_subfolder, "folder")
  File "C:\Users\8prab\AppData\Roaming\Python\Python38\site-packages\joblib\externals\loky\backend\resource_tracker.py", line 190, in register
    self.ensure_running()
  File "C:\Users\8prab\AppData\Roaming\Python\Python38\site-packages\joblib\externals\loky\backend\resource_tracker.py", line 102, in ensure_running
    if self._check_alive():
  File "C:\Users\8prab\AppData\Roaming\Python\Python38\site-packages\joblib\externals\loky\backend\resource_tracker.py", line 182, in _check_alive
    self._send('PROBE', '', '')
  File "C:\Users\8prab\AppData\Roaming\Python\Python38\site-packages\joblib\externals\loky\backend\resource_tracker.py", line 209, in _send
    nbytes = os.write(self._fd, msg)
OSError: [Errno 22] Invalid argument

2022-04-17 19:24:28,008:INFO:Initializing Extreme Gradient Boosting
2022-04-17 19:24:28,012:INFO:Total runtime is 0.12473390102386474 minutes
2022-04-17 19:24:28,036:INFO:SubProcess create_model() called ==================================
2022-04-17 19:24:28,042:INFO:Initializing create_model()
2022-04-17 19:24:28,045:INFO:create_model(estimator=xgboost, fold=StratifiedKFold(n_splits=10, random_state=None, shuffle=False), round=4, cross_validation=True, predict=True, fit_kwargs={}, groups=None, refit=False, verbose=False, system=False, metrics=None, experiment_custom_tags=None, add_to_model_list=True, probability_threshold=None, display=<pycaret.internal.Display.Display object at 0x000001D75ACFC490>, return_train_score=False, kwargs={})
2022-04-17 19:24:28,049:INFO:Checking exceptions
2022-04-17 19:24:28,052:INFO:Importing libraries
2022-04-17 19:24:28,053:INFO:Copying training dataset
2022-04-17 19:24:28,149:INFO:Defining folds
2022-04-17 19:24:28,151:INFO:Declaring metric variables
2022-04-17 19:24:28,176:INFO:Importing untrained model
2022-04-17 19:24:28,222:INFO:Extreme Gradient Boosting Imported succesfully
2022-04-17 19:24:28,294:INFO:Starting cross validation
2022-04-17 19:24:28,300:INFO:Cross validating with StratifiedKFold(n_splits=10, random_state=None, shuffle=False), n_jobs=-1
2022-04-17 19:24:28,304:WARNING:create_model() for xgboost raised an exception or returned all 0.0, trying without fit_kwargs:
2022-04-17 19:24:28,308:WARNING:Traceback (most recent call last):
  File "C:\Users\8prab\.conda\envs\ee\lib\site-packages\pycaret\internal\tabular.py", line 2203, in compare_models
    model, model_fit_time = create_model_supervised(**create_model_args)
  File "C:\Users\8prab\.conda\envs\ee\lib\site-packages\pycaret\internal\tabular.py", line 3200, in create_model_supervised
    scores = cross_validate(
  File "C:\Users\8prab\.conda\envs\ee\lib\site-packages\sklearn\utils\validation.py", line 72, in inner_f
    return f(**kwargs)
  File "C:\Users\8prab\.conda\envs\ee\lib\site-packages\sklearn\model_selection\_validation.py", line 242, in cross_validate
    scores = parallel(
  File "C:\Users\8prab\AppData\Roaming\Python\Python38\site-packages\joblib\parallel.py", line 968, in __call__
    n_jobs = self._initialize_backend()
  File "C:\Users\8prab\AppData\Roaming\Python\Python38\site-packages\joblib\parallel.py", line 735, in _initialize_backend
    n_jobs = self._backend.configure(n_jobs=self.n_jobs, parallel=self,
  File "C:\Users\8prab\AppData\Roaming\Python\Python38\site-packages\joblib\_parallel_backends.py", line 494, in configure
    self._workers = get_memmapping_executor(
  File "C:\Users\8prab\AppData\Roaming\Python\Python38\site-packages\joblib\executor.py", line 20, in get_memmapping_executor
    return MemmappingExecutor.get_memmapping_executor(n_jobs, **kwargs)
  File "C:\Users\8prab\AppData\Roaming\Python\Python38\site-packages\joblib\executor.py", line 42, in get_memmapping_executor
    manager = TemporaryResourcesManager(temp_folder)
  File "C:\Users\8prab\AppData\Roaming\Python\Python38\site-packages\joblib\_memmapping_reducer.py", line 531, in __init__
    self.set_current_context(context_id)
  File "C:\Users\8prab\AppData\Roaming\Python\Python38\site-packages\joblib\_memmapping_reducer.py", line 535, in set_current_context
    self.register_new_context(context_id)
  File "C:\Users\8prab\AppData\Roaming\Python\Python38\site-packages\joblib\_memmapping_reducer.py", line 560, in register_new_context
    self.register_folder_finalizer(new_folder_path, context_id)
  File "C:\Users\8prab\AppData\Roaming\Python\Python38\site-packages\joblib\_memmapping_reducer.py", line 590, in register_folder_finalizer
    resource_tracker.register(pool_subfolder, "folder")
  File "C:\Users\8prab\AppData\Roaming\Python\Python38\site-packages\joblib\externals\loky\backend\resource_tracker.py", line 190, in register
    self.ensure_running()
  File "C:\Users\8prab\AppData\Roaming\Python\Python38\site-packages\joblib\externals\loky\backend\resource_tracker.py", line 102, in ensure_running
    if self._check_alive():
  File "C:\Users\8prab\AppData\Roaming\Python\Python38\site-packages\joblib\externals\loky\backend\resource_tracker.py", line 182, in _check_alive
    self._send('PROBE', '', '')
  File "C:\Users\8prab\AppData\Roaming\Python\Python38\site-packages\joblib\externals\loky\backend\resource_tracker.py", line 209, in _send
    nbytes = os.write(self._fd, msg)
OSError: [Errno 22] Invalid argument

2022-04-17 19:24:28,312:INFO:Initializing create_model()
2022-04-17 19:24:28,316:INFO:create_model(estimator=xgboost, fold=StratifiedKFold(n_splits=10, random_state=None, shuffle=False), round=4, cross_validation=True, predict=True, fit_kwargs={}, groups=None, refit=False, verbose=False, system=False, metrics=None, experiment_custom_tags=None, add_to_model_list=True, probability_threshold=None, display=<pycaret.internal.Display.Display object at 0x000001D75ACFC490>, return_train_score=False, kwargs={})
2022-04-17 19:24:28,318:INFO:Checking exceptions
2022-04-17 19:24:28,321:INFO:Importing libraries
2022-04-17 19:24:28,323:INFO:Copying training dataset
2022-04-17 19:24:28,412:INFO:Defining folds
2022-04-17 19:24:28,416:INFO:Declaring metric variables
2022-04-17 19:24:28,453:INFO:Importing untrained model
2022-04-17 19:24:28,497:INFO:Extreme Gradient Boosting Imported succesfully
2022-04-17 19:24:28,604:INFO:Starting cross validation
2022-04-17 19:24:28,616:INFO:Cross validating with StratifiedKFold(n_splits=10, random_state=None, shuffle=False), n_jobs=-1
2022-04-17 19:24:28,621:ERROR:create_model() for xgboost raised an exception or returned all 0.0:
2022-04-17 19:24:28,632:ERROR:Traceback (most recent call last):
  File "C:\Users\8prab\.conda\envs\ee\lib\site-packages\pycaret\internal\tabular.py", line 2203, in compare_models
    model, model_fit_time = create_model_supervised(**create_model_args)
  File "C:\Users\8prab\.conda\envs\ee\lib\site-packages\pycaret\internal\tabular.py", line 3200, in create_model_supervised
    scores = cross_validate(
  File "C:\Users\8prab\.conda\envs\ee\lib\site-packages\sklearn\utils\validation.py", line 72, in inner_f
    return f(**kwargs)
  File "C:\Users\8prab\.conda\envs\ee\lib\site-packages\sklearn\model_selection\_validation.py", line 242, in cross_validate
    scores = parallel(
  File "C:\Users\8prab\AppData\Roaming\Python\Python38\site-packages\joblib\parallel.py", line 968, in __call__
    n_jobs = self._initialize_backend()
  File "C:\Users\8prab\AppData\Roaming\Python\Python38\site-packages\joblib\parallel.py", line 735, in _initialize_backend
    n_jobs = self._backend.configure(n_jobs=self.n_jobs, parallel=self,
  File "C:\Users\8prab\AppData\Roaming\Python\Python38\site-packages\joblib\_parallel_backends.py", line 494, in configure
    self._workers = get_memmapping_executor(
  File "C:\Users\8prab\AppData\Roaming\Python\Python38\site-packages\joblib\executor.py", line 20, in get_memmapping_executor
    return MemmappingExecutor.get_memmapping_executor(n_jobs, **kwargs)
  File "C:\Users\8prab\AppData\Roaming\Python\Python38\site-packages\joblib\executor.py", line 42, in get_memmapping_executor
    manager = TemporaryResourcesManager(temp_folder)
  File "C:\Users\8prab\AppData\Roaming\Python\Python38\site-packages\joblib\_memmapping_reducer.py", line 531, in __init__
    self.set_current_context(context_id)
  File "C:\Users\8prab\AppData\Roaming\Python\Python38\site-packages\joblib\_memmapping_reducer.py", line 535, in set_current_context
    self.register_new_context(context_id)
  File "C:\Users\8prab\AppData\Roaming\Python\Python38\site-packages\joblib\_memmapping_reducer.py", line 560, in register_new_context
    self.register_folder_finalizer(new_folder_path, context_id)
  File "C:\Users\8prab\AppData\Roaming\Python\Python38\site-packages\joblib\_memmapping_reducer.py", line 590, in register_folder_finalizer
    resource_tracker.register(pool_subfolder, "folder")
  File "C:\Users\8prab\AppData\Roaming\Python\Python38\site-packages\joblib\externals\loky\backend\resource_tracker.py", line 190, in register
    self.ensure_running()
  File "C:\Users\8prab\AppData\Roaming\Python\Python38\site-packages\joblib\externals\loky\backend\resource_tracker.py", line 102, in ensure_running
    if self._check_alive():
  File "C:\Users\8prab\AppData\Roaming\Python\Python38\site-packages\joblib\externals\loky\backend\resource_tracker.py", line 182, in _check_alive
    self._send('PROBE', '', '')
  File "C:\Users\8prab\AppData\Roaming\Python\Python38\site-packages\joblib\externals\loky\backend\resource_tracker.py", line 209, in _send
    nbytes = os.write(self._fd, msg)
OSError: [Errno 22] Invalid argument

During handling of the above exception, another exception occurred:

Traceback (most recent call last):
  File "C:\Users\8prab\.conda\envs\ee\lib\site-packages\pycaret\internal\tabular.py", line 2212, in compare_models
    model, model_fit_time = create_model_supervised(**create_model_args)
  File "C:\Users\8prab\.conda\envs\ee\lib\site-packages\pycaret\internal\tabular.py", line 3200, in create_model_supervised
    scores = cross_validate(
  File "C:\Users\8prab\.conda\envs\ee\lib\site-packages\sklearn\utils\validation.py", line 72, in inner_f
    return f(**kwargs)
  File "C:\Users\8prab\.conda\envs\ee\lib\site-packages\sklearn\model_selection\_validation.py", line 242, in cross_validate
    scores = parallel(
  File "C:\Users\8prab\AppData\Roaming\Python\Python38\site-packages\joblib\parallel.py", line 968, in __call__
    n_jobs = self._initialize_backend()
  File "C:\Users\8prab\AppData\Roaming\Python\Python38\site-packages\joblib\parallel.py", line 735, in _initialize_backend
    n_jobs = self._backend.configure(n_jobs=self.n_jobs, parallel=self,
  File "C:\Users\8prab\AppData\Roaming\Python\Python38\site-packages\joblib\_parallel_backends.py", line 494, in configure
    self._workers = get_memmapping_executor(
  File "C:\Users\8prab\AppData\Roaming\Python\Python38\site-packages\joblib\executor.py", line 20, in get_memmapping_executor
    return MemmappingExecutor.get_memmapping_executor(n_jobs, **kwargs)
  File "C:\Users\8prab\AppData\Roaming\Python\Python38\site-packages\joblib\executor.py", line 42, in get_memmapping_executor
    manager = TemporaryResourcesManager(temp_folder)
  File "C:\Users\8prab\AppData\Roaming\Python\Python38\site-packages\joblib\_memmapping_reducer.py", line 531, in __init__
    self.set_current_context(context_id)
  File "C:\Users\8prab\AppData\Roaming\Python\Python38\site-packages\joblib\_memmapping_reducer.py", line 535, in set_current_context
    self.register_new_context(context_id)
  File "C:\Users\8prab\AppData\Roaming\Python\Python38\site-packages\joblib\_memmapping_reducer.py", line 560, in register_new_context
    self.register_folder_finalizer(new_folder_path, context_id)
  File "C:\Users\8prab\AppData\Roaming\Python\Python38\site-packages\joblib\_memmapping_reducer.py", line 590, in register_folder_finalizer
    resource_tracker.register(pool_subfolder, "folder")
  File "C:\Users\8prab\AppData\Roaming\Python\Python38\site-packages\joblib\externals\loky\backend\resource_tracker.py", line 190, in register
    self.ensure_running()
  File "C:\Users\8prab\AppData\Roaming\Python\Python38\site-packages\joblib\externals\loky\backend\resource_tracker.py", line 102, in ensure_running
    if self._check_alive():
  File "C:\Users\8prab\AppData\Roaming\Python\Python38\site-packages\joblib\externals\loky\backend\resource_tracker.py", line 182, in _check_alive
    self._send('PROBE', '', '')
  File "C:\Users\8prab\AppData\Roaming\Python\Python38\site-packages\joblib\externals\loky\backend\resource_tracker.py", line 209, in _send
    nbytes = os.write(self._fd, msg)
OSError: [Errno 22] Invalid argument

2022-04-17 19:24:28,702:INFO:Initializing Light Gradient Boosting Machine
2022-04-17 19:24:28,705:INFO:Total runtime is 0.13628635406494138 minutes
2022-04-17 19:24:28,737:INFO:SubProcess create_model() called ==================================
2022-04-17 19:24:28,743:INFO:Initializing create_model()
2022-04-17 19:24:28,746:INFO:create_model(estimator=lightgbm, fold=StratifiedKFold(n_splits=10, random_state=None, shuffle=False), round=4, cross_validation=True, predict=True, fit_kwargs={}, groups=None, refit=False, verbose=False, system=False, metrics=None, experiment_custom_tags=None, add_to_model_list=True, probability_threshold=None, display=<pycaret.internal.Display.Display object at 0x000001D75ACFC490>, return_train_score=False, kwargs={})
2022-04-17 19:24:28,748:INFO:Checking exceptions
2022-04-17 19:24:28,751:INFO:Importing libraries
2022-04-17 19:24:28,755:INFO:Copying training dataset
2022-04-17 19:24:28,859:INFO:Defining folds
2022-04-17 19:24:28,864:INFO:Declaring metric variables
2022-04-17 19:24:28,897:INFO:Importing untrained model
2022-04-17 19:24:28,920:INFO:Light Gradient Boosting Machine Imported succesfully
2022-04-17 19:24:28,983:INFO:Starting cross validation
2022-04-17 19:24:28,986:INFO:Cross validating with StratifiedKFold(n_splits=10, random_state=None, shuffle=False), n_jobs=-1
2022-04-17 19:24:28,989:WARNING:create_model() for lightgbm raised an exception or returned all 0.0, trying without fit_kwargs:
2022-04-17 19:24:28,995:WARNING:Traceback (most recent call last):
  File "C:\Users\8prab\.conda\envs\ee\lib\site-packages\pycaret\internal\tabular.py", line 2203, in compare_models
    model, model_fit_time = create_model_supervised(**create_model_args)
  File "C:\Users\8prab\.conda\envs\ee\lib\site-packages\pycaret\internal\tabular.py", line 3200, in create_model_supervised
    scores = cross_validate(
  File "C:\Users\8prab\.conda\envs\ee\lib\site-packages\sklearn\utils\validation.py", line 72, in inner_f
    return f(**kwargs)
  File "C:\Users\8prab\.conda\envs\ee\lib\site-packages\sklearn\model_selection\_validation.py", line 242, in cross_validate
    scores = parallel(
  File "C:\Users\8prab\AppData\Roaming\Python\Python38\site-packages\joblib\parallel.py", line 968, in __call__
    n_jobs = self._initialize_backend()
  File "C:\Users\8prab\AppData\Roaming\Python\Python38\site-packages\joblib\parallel.py", line 735, in _initialize_backend
    n_jobs = self._backend.configure(n_jobs=self.n_jobs, parallel=self,
  File "C:\Users\8prab\AppData\Roaming\Python\Python38\site-packages\joblib\_parallel_backends.py", line 494, in configure
    self._workers = get_memmapping_executor(
  File "C:\Users\8prab\AppData\Roaming\Python\Python38\site-packages\joblib\executor.py", line 20, in get_memmapping_executor
    return MemmappingExecutor.get_memmapping_executor(n_jobs, **kwargs)
  File "C:\Users\8prab\AppData\Roaming\Python\Python38\site-packages\joblib\executor.py", line 42, in get_memmapping_executor
    manager = TemporaryResourcesManager(temp_folder)
  File "C:\Users\8prab\AppData\Roaming\Python\Python38\site-packages\joblib\_memmapping_reducer.py", line 531, in __init__
    self.set_current_context(context_id)
  File "C:\Users\8prab\AppData\Roaming\Python\Python38\site-packages\joblib\_memmapping_reducer.py", line 535, in set_current_context
    self.register_new_context(context_id)
  File "C:\Users\8prab\AppData\Roaming\Python\Python38\site-packages\joblib\_memmapping_reducer.py", line 560, in register_new_context
    self.register_folder_finalizer(new_folder_path, context_id)
  File "C:\Users\8prab\AppData\Roaming\Python\Python38\site-packages\joblib\_memmapping_reducer.py", line 590, in register_folder_finalizer
    resource_tracker.register(pool_subfolder, "folder")
  File "C:\Users\8prab\AppData\Roaming\Python\Python38\site-packages\joblib\externals\loky\backend\resource_tracker.py", line 190, in register
    self.ensure_running()
  File "C:\Users\8prab\AppData\Roaming\Python\Python38\site-packages\joblib\externals\loky\backend\resource_tracker.py", line 102, in ensure_running
    if self._check_alive():
  File "C:\Users\8prab\AppData\Roaming\Python\Python38\site-packages\joblib\externals\loky\backend\resource_tracker.py", line 182, in _check_alive
    self._send('PROBE', '', '')
  File "C:\Users\8prab\AppData\Roaming\Python\Python38\site-packages\joblib\externals\loky\backend\resource_tracker.py", line 209, in _send
    nbytes = os.write(self._fd, msg)
OSError: [Errno 22] Invalid argument

2022-04-17 19:24:28,997:INFO:Initializing create_model()
2022-04-17 19:24:29,000:INFO:create_model(estimator=lightgbm, fold=StratifiedKFold(n_splits=10, random_state=None, shuffle=False), round=4, cross_validation=True, predict=True, fit_kwargs={}, groups=None, refit=False, verbose=False, system=False, metrics=None, experiment_custom_tags=None, add_to_model_list=True, probability_threshold=None, display=<pycaret.internal.Display.Display object at 0x000001D75ACFC490>, return_train_score=False, kwargs={})
2022-04-17 19:24:29,002:INFO:Checking exceptions
2022-04-17 19:24:29,004:INFO:Importing libraries
2022-04-17 19:24:29,005:INFO:Copying training dataset
2022-04-17 19:24:29,105:INFO:Defining folds
2022-04-17 19:24:29,106:INFO:Declaring metric variables
2022-04-17 19:24:29,127:INFO:Importing untrained model
2022-04-17 19:24:29,157:INFO:Light Gradient Boosting Machine Imported succesfully
2022-04-17 19:24:29,204:INFO:Starting cross validation
2022-04-17 19:24:29,207:INFO:Cross validating with StratifiedKFold(n_splits=10, random_state=None, shuffle=False), n_jobs=-1
2022-04-17 19:24:29,210:ERROR:create_model() for lightgbm raised an exception or returned all 0.0:
2022-04-17 19:24:29,216:ERROR:Traceback (most recent call last):
  File "C:\Users\8prab\.conda\envs\ee\lib\site-packages\pycaret\internal\tabular.py", line 2203, in compare_models
    model, model_fit_time = create_model_supervised(**create_model_args)
  File "C:\Users\8prab\.conda\envs\ee\lib\site-packages\pycaret\internal\tabular.py", line 3200, in create_model_supervised
    scores = cross_validate(
  File "C:\Users\8prab\.conda\envs\ee\lib\site-packages\sklearn\utils\validation.py", line 72, in inner_f
    return f(**kwargs)
  File "C:\Users\8prab\.conda\envs\ee\lib\site-packages\sklearn\model_selection\_validation.py", line 242, in cross_validate
    scores = parallel(
  File "C:\Users\8prab\AppData\Roaming\Python\Python38\site-packages\joblib\parallel.py", line 968, in __call__
    n_jobs = self._initialize_backend()
  File "C:\Users\8prab\AppData\Roaming\Python\Python38\site-packages\joblib\parallel.py", line 735, in _initialize_backend
    n_jobs = self._backend.configure(n_jobs=self.n_jobs, parallel=self,
  File "C:\Users\8prab\AppData\Roaming\Python\Python38\site-packages\joblib\_parallel_backends.py", line 494, in configure
    self._workers = get_memmapping_executor(
  File "C:\Users\8prab\AppData\Roaming\Python\Python38\site-packages\joblib\executor.py", line 20, in get_memmapping_executor
    return MemmappingExecutor.get_memmapping_executor(n_jobs, **kwargs)
  File "C:\Users\8prab\AppData\Roaming\Python\Python38\site-packages\joblib\executor.py", line 42, in get_memmapping_executor
    manager = TemporaryResourcesManager(temp_folder)
  File "C:\Users\8prab\AppData\Roaming\Python\Python38\site-packages\joblib\_memmapping_reducer.py", line 531, in __init__
    self.set_current_context(context_id)
  File "C:\Users\8prab\AppData\Roaming\Python\Python38\site-packages\joblib\_memmapping_reducer.py", line 535, in set_current_context
    self.register_new_context(context_id)
  File "C:\Users\8prab\AppData\Roaming\Python\Python38\site-packages\joblib\_memmapping_reducer.py", line 560, in register_new_context
    self.register_folder_finalizer(new_folder_path, context_id)
  File "C:\Users\8prab\AppData\Roaming\Python\Python38\site-packages\joblib\_memmapping_reducer.py", line 590, in register_folder_finalizer
    resource_tracker.register(pool_subfolder, "folder")
  File "C:\Users\8prab\AppData\Roaming\Python\Python38\site-packages\joblib\externals\loky\backend\resource_tracker.py", line 190, in register
    self.ensure_running()
  File "C:\Users\8prab\AppData\Roaming\Python\Python38\site-packages\joblib\externals\loky\backend\resource_tracker.py", line 102, in ensure_running
    if self._check_alive():
  File "C:\Users\8prab\AppData\Roaming\Python\Python38\site-packages\joblib\externals\loky\backend\resource_tracker.py", line 182, in _check_alive
    self._send('PROBE', '', '')
  File "C:\Users\8prab\AppData\Roaming\Python\Python38\site-packages\joblib\externals\loky\backend\resource_tracker.py", line 209, in _send
    nbytes = os.write(self._fd, msg)
OSError: [Errno 22] Invalid argument

During handling of the above exception, another exception occurred:

Traceback (most recent call last):
  File "C:\Users\8prab\.conda\envs\ee\lib\site-packages\pycaret\internal\tabular.py", line 2212, in compare_models
    model, model_fit_time = create_model_supervised(**create_model_args)
  File "C:\Users\8prab\.conda\envs\ee\lib\site-packages\pycaret\internal\tabular.py", line 3200, in create_model_supervised
    scores = cross_validate(
  File "C:\Users\8prab\.conda\envs\ee\lib\site-packages\sklearn\utils\validation.py", line 72, in inner_f
    return f(**kwargs)
  File "C:\Users\8prab\.conda\envs\ee\lib\site-packages\sklearn\model_selection\_validation.py", line 242, in cross_validate
    scores = parallel(
  File "C:\Users\8prab\AppData\Roaming\Python\Python38\site-packages\joblib\parallel.py", line 968, in __call__
    n_jobs = self._initialize_backend()
  File "C:\Users\8prab\AppData\Roaming\Python\Python38\site-packages\joblib\parallel.py", line 735, in _initialize_backend
    n_jobs = self._backend.configure(n_jobs=self.n_jobs, parallel=self,
  File "C:\Users\8prab\AppData\Roaming\Python\Python38\site-packages\joblib\_parallel_backends.py", line 494, in configure
    self._workers = get_memmapping_executor(
  File "C:\Users\8prab\AppData\Roaming\Python\Python38\site-packages\joblib\executor.py", line 20, in get_memmapping_executor
    return MemmappingExecutor.get_memmapping_executor(n_jobs, **kwargs)
  File "C:\Users\8prab\AppData\Roaming\Python\Python38\site-packages\joblib\executor.py", line 42, in get_memmapping_executor
    manager = TemporaryResourcesManager(temp_folder)
  File "C:\Users\8prab\AppData\Roaming\Python\Python38\site-packages\joblib\_memmapping_reducer.py", line 531, in __init__
    self.set_current_context(context_id)
  File "C:\Users\8prab\AppData\Roaming\Python\Python38\site-packages\joblib\_memmapping_reducer.py", line 535, in set_current_context
    self.register_new_context(context_id)
  File "C:\Users\8prab\AppData\Roaming\Python\Python38\site-packages\joblib\_memmapping_reducer.py", line 560, in register_new_context
    self.register_folder_finalizer(new_folder_path, context_id)
  File "C:\Users\8prab\AppData\Roaming\Python\Python38\site-packages\joblib\_memmapping_reducer.py", line 590, in register_folder_finalizer
    resource_tracker.register(pool_subfolder, "folder")
  File "C:\Users\8prab\AppData\Roaming\Python\Python38\site-packages\joblib\externals\loky\backend\resource_tracker.py", line 190, in register
    self.ensure_running()
  File "C:\Users\8prab\AppData\Roaming\Python\Python38\site-packages\joblib\externals\loky\backend\resource_tracker.py", line 102, in ensure_running
    if self._check_alive():
  File "C:\Users\8prab\AppData\Roaming\Python\Python38\site-packages\joblib\externals\loky\backend\resource_tracker.py", line 182, in _check_alive
    self._send('PROBE', '', '')
  File "C:\Users\8prab\AppData\Roaming\Python\Python38\site-packages\joblib\externals\loky\backend\resource_tracker.py", line 209, in _send
    nbytes = os.write(self._fd, msg)
OSError: [Errno 22] Invalid argument

2022-04-17 19:24:29,245:INFO:Initializing CatBoost Classifier
2022-04-17 19:24:29,246:INFO:Total runtime is 0.14529560804367064 minutes
2022-04-17 19:24:29,269:INFO:SubProcess create_model() called ==================================
2022-04-17 19:24:29,272:INFO:Initializing create_model()
2022-04-17 19:24:29,274:INFO:create_model(estimator=catboost, fold=StratifiedKFold(n_splits=10, random_state=None, shuffle=False), round=4, cross_validation=True, predict=True, fit_kwargs={}, groups=None, refit=False, verbose=False, system=False, metrics=None, experiment_custom_tags=None, add_to_model_list=True, probability_threshold=None, display=<pycaret.internal.Display.Display object at 0x000001D75ACFC490>, return_train_score=False, kwargs={})
2022-04-17 19:24:29,275:INFO:Checking exceptions
2022-04-17 19:24:29,277:INFO:Importing libraries
2022-04-17 19:24:29,279:INFO:Copying training dataset
2022-04-17 19:24:29,355:INFO:Defining folds
2022-04-17 19:24:29,357:INFO:Declaring metric variables
2022-04-17 19:24:29,382:INFO:Importing untrained model
2022-04-17 19:24:29,400:INFO:CatBoost Classifier Imported succesfully
2022-04-17 19:24:29,445:INFO:Starting cross validation
2022-04-17 19:24:29,450:INFO:Cross validating with StratifiedKFold(n_splits=10, random_state=None, shuffle=False), n_jobs=-1
2022-04-17 19:24:29,454:WARNING:create_model() for catboost raised an exception or returned all 0.0, trying without fit_kwargs:
2022-04-17 19:24:29,458:WARNING:Traceback (most recent call last):
  File "C:\Users\8prab\.conda\envs\ee\lib\site-packages\pycaret\internal\tabular.py", line 2203, in compare_models
    model, model_fit_time = create_model_supervised(**create_model_args)
  File "C:\Users\8prab\.conda\envs\ee\lib\site-packages\pycaret\internal\tabular.py", line 3200, in create_model_supervised
    scores = cross_validate(
  File "C:\Users\8prab\.conda\envs\ee\lib\site-packages\sklearn\utils\validation.py", line 72, in inner_f
    return f(**kwargs)
  File "C:\Users\8prab\.conda\envs\ee\lib\site-packages\sklearn\model_selection\_validation.py", line 242, in cross_validate
    scores = parallel(
  File "C:\Users\8prab\AppData\Roaming\Python\Python38\site-packages\joblib\parallel.py", line 968, in __call__
    n_jobs = self._initialize_backend()
  File "C:\Users\8prab\AppData\Roaming\Python\Python38\site-packages\joblib\parallel.py", line 735, in _initialize_backend
    n_jobs = self._backend.configure(n_jobs=self.n_jobs, parallel=self,
  File "C:\Users\8prab\AppData\Roaming\Python\Python38\site-packages\joblib\_parallel_backends.py", line 494, in configure
    self._workers = get_memmapping_executor(
  File "C:\Users\8prab\AppData\Roaming\Python\Python38\site-packages\joblib\executor.py", line 20, in get_memmapping_executor
    return MemmappingExecutor.get_memmapping_executor(n_jobs, **kwargs)
  File "C:\Users\8prab\AppData\Roaming\Python\Python38\site-packages\joblib\executor.py", line 42, in get_memmapping_executor
    manager = TemporaryResourcesManager(temp_folder)
  File "C:\Users\8prab\AppData\Roaming\Python\Python38\site-packages\joblib\_memmapping_reducer.py", line 531, in __init__
    self.set_current_context(context_id)
  File "C:\Users\8prab\AppData\Roaming\Python\Python38\site-packages\joblib\_memmapping_reducer.py", line 535, in set_current_context
    self.register_new_context(context_id)
  File "C:\Users\8prab\AppData\Roaming\Python\Python38\site-packages\joblib\_memmapping_reducer.py", line 560, in register_new_context
    self.register_folder_finalizer(new_folder_path, context_id)
  File "C:\Users\8prab\AppData\Roaming\Python\Python38\site-packages\joblib\_memmapping_reducer.py", line 590, in register_folder_finalizer
    resource_tracker.register(pool_subfolder, "folder")
  File "C:\Users\8prab\AppData\Roaming\Python\Python38\site-packages\joblib\externals\loky\backend\resource_tracker.py", line 190, in register
    self.ensure_running()
  File "C:\Users\8prab\AppData\Roaming\Python\Python38\site-packages\joblib\externals\loky\backend\resource_tracker.py", line 102, in ensure_running
    if self._check_alive():
  File "C:\Users\8prab\AppData\Roaming\Python\Python38\site-packages\joblib\externals\loky\backend\resource_tracker.py", line 182, in _check_alive
    self._send('PROBE', '', '')
  File "C:\Users\8prab\AppData\Roaming\Python\Python38\site-packages\joblib\externals\loky\backend\resource_tracker.py", line 209, in _send
    nbytes = os.write(self._fd, msg)
OSError: [Errno 22] Invalid argument

2022-04-17 19:24:29,463:INFO:Initializing create_model()
2022-04-17 19:24:29,465:INFO:create_model(estimator=catboost, fold=StratifiedKFold(n_splits=10, random_state=None, shuffle=False), round=4, cross_validation=True, predict=True, fit_kwargs={}, groups=None, refit=False, verbose=False, system=False, metrics=None, experiment_custom_tags=None, add_to_model_list=True, probability_threshold=None, display=<pycaret.internal.Display.Display object at 0x000001D75ACFC490>, return_train_score=False, kwargs={})
2022-04-17 19:24:29,468:INFO:Checking exceptions
2022-04-17 19:24:29,470:INFO:Importing libraries
2022-04-17 19:24:29,471:INFO:Copying training dataset
2022-04-17 19:24:29,536:INFO:Defining folds
2022-04-17 19:24:29,538:INFO:Declaring metric variables
2022-04-17 19:24:29,565:INFO:Importing untrained model
2022-04-17 19:24:29,588:INFO:CatBoost Classifier Imported succesfully
2022-04-17 19:24:29,656:INFO:Starting cross validation
2022-04-17 19:24:29,658:INFO:Cross validating with StratifiedKFold(n_splits=10, random_state=None, shuffle=False), n_jobs=-1
2022-04-17 19:24:29,663:ERROR:create_model() for catboost raised an exception or returned all 0.0:
2022-04-17 19:24:29,668:ERROR:Traceback (most recent call last):
  File "C:\Users\8prab\.conda\envs\ee\lib\site-packages\pycaret\internal\tabular.py", line 2203, in compare_models
    model, model_fit_time = create_model_supervised(**create_model_args)
  File "C:\Users\8prab\.conda\envs\ee\lib\site-packages\pycaret\internal\tabular.py", line 3200, in create_model_supervised
    scores = cross_validate(
  File "C:\Users\8prab\.conda\envs\ee\lib\site-packages\sklearn\utils\validation.py", line 72, in inner_f
    return f(**kwargs)
  File "C:\Users\8prab\.conda\envs\ee\lib\site-packages\sklearn\model_selection\_validation.py", line 242, in cross_validate
    scores = parallel(
  File "C:\Users\8prab\AppData\Roaming\Python\Python38\site-packages\joblib\parallel.py", line 968, in __call__
    n_jobs = self._initialize_backend()
  File "C:\Users\8prab\AppData\Roaming\Python\Python38\site-packages\joblib\parallel.py", line 735, in _initialize_backend
    n_jobs = self._backend.configure(n_jobs=self.n_jobs, parallel=self,
  File "C:\Users\8prab\AppData\Roaming\Python\Python38\site-packages\joblib\_parallel_backends.py", line 494, in configure
    self._workers = get_memmapping_executor(
  File "C:\Users\8prab\AppData\Roaming\Python\Python38\site-packages\joblib\executor.py", line 20, in get_memmapping_executor
    return MemmappingExecutor.get_memmapping_executor(n_jobs, **kwargs)
  File "C:\Users\8prab\AppData\Roaming\Python\Python38\site-packages\joblib\executor.py", line 42, in get_memmapping_executor
    manager = TemporaryResourcesManager(temp_folder)
  File "C:\Users\8prab\AppData\Roaming\Python\Python38\site-packages\joblib\_memmapping_reducer.py", line 531, in __init__
    self.set_current_context(context_id)
  File "C:\Users\8prab\AppData\Roaming\Python\Python38\site-packages\joblib\_memmapping_reducer.py", line 535, in set_current_context
    self.register_new_context(context_id)
  File "C:\Users\8prab\AppData\Roaming\Python\Python38\site-packages\joblib\_memmapping_reducer.py", line 560, in register_new_context
    self.register_folder_finalizer(new_folder_path, context_id)
  File "C:\Users\8prab\AppData\Roaming\Python\Python38\site-packages\joblib\_memmapping_reducer.py", line 590, in register_folder_finalizer
    resource_tracker.register(pool_subfolder, "folder")
  File "C:\Users\8prab\AppData\Roaming\Python\Python38\site-packages\joblib\externals\loky\backend\resource_tracker.py", line 190, in register
    self.ensure_running()
  File "C:\Users\8prab\AppData\Roaming\Python\Python38\site-packages\joblib\externals\loky\backend\resource_tracker.py", line 102, in ensure_running
    if self._check_alive():
  File "C:\Users\8prab\AppData\Roaming\Python\Python38\site-packages\joblib\externals\loky\backend\resource_tracker.py", line 182, in _check_alive
    self._send('PROBE', '', '')
  File "C:\Users\8prab\AppData\Roaming\Python\Python38\site-packages\joblib\externals\loky\backend\resource_tracker.py", line 209, in _send
    nbytes = os.write(self._fd, msg)
OSError: [Errno 22] Invalid argument

During handling of the above exception, another exception occurred:

Traceback (most recent call last):
  File "C:\Users\8prab\.conda\envs\ee\lib\site-packages\pycaret\internal\tabular.py", line 2212, in compare_models
    model, model_fit_time = create_model_supervised(**create_model_args)
  File "C:\Users\8prab\.conda\envs\ee\lib\site-packages\pycaret\internal\tabular.py", line 3200, in create_model_supervised
    scores = cross_validate(
  File "C:\Users\8prab\.conda\envs\ee\lib\site-packages\sklearn\utils\validation.py", line 72, in inner_f
    return f(**kwargs)
  File "C:\Users\8prab\.conda\envs\ee\lib\site-packages\sklearn\model_selection\_validation.py", line 242, in cross_validate
    scores = parallel(
  File "C:\Users\8prab\AppData\Roaming\Python\Python38\site-packages\joblib\parallel.py", line 968, in __call__
    n_jobs = self._initialize_backend()
  File "C:\Users\8prab\AppData\Roaming\Python\Python38\site-packages\joblib\parallel.py", line 735, in _initialize_backend
    n_jobs = self._backend.configure(n_jobs=self.n_jobs, parallel=self,
  File "C:\Users\8prab\AppData\Roaming\Python\Python38\site-packages\joblib\_parallel_backends.py", line 494, in configure
    self._workers = get_memmapping_executor(
  File "C:\Users\8prab\AppData\Roaming\Python\Python38\site-packages\joblib\executor.py", line 20, in get_memmapping_executor
    return MemmappingExecutor.get_memmapping_executor(n_jobs, **kwargs)
  File "C:\Users\8prab\AppData\Roaming\Python\Python38\site-packages\joblib\executor.py", line 42, in get_memmapping_executor
    manager = TemporaryResourcesManager(temp_folder)
  File "C:\Users\8prab\AppData\Roaming\Python\Python38\site-packages\joblib\_memmapping_reducer.py", line 531, in __init__
    self.set_current_context(context_id)
  File "C:\Users\8prab\AppData\Roaming\Python\Python38\site-packages\joblib\_memmapping_reducer.py", line 535, in set_current_context
    self.register_new_context(context_id)
  File "C:\Users\8prab\AppData\Roaming\Python\Python38\site-packages\joblib\_memmapping_reducer.py", line 560, in register_new_context
    self.register_folder_finalizer(new_folder_path, context_id)
  File "C:\Users\8prab\AppData\Roaming\Python\Python38\site-packages\joblib\_memmapping_reducer.py", line 590, in register_folder_finalizer
    resource_tracker.register(pool_subfolder, "folder")
  File "C:\Users\8prab\AppData\Roaming\Python\Python38\site-packages\joblib\externals\loky\backend\resource_tracker.py", line 190, in register
    self.ensure_running()
  File "C:\Users\8prab\AppData\Roaming\Python\Python38\site-packages\joblib\externals\loky\backend\resource_tracker.py", line 102, in ensure_running
    if self._check_alive():
  File "C:\Users\8prab\AppData\Roaming\Python\Python38\site-packages\joblib\externals\loky\backend\resource_tracker.py", line 182, in _check_alive
    self._send('PROBE', '', '')
  File "C:\Users\8prab\AppData\Roaming\Python\Python38\site-packages\joblib\externals\loky\backend\resource_tracker.py", line 209, in _send
    nbytes = os.write(self._fd, msg)
OSError: [Errno 22] Invalid argument

2022-04-17 19:24:29,702:INFO:Initializing Dummy Classifier
2022-04-17 19:24:29,704:INFO:Total runtime is 0.15293089548746744 minutes
2022-04-17 19:24:29,730:INFO:SubProcess create_model() called ==================================
2022-04-17 19:24:29,732:INFO:Initializing create_model()
2022-04-17 19:24:29,734:INFO:create_model(estimator=dummy, fold=StratifiedKFold(n_splits=10, random_state=None, shuffle=False), round=4, cross_validation=True, predict=True, fit_kwargs={}, groups=None, refit=False, verbose=False, system=False, metrics=None, experiment_custom_tags=None, add_to_model_list=True, probability_threshold=None, display=<pycaret.internal.Display.Display object at 0x000001D75ACFC490>, return_train_score=False, kwargs={})
2022-04-17 19:24:29,735:INFO:Checking exceptions
2022-04-17 19:24:29,737:INFO:Importing libraries
2022-04-17 19:24:29,738:INFO:Copying training dataset
2022-04-17 19:24:29,883:INFO:Defining folds
2022-04-17 19:24:29,885:INFO:Declaring metric variables
2022-04-17 19:24:29,902:INFO:Importing untrained model
2022-04-17 19:24:29,977:INFO:Dummy Classifier Imported succesfully
2022-04-17 19:24:30,032:INFO:Starting cross validation
2022-04-17 19:24:30,035:INFO:Cross validating with StratifiedKFold(n_splits=10, random_state=None, shuffle=False), n_jobs=-1
2022-04-17 19:24:30,038:WARNING:create_model() for dummy raised an exception or returned all 0.0, trying without fit_kwargs:
2022-04-17 19:24:30,043:WARNING:Traceback (most recent call last):
  File "C:\Users\8prab\.conda\envs\ee\lib\site-packages\pycaret\internal\tabular.py", line 2203, in compare_models
    model, model_fit_time = create_model_supervised(**create_model_args)
  File "C:\Users\8prab\.conda\envs\ee\lib\site-packages\pycaret\internal\tabular.py", line 3200, in create_model_supervised
    scores = cross_validate(
  File "C:\Users\8prab\.conda\envs\ee\lib\site-packages\sklearn\utils\validation.py", line 72, in inner_f
    return f(**kwargs)
  File "C:\Users\8prab\.conda\envs\ee\lib\site-packages\sklearn\model_selection\_validation.py", line 242, in cross_validate
    scores = parallel(
  File "C:\Users\8prab\AppData\Roaming\Python\Python38\site-packages\joblib\parallel.py", line 968, in __call__
    n_jobs = self._initialize_backend()
  File "C:\Users\8prab\AppData\Roaming\Python\Python38\site-packages\joblib\parallel.py", line 735, in _initialize_backend
    n_jobs = self._backend.configure(n_jobs=self.n_jobs, parallel=self,
  File "C:\Users\8prab\AppData\Roaming\Python\Python38\site-packages\joblib\_parallel_backends.py", line 494, in configure
    self._workers = get_memmapping_executor(
  File "C:\Users\8prab\AppData\Roaming\Python\Python38\site-packages\joblib\executor.py", line 20, in get_memmapping_executor
    return MemmappingExecutor.get_memmapping_executor(n_jobs, **kwargs)
  File "C:\Users\8prab\AppData\Roaming\Python\Python38\site-packages\joblib\executor.py", line 42, in get_memmapping_executor
    manager = TemporaryResourcesManager(temp_folder)
  File "C:\Users\8prab\AppData\Roaming\Python\Python38\site-packages\joblib\_memmapping_reducer.py", line 531, in __init__
    self.set_current_context(context_id)
  File "C:\Users\8prab\AppData\Roaming\Python\Python38\site-packages\joblib\_memmapping_reducer.py", line 535, in set_current_context
    self.register_new_context(context_id)
  File "C:\Users\8prab\AppData\Roaming\Python\Python38\site-packages\joblib\_memmapping_reducer.py", line 560, in register_new_context
    self.register_folder_finalizer(new_folder_path, context_id)
  File "C:\Users\8prab\AppData\Roaming\Python\Python38\site-packages\joblib\_memmapping_reducer.py", line 590, in register_folder_finalizer
    resource_tracker.register(pool_subfolder, "folder")
  File "C:\Users\8prab\AppData\Roaming\Python\Python38\site-packages\joblib\externals\loky\backend\resource_tracker.py", line 190, in register
    self.ensure_running()
  File "C:\Users\8prab\AppData\Roaming\Python\Python38\site-packages\joblib\externals\loky\backend\resource_tracker.py", line 102, in ensure_running
    if self._check_alive():
  File "C:\Users\8prab\AppData\Roaming\Python\Python38\site-packages\joblib\externals\loky\backend\resource_tracker.py", line 182, in _check_alive
    self._send('PROBE', '', '')
  File "C:\Users\8prab\AppData\Roaming\Python\Python38\site-packages\joblib\externals\loky\backend\resource_tracker.py", line 209, in _send
    nbytes = os.write(self._fd, msg)
OSError: [Errno 22] Invalid argument

2022-04-17 19:24:30,047:INFO:Initializing create_model()
2022-04-17 19:24:30,049:INFO:create_model(estimator=dummy, fold=StratifiedKFold(n_splits=10, random_state=None, shuffle=False), round=4, cross_validation=True, predict=True, fit_kwargs={}, groups=None, refit=False, verbose=False, system=False, metrics=None, experiment_custom_tags=None, add_to_model_list=True, probability_threshold=None, display=<pycaret.internal.Display.Display object at 0x000001D75ACFC490>, return_train_score=False, kwargs={})
2022-04-17 19:24:30,051:INFO:Checking exceptions
2022-04-17 19:24:30,053:INFO:Importing libraries
2022-04-17 19:24:30,055:INFO:Copying training dataset
2022-04-17 19:24:30,190:INFO:Defining folds
2022-04-17 19:24:30,191:INFO:Declaring metric variables
2022-04-17 19:24:30,216:INFO:Importing untrained model
2022-04-17 19:24:30,247:INFO:Dummy Classifier Imported succesfully
2022-04-17 19:24:30,371:INFO:Starting cross validation
2022-04-17 19:24:30,374:INFO:Cross validating with StratifiedKFold(n_splits=10, random_state=None, shuffle=False), n_jobs=-1
2022-04-17 19:24:30,421:ERROR:create_model() for dummy raised an exception or returned all 0.0:
2022-04-17 19:24:30,427:ERROR:Traceback (most recent call last):
  File "C:\Users\8prab\.conda\envs\ee\lib\site-packages\pycaret\internal\tabular.py", line 2203, in compare_models
    model, model_fit_time = create_model_supervised(**create_model_args)
  File "C:\Users\8prab\.conda\envs\ee\lib\site-packages\pycaret\internal\tabular.py", line 3200, in create_model_supervised
    scores = cross_validate(
  File "C:\Users\8prab\.conda\envs\ee\lib\site-packages\sklearn\utils\validation.py", line 72, in inner_f
    return f(**kwargs)
  File "C:\Users\8prab\.conda\envs\ee\lib\site-packages\sklearn\model_selection\_validation.py", line 242, in cross_validate
    scores = parallel(
  File "C:\Users\8prab\AppData\Roaming\Python\Python38\site-packages\joblib\parallel.py", line 968, in __call__
    n_jobs = self._initialize_backend()
  File "C:\Users\8prab\AppData\Roaming\Python\Python38\site-packages\joblib\parallel.py", line 735, in _initialize_backend
    n_jobs = self._backend.configure(n_jobs=self.n_jobs, parallel=self,
  File "C:\Users\8prab\AppData\Roaming\Python\Python38\site-packages\joblib\_parallel_backends.py", line 494, in configure
    self._workers = get_memmapping_executor(
  File "C:\Users\8prab\AppData\Roaming\Python\Python38\site-packages\joblib\executor.py", line 20, in get_memmapping_executor
    return MemmappingExecutor.get_memmapping_executor(n_jobs, **kwargs)
  File "C:\Users\8prab\AppData\Roaming\Python\Python38\site-packages\joblib\executor.py", line 42, in get_memmapping_executor
    manager = TemporaryResourcesManager(temp_folder)
  File "C:\Users\8prab\AppData\Roaming\Python\Python38\site-packages\joblib\_memmapping_reducer.py", line 531, in __init__
    self.set_current_context(context_id)
  File "C:\Users\8prab\AppData\Roaming\Python\Python38\site-packages\joblib\_memmapping_reducer.py", line 535, in set_current_context
    self.register_new_context(context_id)
  File "C:\Users\8prab\AppData\Roaming\Python\Python38\site-packages\joblib\_memmapping_reducer.py", line 560, in register_new_context
    self.register_folder_finalizer(new_folder_path, context_id)
  File "C:\Users\8prab\AppData\Roaming\Python\Python38\site-packages\joblib\_memmapping_reducer.py", line 590, in register_folder_finalizer
    resource_tracker.register(pool_subfolder, "folder")
  File "C:\Users\8prab\AppData\Roaming\Python\Python38\site-packages\joblib\externals\loky\backend\resource_tracker.py", line 190, in register
    self.ensure_running()
  File "C:\Users\8prab\AppData\Roaming\Python\Python38\site-packages\joblib\externals\loky\backend\resource_tracker.py", line 102, in ensure_running
    if self._check_alive():
  File "C:\Users\8prab\AppData\Roaming\Python\Python38\site-packages\joblib\externals\loky\backend\resource_tracker.py", line 182, in _check_alive
    self._send('PROBE', '', '')
  File "C:\Users\8prab\AppData\Roaming\Python\Python38\site-packages\joblib\externals\loky\backend\resource_tracker.py", line 209, in _send
    nbytes = os.write(self._fd, msg)
OSError: [Errno 22] Invalid argument

During handling of the above exception, another exception occurred:

Traceback (most recent call last):
  File "C:\Users\8prab\.conda\envs\ee\lib\site-packages\pycaret\internal\tabular.py", line 2212, in compare_models
    model, model_fit_time = create_model_supervised(**create_model_args)
  File "C:\Users\8prab\.conda\envs\ee\lib\site-packages\pycaret\internal\tabular.py", line 3200, in create_model_supervised
    scores = cross_validate(
  File "C:\Users\8prab\.conda\envs\ee\lib\site-packages\sklearn\utils\validation.py", line 72, in inner_f
    return f(**kwargs)
  File "C:\Users\8prab\.conda\envs\ee\lib\site-packages\sklearn\model_selection\_validation.py", line 242, in cross_validate
    scores = parallel(
  File "C:\Users\8prab\AppData\Roaming\Python\Python38\site-packages\joblib\parallel.py", line 968, in __call__
    n_jobs = self._initialize_backend()
  File "C:\Users\8prab\AppData\Roaming\Python\Python38\site-packages\joblib\parallel.py", line 735, in _initialize_backend
    n_jobs = self._backend.configure(n_jobs=self.n_jobs, parallel=self,
  File "C:\Users\8prab\AppData\Roaming\Python\Python38\site-packages\joblib\_parallel_backends.py", line 494, in configure
    self._workers = get_memmapping_executor(
  File "C:\Users\8prab\AppData\Roaming\Python\Python38\site-packages\joblib\executor.py", line 20, in get_memmapping_executor
    return MemmappingExecutor.get_memmapping_executor(n_jobs, **kwargs)
  File "C:\Users\8prab\AppData\Roaming\Python\Python38\site-packages\joblib\executor.py", line 42, in get_memmapping_executor
    manager = TemporaryResourcesManager(temp_folder)
  File "C:\Users\8prab\AppData\Roaming\Python\Python38\site-packages\joblib\_memmapping_reducer.py", line 531, in __init__
    self.set_current_context(context_id)
  File "C:\Users\8prab\AppData\Roaming\Python\Python38\site-packages\joblib\_memmapping_reducer.py", line 535, in set_current_context
    self.register_new_context(context_id)
  File "C:\Users\8prab\AppData\Roaming\Python\Python38\site-packages\joblib\_memmapping_reducer.py", line 560, in register_new_context
    self.register_folder_finalizer(new_folder_path, context_id)
  File "C:\Users\8prab\AppData\Roaming\Python\Python38\site-packages\joblib\_memmapping_reducer.py", line 590, in register_folder_finalizer
    resource_tracker.register(pool_subfolder, "folder")
  File "C:\Users\8prab\AppData\Roaming\Python\Python38\site-packages\joblib\externals\loky\backend\resource_tracker.py", line 190, in register
    self.ensure_running()
  File "C:\Users\8prab\AppData\Roaming\Python\Python38\site-packages\joblib\externals\loky\backend\resource_tracker.py", line 102, in ensure_running
    if self._check_alive():
  File "C:\Users\8prab\AppData\Roaming\Python\Python38\site-packages\joblib\externals\loky\backend\resource_tracker.py", line 182, in _check_alive
    self._send('PROBE', '', '')
  File "C:\Users\8prab\AppData\Roaming\Python\Python38\site-packages\joblib\externals\loky\backend\resource_tracker.py", line 209, in _send
    nbytes = os.write(self._fd, msg)
OSError: [Errno 22] Invalid argument

2022-04-17 19:24:30,548:INFO:create_model_container: 0
2022-04-17 19:24:30,549:INFO:master_model_container: 0
2022-04-17 19:24:30,551:INFO:display_container: 2
2022-04-17 19:24:30,552:INFO:[]
2022-04-17 19:24:30,553:INFO:compare_models() succesfully completed......................................
